Workbook

Sheet Cover
B2: SEO KEYWORD RESEARCH & STRATEGY WORKBOOK
B3: Southern Smiles Dental Center | Gadsden, AL, USA
B4: Prepared By: Md. Abdul Alim | Local SEO & AI Search Optimization Consultant
B9: KEYWORD RESEARCH DASHBOARD
B10: TOTAL KEYWORDS RESEARCHED | E10: KEYWORD CLUSTERS | H10: EST. MONTHLY SEARCH VOLUME | K10: LOCAL / REGIONAL / NATIONAL
B11: =COUNTA('Keyword Master Database'!$A$2:$A$242) -> 241 | E11: =COUNTA('Keyword Clusters'!A2:A27) -> 26 | H11: =SUMIF('Keyword Master Database'!$AA$2:$AA$242,"<>National",'Keyword Master Database'!$H$2:$H$242) -> 12550 | K11: =COUNTIF('Keyword Master Database'!$AA$2:$AA$242,"Local")&" / "&COUNTIF('Keyword Master Database'!$AA$2:$AA$242,"Regional")&" / "&COUNTIF('Keyword Master Database'!$AA$2:$AA$242,"National") -> 119 / 8 / 114
B12: keywords in master database | E12: grouped by intent & SERP | H12: ="Local + Regional | incl. national: "&TEXT(SUM('Keyword Master Database'!$H$2:$H$242),"#,##0") -> Local + Regional | incl. national: 3,196,210 | K12: keyword counts by geo scope
B14: AVERAGE KEYWORD DIFFICULTY | E14: CRITICAL + HIGH PRIORITY | H14: PAGES MAPPED | K14: NEW PAGES RECOMMENDED
B15: =ROUND(AVERAGE('Keyword Master Database'!$J$2:$J$242),1) -> 30.5 | E15: =COUNTIF('Keyword Master Database'!$W$2:$W$242,"Critical")+COUNTIF('Keyword Master Database'!$W$2:$W$242,"High") -> 102 | H15: =COUNTA('Keyword Mapping'!A2:A71) -> 70 | K15: =COUNTIF('Keyword Mapping'!G2:G71,"New") -> 67
B16: estimated KD, 0-100 | E16: keywords to target first | H16: URLs with a primary keyword | K16: net-new URLs to create
B18: INTERNAL LINKS PLANNED | E18: CONTENT OPPORTUNITIES | H18: AVG. SEO PRIORITY SCORE | K18: QUICK WINS IDENTIFIED
B19: =COUNTA('Internal Linking Blueprint'!A2:A296) -> 295 | E19: =COUNTA('Content Roadmap'!D2:D71) -> 70 | H19: =ROUND(AVERAGE('Keyword Master Database'!$V$2:$V$242),0) -> 65 | K19: =COUNTA('Quick Wins'!A2:A19) -> 18
B20: contextual + structural links | E20: roadmap items (6 months) | H20: weighted score, 0-100 | K20: actions for first 30-60 days
B24: DISTRIBUTION SUMMARY
B25: Search Intent | C25: Keywords | D25: Share | E25: Priority Level | F25: Keywords | G25: Share | I25: Funnel Stage | K25: Keywords | L25: Share | M25: Remarks
B26: Informational | C26: =COUNTIF('Keyword Master Database'!$E$2:$E$242,B26) -> 47 | D26: =IF(SUM(C26:C29)=0,0,C26/SUM(C26:C29)) -> 0.19502075 | E26: Critical | F26: =COUNTIF('Keyword Master Database'!$W$2:$W$242,E26) -> 13 | G26: =IF(SUM(F26:F29)=0,0,F26/SUM(F26:F29)) -> 0.060185185 | I26: TOFU | K26: =COUNTIF('Keyword Master Database'!$F$2:$F$242,I26) -> 43 | L26: =IF(SUM(K26:K28)=0,0,K26/SUM(K26:K28)) -> 0.17842324
B27: Navigational | C27: =COUNTIF('Keyword Master Database'!$E$2:$E$242,B27) -> 15 | D27: =IF(SUM(C26:C29)=0,0,C27/SUM(C26:C29)) -> 0.062240664 | E27: High | F27: =COUNTIF('Keyword Master Database'!$W$2:$W$242,E27) -> 89 | G27: =IF(SUM(F26:F29)=0,0,F27/SUM(F26:F29)) -> 0.41203704 | I27: MOFU | K27: =COUNTIF('Keyword Master Database'!$F$2:$F$242,I27) -> 75 | L27: =IF(SUM(K26:K28)=0,0,K27/SUM(K26:K28)) -> 0.31120332
B28: Commercial | C28: =COUNTIF('Keyword Master Database'!$E$2:$E$242,B28) -> 69 | D28: =IF(SUM(C26:C29)=0,0,C28/SUM(C26:C29)) -> 0.28630705 | E28: Medium | F28: =COUNTIF('Keyword Master Database'!$W$2:$W$242,E28) -> 30 | G28: =IF(SUM(F26:F29)=0,0,F28/SUM(F26:F29)) -> 0.13888889 | I28: BOFU | K28: =COUNTIF('Keyword Master Database'!$F$2:$F$242,I28) -> 123 | L28: =IF(SUM(K26:K28)=0,0,K28/SUM(K26:K28)) -> 0.51037344
B29: Transactional | C29: =COUNTIF('Keyword Master Database'!$E$2:$E$242,B29) -> 110 | D29: =IF(SUM(C26:C29)=0,0,C29/SUM(C26:C29)) -> 0.45643154 | E29: Low | F29: =COUNTIF('Keyword Master Database'!$W$2:$W$242,E29) -> 84 | G29: =IF(SUM(F26:F29)=0,0,F29/SUM(F26:F29)) -> 0.38888889
B33: VISUAL DASHBOARD
B52: WORKBOOK CONTENTS
B53: Sheet Name | F53: Purpose
B54: Business Analysis | F54: Business information, website analysis and SEO goals
B55: Keyword Master Database | F55: Complete keyword research database with metrics and strategy
B56: Keyword Clusters | F56: Keyword grouping and semantic organization
B57: Competitor Analysis | F57: Competitor keyword insights and opportunities
B58: Keyword Mapping | F58: Keyword to page targeting strategy
B59: Topical Authority Map | F59: Content authority planning
B60: SEO Silo Architecture | F60: Website structure planning
B61: Internal Linking Blueprint | F61: Internal authority flow strategy
B62: Content Roadmap | F62: Future content creation strategy
B63: Quick Wins | F63: Immediate SEO opportunities

Sheet Business Analysis
A1: BUSINESS ANALYSIS
A5: Field | B5: Details | C5: Notes / Source | D5: Status
A6: Business Name | B6: Southern Smiles Dental Center | C6: Provided | D6: Provided
A7: Website | B7: https://www.southernsmilesgadsden.com/ | C7: Provided | D7: Provided
A8: Industry | B8: Dental Clinic (general & family dentistry, dentures) | C8: Provided | D8: Provided
A9: Country | B9: United States | C9: Provided | D9: Provided
A10: Location | B10: 315 N 3rd St, Gadsden, AL 35901, United States | C10: Provided; phone (256) 459-5309 per website | D10: Provided
A11: Services | B11: Bridges; Clear Braces & Clear Aligners; Crowns; Dental Surgery; Extractions; Partials; Root Canals; Routine Cleaning; Same Day Dentures; X-Ray & Exams; and more (fillings and free denture adjustments also referenced on the website) | C11: Provided + website homepage | D11: Provided
A12: Products | B12: Not provided - service-based practice. Dentures are fabricated in the on-site denture laboratory. | C12: Not supplied; website states dentures are made on-site | D12: Not provided
A13: Goal | B13: 1) Generate more local leads 2) Increase organic traffic 3) Improve service-page + commercial + transactional keyword rankings 4) Build topical authority | C13: Provided | D13: Provided
A14: Primary SEO Focus | B14: Local SEO + AI SEO (AI Overviews / ChatGPT / Perplexity visibility) | C14: Provided | D14: Provided
A15: Service Area | B15: Etowah, St. Clair and Calhoun Counties, AL | C15: Website homepage | D15: Observed
A16: Office Hours | B16: Mon-Wed 8am-1pm & 2pm-5pm; closed Thu-Sun | C16: Website homepage (observed Oct 2026) - verify against Google Business Profile | D16: Observed
A19: WEBSITE ANALYSIS SNAPSHOT
A20: Area | B20: Finding (observed on southernsmilesgadsden.com) | C20: SEO Implication / Opportunity | D20: Priority
A21: Site architecture | B21: Navigation exposes only Home and Contact. Every service is described on a single homepage; there are no service, location, pricing, FAQ, about or blog pages. | C21: No dedicated URLs to rank for service + city queries. This is the single biggest ceiling on organic growth. | D21: Critical
A22: Current keyword targeting | B22: Title tag: 'Southern Smiles Dental Center | Dental Office & Dentures Gadsden'. H2 'Same Day Dentures Gadsden, AL'; H3s 'Affordable Dentist Near Gadsden' and 'Dentist Gadsden, AL'. | C22: Several intents compete on one URL and the H1 is brand-only. Split intents into dedicated pages and keep the homepage focused on 'dentist Gadsden AL'. | D22: High
A23: Existing strengths | B23: On-site denture lab; free denture adjustments; same-day dentures; 'almost any insurance'; click-to-call; consistent NAP; service-area list of 11 towns. | C23: Strong, citeable differentiators - expand into pages, FAQs and schema so AI search engines can quote them. | D23: Leverage
A24: Pricing transparency | B24: No prices on the main site. The legacy domain publishes a full price sheet (crowns, root canals, extractions, cleaning, same-day dentures, partials, Six Month Smiles). | C24: Cost queries are high-converting. Publish a verified fee schedule (confirm current pricing with client before launch). | D24: High
A25: Legacy domain | B25: southernsmilesdentalcenter.com is live with the same address and phone number. | C25: Split brand signals and duplicate NAP. 301-redirect to the main domain after migrating useful content. | D25: High
A26: Trust / E-E-A-T | B26: 'Dr Morrison' is named without full name, credentials or photo. No reviews page. Meta description claims 'A+' without on-page proof. | C26: Add provider bio, credentials, patient reviews and verifiable trust signals. | D26: High
A27: Image alt text | B27: Hero slider images carry alt/title text 'Drain Cleaning Plumber SL2/SL3' (template leftovers). | C27: Irrelevant on-page signals - replace with descriptive dental alt text. | D27: Medium
A28: Office hours | B28: Open Mon-Wed only; closed Thursday-Sunday. | C28: Limits emergency/walk-in/weekend capture. Set expectations in content and GBP before targeting emergency keywords. | D28: High
A29: Content & AI search | B29: No blog, FAQ or resource content. | C29: Missing TOFU/MOFU coverage and AI-citeable Q&A. Build an FAQ page and supporting articles per silo. | D29: High
A30: Technical / GBP | B30: Schema, Core Web Vitals and Google Business Profile were not audited in this deliverable. | C30: Recommend a separate technical + GBP audit alongside this keyword plan. | D30: Medium
A33: SCORING METHODOLOGY
A34: Scoring Factor | B34: Weight (editable) | C34: Definition | D34: Status
A35: Business Value Score (1-5) | B35: 0.25 | C35: Revenue/lead/appointment value of the keyword
A36: Search Demand Score (1-5) | B36: 0.15 | C36: Market-relative demand. Local/Regional: 1 <20 | 2 20-49 | 3 50-119 | 4 120-249 | 5 250+ monthly searches. National: 1 <300 | 2 300-999 | 3 1,000-2,999 | 4 3,000-9,999 | 5 10,000+
A37: Ranking Opportunity Score (1-5) | B37: 0.2 | C37: Realistic ranking chance from KD (5: KD<=15 | 4: <=25 | 3: <=35 | 2: <=50 | 1: >50)
A38: Intent Strength Score (1-5) | B38: 0.15 | C38: How close the searcher is to acting
A39: Conversion Potential Score (1-5) | B39: 0.15 | C39: Likelihood of producing a call, booking or lead
A40: Topical Importance Score (1-5) | B40: 0.1 | C40: Importance for building authority around dentistry/dentures in Gadsden
A41: Weight check (must equal 100%) | B41: =SUM(B35:B40) -> 1 | C41: SEO Priority Score = weighted average of the six scores / 5 x 100
A43: Priority Level | B43: Score Range | C43: Meaning | D43: Status
A44: Critical | B44: 90-100 | C44: Build/optimize first - highest revenue and ranking potential
A45: High | B45: 75-89 | C45: Core targets for Months 1-3
A46: Medium | B46: 60-74 | C46: Supporting pages and secondary targets
A47: Low | B47: 40-59 | C47: Topical-authority and long-tail support content
A48: Optional | B48: Below 40 | C48: Monitor or pursue opportunistically

Sheet Keyword Master Database
A1: Keyword | B1: Keyword Type | C1: Parent Topic | D1: Cluster | E1: Search Intent | F1: Funnel Stage | G1: Primary/Secondary | H1: Search Volume | I1: Volume Source | J1: Estimated KD | K1: KD Source | L1: Estimated CPC | M1: CPC Source | N1: SERP Competition | O1: Ranking Competitors | P1: Business Value Score (1-5) | Q1: Search Demand Score (1-5) | R1: Ranking Opportunity Score (1-5) | S1: Intent Strength Score (1-5) | T1: Conversion Potential Score (1-5) | U1: Topical Importance Score (1-5) | V1: SEO Priority Score | W1: Priority Level | X1: Target URL | Y1: Recommended Action | Z1: Notes | AA1: Geo Scope
A2: dentist gadsden al | B2: Core Service | C2: Dentist Gadsden AL | D2: Local Dentist - Gadsden (Core) | E2: Transactional | F2: BOFU | G2: Primary | H2: 390 | I2: SEO Market Estimate | J2: 25 | K2: SERP Competition Analysis | L2: 7.8 | M2: Commercial Intent Analysis | N2: =IF(J2<=20,"Easy",IF(J2<=40,"Moderate",IF(J2<=70,"Competitive","Very Competitive"))) -> Moderate | O2: Gadsden Dental; Gadsden Family Dentistry; Aspen Dental | P2: 5 | Q2: 5 | R2: 4 | S2: 5 | T2: 5 | U2: 5 | V2: =ROUND((P2*'Business Analysis'!$B$35+Q2*'Business Analysis'!$B$36+R2*'Business Analysis'!$B$37+S2*'Business Analysis'!$B$38+T2*'Business Analysis'!$B$39+U2*'Business Analysis'!$B$40)/5*100,0) -> 96 | W2: =IF(V2>=90,"Critical",IF(V2>=75,"High",IF(V2>=60,"Medium",IF(V2>=40,"Low","Optional")))) -> Critical | X2: / | Y2: Optimize | Z2: Homepage primary - align title tag, H1 and intro copy | AA2: Local
A3: dentist in gadsden alabama | B3: Core Service | C3: Dentist Gadsden AL | D3: Local Dentist - Gadsden (Core) | E3: Transactional | F3: BOFU | G3: Secondary | H3: 260 | I3: SEO Market Estimate | J3: 26 | K3: SERP Competition Analysis | L3: 7.4 | M3: Commercial Intent Analysis | N3: =IF(J3<=20,"Easy",IF(J3<=40,"Moderate",IF(J3<=70,"Competitive","Very Competitive"))) -> Moderate | O3: Gadsden Dental; Gadsden Family Dentistry; Aspen Dental | P3: 5 | Q3: 5 | R3: 3 | S3: 5 | T3: 5 | U3: 5 | V3: =ROUND((P3*'Business Analysis'!$B$35+Q3*'Business Analysis'!$B$36+R3*'Business Analysis'!$B$37+S3*'Business Analysis'!$B$38+T3*'Business Analysis'!$B$39+U3*'Business Analysis'!$B$40)/5*100,0) -> 92 | W3: =IF(V3>=90,"Critical",IF(V3>=75,"High",IF(V3>=60,"Medium",IF(V3>=40,"Low","Optional")))) -> Critical | X3: / | Y3: Optimize | Z3: High-intent local conversion keyword | AA3: Local
A4: gadsden dentist | B4: Core Service | C4: Dentist Gadsden AL | D4: Local Dentist - Gadsden (Core) | E4: Transactional | F4: BOFU | G4: Secondary | H4: 210 | I4: SEO Market Estimate | J4: 24 | K4: SERP Competition Analysis | L4: 7.1 | M4: Commercial Intent Analysis | N4: =IF(J4<=20,"Easy",IF(J4<=40,"Moderate",IF(J4<=70,"Competitive","Very Competitive"))) -> Moderate | O4: Gadsden Dental; Gadsden Family Dentistry; Aspen Dental | P4: 5 | Q4: 4 | R4: 4 | S4: 5 | T4: 5 | U4: 5 | V4: =ROUND((P4*'Business Analysis'!$B$35+Q4*'Business Analysis'!$B$36+R4*'Business Analysis'!$B$37+S4*'Business Analysis'!$B$38+T4*'Business Analysis'!$B$39+U4*'Business Analysis'!$B$40)/5*100,0) -> 93 | W4: =IF(V4>=90,"Critical",IF(V4>=75,"High",IF(V4>=60,"Medium",IF(V4>=40,"Low","Optional")))) -> Critical | X4: / | Y4: Optimize | Z4: High-intent local conversion keyword | AA4: Local
A5: dentists in gadsden al | B5: Commercial | C5: Dentist Gadsden AL | D5: Local Dentist - Gadsden (Core) | E5: Commercial | F5: MOFU | G5: Secondary | H5: 260 | I5: SEO Market Estimate | J5: 27 | K5: SERP Competition Analysis | L5: 6.9 | M5: Commercial Intent Analysis | N5: =IF(J5<=20,"Easy",IF(J5<=40,"Moderate",IF(J5<=70,"Competitive","Very Competitive"))) -> Moderate | O5: Gadsden Dental; Gadsden Family Dentistry; Aspen Dental | P5: 5 | Q5: 5 | R5: 3 | S5: 4 | T5: 4 | U5: 5 | V5: =ROUND((P5*'Business Analysis'!$B$35+Q5*'Business Analysis'!$B$36+R5*'Business Analysis'!$B$37+S5*'Business Analysis'!$B$38+T5*'Business Analysis'!$B$39+U5*'Business Analysis'!$B$40)/5*100,0) -> 86 | W5: =IF(V5>=90,"Critical",IF(V5>=75,"High",IF(V5>=60,"Medium",IF(V5>=40,"Low","Optional")))) -> High | X5: / | Y5: Optimize | Z5: Local research query - support with reviews and transparent pricing | AA5: Local
A6: best dentist in gadsden al | B6: Commercial | C6: Dentist Gadsden AL | D6: Local Dentist - Gadsden (Core) | E6: Commercial | F6: MOFU | G6: Secondary | H6: 170 | I6: SEO Market Estimate | J6: 30 | K6: SERP Competition Analysis | L6: 7.2 | M6: Commercial Intent Analysis | N6: =IF(J6<=20,"Easy",IF(J6<=40,"Moderate",IF(J6<=70,"Competitive","Very Competitive"))) -> Moderate | O6: Gadsden Dental; Gadsden Family Dentistry; Aspen Dental | P6: 5 | Q6: 4 | R6: 3 | S6: 4 | T6: 4 | U6: 5 | V6: =ROUND((P6*'Business Analysis'!$B$35+Q6*'Business Analysis'!$B$36+R6*'Business Analysis'!$B$37+S6*'Business Analysis'!$B$38+T6*'Business Analysis'!$B$39+U6*'Business Analysis'!$B$40)/5*100,0) -> 83 | W6: =IF(V6>=90,"Critical",IF(V6>=75,"High",IF(V6>=60,"Medium",IF(V6>=40,"Low","Optional")))) -> High | X6: / | Y6: Optimize | Z6: Support with reviews, provider bio and schema | AA6: Local
A7: top rated dentist gadsden al | B7: Commercial | C7: Dentist Gadsden AL | D7: Local Dentist - Gadsden (Core) | E7: Commercial | F7: MOFU | G7: Secondary | H7: 70 | I7: SEO Market Estimate | J7: 26 | K7: SERP Competition Analysis | L7: 6.8 | M7: Commercial Intent Analysis | N7: =IF(J7<=20,"Easy",IF(J7<=40,"Moderate",IF(J7<=70,"Competitive","Very Competitive"))) -> Moderate | O7: Gadsden Dental; Gadsden Family Dentistry; Aspen Dental | P7: 5 | Q7: 3 | R7: 3 | S7: 4 | T7: 4 | U7: 5 | V7: =ROUND((P7*'Business Analysis'!$B$35+Q7*'Business Analysis'!$B$36+R7*'Business Analysis'!$B$37+S7*'Business Analysis'!$B$38+T7*'Business Analysis'!$B$39+U7*'Business Analysis'!$B$40)/5*100,0) -> 80 | W7: =IF(V7>=90,"Critical",IF(V7>=75,"High",IF(V7>=60,"Medium",IF(V7>=40,"Low","Optional")))) -> High | X7: / | Y7: Optimize | Z7: Local research query - support with reviews and transparent pricing | AA7: Local
A8: dental office gadsden al | B8: Core Service | C8: Dentist Gadsden AL | D8: Local Dentist - Gadsden (Core) | E8: Transactional | F8: BOFU | G8: Secondary | H8: 140 | I8: SEO Market Estimate | J8: 22 | K8: SERP Competition Analysis | L8: 7 | M8: Commercial Intent Analysis | N8: =IF(J8<=20,"Easy",IF(J8<=40,"Moderate",IF(J8<=70,"Competitive","Very Competitive"))) -> Moderate | O8: Gadsden Dental; Gadsden Family Dentistry; Aspen Dental | P8: 5 | Q8: 4 | R8: 4 | S8: 5 | T8: 5 | U8: 5 | V8: =ROUND((P8*'Business Analysis'!$B$35+Q8*'Business Analysis'!$B$36+R8*'Business Analysis'!$B$37+S8*'Business Analysis'!$B$38+T8*'Business Analysis'!$B$39+U8*'Business Analysis'!$B$40)/5*100,0) -> 93 | W8: =IF(V8>=90,"Critical",IF(V8>=75,"High",IF(V8>=60,"Medium",IF(V8>=40,"Low","Optional")))) -> Critical | X8: / | Y8: Optimize | Z8: High-intent local conversion keyword | AA8: Local
A9: dental clinic gadsden al | B9: Core Service | C9: Dentist Gadsden AL | D9: Local Dentist - Gadsden (Core) | E9: Transactional | F9: BOFU | G9: Secondary | H9: 60 | I9: SEO Market Estimate | J9: 20 | K9: SERP Competition Analysis | L9: 6.5 | M9: Commercial Intent Analysis | N9: =IF(J9<=20,"Easy",IF(J9<=40,"Moderate",IF(J9<=70,"Competitive","Very Competitive"))) -> Easy | O9: Gadsden Dental; Gadsden Family Dentistry; Aspen Dental | P9: 5 | Q9: 3 | R9: 4 | S9: 5 | T9: 5 | U9: 5 | V9: =ROUND((P9*'Business Analysis'!$B$35+Q9*'Business Analysis'!$B$36+R9*'Business Analysis'!$B$37+S9*'Business Analysis'!$B$38+T9*'Business Analysis'!$B$39+U9*'Business Analysis'!$B$40)/5*100,0) -> 90 | W9: =IF(V9>=90,"Critical",IF(V9>=75,"High",IF(V9>=60,"Medium",IF(V9>=40,"Low","Optional")))) -> Critical | X9: / | Y9: Optimize | Z9: High-intent local conversion keyword | AA9: Local
A10: general dentist gadsden al | B10: Core Service | C10: Dentist Gadsden AL | D10: Local Dentist - Gadsden (Core) | E10: Transactional | F10: BOFU | G10: Secondary | H10: 90 | I10: SEO Market Estimate | J10: 23 | K10: SERP Competition Analysis | L10: 6.9 | M10: Commercial Intent Analysis | N10: =IF(J10<=20,"Easy",IF(J10<=40,"Moderate",IF(J10<=70,"Competitive","Very Competitive"))) -> Moderate | O10: Gadsden Dental; Gadsden Family Dentistry; Aspen Dental | P10: 5 | Q10: 3 | R10: 4 | S10: 5 | T10: 5 | U10: 5 | V10: =ROUND((P10*'Business Analysis'!$B$35+Q10*'Business Analysis'!$B$36+R10*'Business Analysis'!$B$37+S10*'Business Analysis'!$B$38+T10*'Business Analysis'!$B$39+U10*'Business Analysis'!$B$40)/5*100,0) -> 90 | W10: =IF(V10>=90,"Critical",IF(V10>=75,"High",IF(V10>=60,"Medium",IF(V10>=40,"Low","Optional")))) -> Critical | X10: / | Y10: Optimize | Z10: High-intent local conversion keyword | AA10: Local
A11: dentist near me gadsden al | B11: Transactional | C11: Dentist Gadsden AL | D11: Local Dentist - Gadsden (Core) | E11: Transactional | F11: BOFU | G11: Secondary | H11: 90 | I11: SEO Market Estimate | J11: 28 | K11: SERP Competition Analysis | L11: 8.1 | M11: Commercial Intent Analysis | N11: =IF(J11<=20,"Easy",IF(J11<=40,"Moderate",IF(J11<=70,"Competitive","Very Competitive"))) -> Moderate | O11: Gadsden Dental; Gadsden Family Dentistry; Aspen Dental | P11: 5 | Q11: 3 | R11: 3 | S11: 5 | T11: 5 | U11: 5 | V11: =ROUND((P11*'Business Analysis'!$B$35+Q11*'Business Analysis'!$B$36+R11*'Business Analysis'!$B$37+S11*'Business Analysis'!$B$38+T11*'Business Analysis'!$B$39+U11*'Business Analysis'!$B$40)/5*100,0) -> 86 | W11: =IF(V11>=90,"Critical",IF(V11>=75,"High",IF(V11>=60,"Medium",IF(V11>=40,"Low","Optional")))) -> High | X11: / | Y11: Optimize | Z11: Pair with Google Business Profile optimization | AA11: Local
A12: dentist accepting new patients gadsden al | B12: Transactional | C12: Dentist Gadsden AL | D12: Local Dentist - Gadsden (Core) | E12: Transactional | F12: BOFU | G12: Primary | H12: 70 | I12: SEO Market Estimate | J12: 19 | K12: SERP Competition Analysis | L12: 7.5 | M12: Commercial Intent Analysis | N12: =IF(J12<=20,"Easy",IF(J12<=40,"Moderate",IF(J12<=70,"Competitive","Very Competitive"))) -> Easy | O12: Gadsden Dental; Gadsden Family Dentistry; Aspen Dental | P12: 5 | Q12: 3 | R12: 4 | S12: 5 | T12: 5 | U12: 5 | V12: =ROUND((P12*'Business Analysis'!$B$35+Q12*'Business Analysis'!$B$36+R12*'Business Analysis'!$B$37+S12*'Business Analysis'!$B$38+T12*'Business Analysis'!$B$39+U12*'Business Analysis'!$B$40)/5*100,0) -> 90 | W12: =IF(V12>=90,"Critical",IF(V12>=75,"High",IF(V12>=60,"Medium",IF(V12>=40,"Low","Optional")))) -> Critical | X12: /new-patients/ | Y12: Create | Z12: High-intent local conversion keyword | AA12: Local
A13: new patient dentist gadsden al | B13: Transactional | C13: Dentist Gadsden AL | D13: Local Dentist - Gadsden (Core) | E13: Transactional | F13: BOFU | G13: Secondary | H13: 50 | I13: SEO Market Estimate | J13: 18 | K13: SERP Competition Analysis | L13: 7.2 | M13: Commercial Intent Analysis | N13: =IF(J13<=20,"Easy",IF(J13<=40,"Moderate",IF(J13<=70,"Competitive","Very Competitive"))) -> Easy | O13: Gadsden Dental; Gadsden Family Dentistry; Aspen Dental | P13: 5 | Q13: 3 | R13: 4 | S13: 5 | T13: 5 | U13: 5 | V13: =ROUND((P13*'Business Analysis'!$B$35+Q13*'Business Analysis'!$B$36+R13*'Business Analysis'!$B$37+S13*'Business Analysis'!$B$38+T13*'Business Analysis'!$B$39+U13*'Business Analysis'!$B$40)/5*100,0) -> 90 | W13: =IF(V13>=90,"Critical",IF(V13>=75,"High",IF(V13>=60,"Medium",IF(V13>=40,"Low","Optional")))) -> Critical | X13: /new-patients/ | Y13: Create | Z13: High-intent local conversion keyword | AA13: Local
... A218: dental office with on-site lab | B218: Semantic | C218: Southern Smiles Brand | D218: Brand & Navigational | E218: Commercial | F218: MOFU | G218: Primary | H218: 30 | I218: SEO Market Estimate | J218: 12 | K218: SERP Competition Analysis | L218: 6.2 | M218: Commercial Intent Analysis | N218: =IF(J218<=20,"Easy",IF(J218<=40,"Moderate",IF(J218<=70,"Competitive","Very Competitive"))) -> Easy | O218: Aspen Dental; Healthline; Delta Dental; Colgate | P218: 3 | Q218: 1 | R218: 5 | S218: 3 | T218: 2 | U218: 3 | V218: =ROUND((P218*'Business Analysis'!$B$35+Q218*'Business Analysis'!$B$36+R218*'Business Analysis'!$B$37+S218*'Business Analysis'!$B$38+T218*'Business Analysis'!$B$39+U218*'Business Analysis'!$B$40)/5*100,0) -> 59 | W218: =IF(V218>=90,"Critical",IF(V218>=75,"High",IF(V218>=60,"Medium",IF(V218>=40,"Low","Optional")))) -> Low | X218: /about/ | Y218: Create | Z218: Cost/comparison research - answer with Gadsden-specific pricing context | AA218: National
A219: aspen dental gadsden al | B219: Competitor Brand | C219: Competitor Brands | D219: Competitor Brand (Monitor Only) | E219: Navigational | F219: BOFU | G219: Secondary | H219: 1300 | I219: SEO Market Estimate | J219: 38 | K219: SERP Competition Analysis | L219: 6.1 | M219: Commercial Intent Analysis | N219: =IF(J219<=20,"Easy",IF(J219<=40,"Moderate",IF(J219<=70,"Competitive","Very Competitive"))) -> Moderate | O219: Competitor's own site; Facebook; Yelp | P219: 1 | Q219: 5 | R219: 2 | S219: 2 | T219: 1 | U219: 1 | V219: =ROUND((P219*'Business Analysis'!$B$35+Q219*'Business Analysis'!$B$36+R219*'Business Analysis'!$B$37+S219*'Business Analysis'!$B$38+T219*'Business Analysis'!$B$39+U219*'Business Analysis'!$B$40)/5*100,0) -> 39 | W219: =IF(V219>=90,"Critical",IF(V219>=75,"High",IF(V219>=60,"Medium",IF(V219>=40,"Low","Optional")))) -> Optional | Y219: Monitor | Z219: Competitor brand - monitor only; no dedicated page | AA219: Local
A220: alabama family dentistry gadsden | B220: Competitor Brand | C220: Competitor Brands | D220: Competitor Brand (Monitor Only) | E220: Navigational | F220: BOFU | G220: Secondary | H220: 170 | I220: SEO Market Estimate | J220: 15 | K220: SERP Competition Analysis | L220: 4.2 | M220: Commercial Intent Analysis | N220: =IF(J220<=20,"Easy",IF(J220<=40,"Moderate",IF(J220<=70,"Competitive","Very Competitive"))) -> Easy | O220: Competitor's own site; Facebook; Yelp | P220: 1 | Q220: 4 | R220: 5 | S220: 2 | T220: 1 | U220: 1 | V220: =ROUND((P220*'Business Analysis'!$B$35+Q220*'Business Analysis'!$B$36+R220*'Business Analysis'!$B$37+S220*'Business Analysis'!$B$38+T220*'Business Analysis'!$B$39+U220*'Business Analysis'!$B$40)/5*100,0) -> 48 | W220: =IF(V220>=90,"Critical",IF(V220>=75,"High",IF(V220>=60,"Medium",IF(V220>=40,"Low","Optional")))) -> Low | Y220: Monitor | Z220: Competitor brand - monitor only; no dedicated page | AA220: Local
A221: gadsden family dentistry | B221: Competitor Brand | C221: Competitor Brands | D221: Competitor Brand (Monitor Only) | E221: Navigational | F221: BOFU | G221: Secondary | H221: 110 | I221: SEO Market Estimate | J221: 14 | K221: SERP Competition Analysis | L221: 4 | M221: Commercial Intent Analysis | N221: =IF(J221<=20,"Easy",IF(J221<=40,"Moderate",IF(J221<=70,"Competitive","Very Competitive"))) -> Easy | O221: Competitor's own site; Facebook; Yelp | P221: 1 | Q221: 3 | R221: 5 | S221: 2 | T221: 1 | U221: 1 | V221: =ROUND((P221*'Business Analysis'!$B$35+Q221*'Business Analysis'!$B$36+R221*'Business Analysis'!$B$37+S221*'Business Analysis'!$B$38+T221*'Business Analysis'!$B$39+U221*'Business Analysis'!$B$40)/5*100,0) -> 45 | W221: =IF(V221>=90,"Critical",IF(V221>=75,"High",IF(V221>=60,"Medium",IF(V221>=40,"Low","Optional")))) -> Low | Y221: Monitor | Z221: Competitor brand - monitor only; no dedicated page | AA221: Local
A222: coosa family dentistry gadsden al | B222: Competitor Brand | C222: Competitor Brands | D222: Competitor Brand (Monitor Only) | E222: Navigational | F222: BOFU | G222: Secondary | H222: 60 | I222: SEO Market Estimate | J222: 10 | K222: SERP Competition Analysis | L222: 3.8 | M222: Commercial Intent Analysis | N222: =IF(J222<=20,"Easy",IF(J222<=40,"Moderate",IF(J222<=70,"Competitive","Very Competitive"))) -> Easy | O222: Competitor's own site; Facebook; Yelp | P222: 1 | Q222: 3 | R222: 5 | S222: 2 | T222: 1 | U222: 1 | V222: =ROUND((P222*'Business Analysis'!$B$35+Q222*'Business Analysis'!$B$36+R222*'Business Analysis'!$B$37+S222*'Business Analysis'!$B$38+T222*'Business Analysis'!$B$39+U222*'Business Analysis'!$B$40)/5*100,0) -> 45 | W222: =IF(V222>=90,"Critical",IF(V222>=75,"High",IF(V222>=60,"Medium",IF(V222>=40,"Low","Optional")))) -> Low | Y222: Monitor | Z222: Competitor brand - monitor only; no dedicated page | AA222: Local
A223: legacy dental alabama | B223: Competitor Brand | C223: Competitor Brands | D223: Competitor Brand (Monitor Only) | E223: Navigational | F223: BOFU | G223: Secondary | H223: 90 | I223: SEO Market Estimate | J223: 12 | K223: SERP Competition Analysis | L223: 3.5 | M223: Commercial Intent Analysis | N223: =IF(J223<=20,"Easy",IF(J223<=40,"Moderate",IF(J223<=70,"Competitive","Very Competitive"))) -> Easy | O223: Competitor's own site; Facebook; Yelp | P223: 1 | Q223: 3 | R223: 5 | S223: 2 | T223: 1 | U223: 1 | V223: =ROUND((P223*'Business Analysis'!$B$35+Q223*'Business Analysis'!$B$36+R223*'Business Analysis'!$B$37+S223*'Business Analysis'!$B$38+T223*'Business Analysis'!$B$39+U223*'Business Analysis'!$B$40)/5*100,0) -> 45 | W223: =IF(V223>=90,"Critical",IF(V223>=75,"High",IF(V223>=60,"Medium",IF(V223>=40,"Low","Optional")))) -> Low | Y223: Monitor | Z223: Competitor brand - monitor only; no dedicated page | AA223: Regional
A224: clay ellis dds gadsden al | B224: Competitor Brand | C224: Competitor Brands | D224: Competitor Brand (Monitor Only) | E224: Navigational | F224: BOFU | G224: Secondary | H224: 50 | I224: SEO Market Estimate | J224: 10 | K224: SERP Competition Analysis | L224: 3.2 | M224: Commercial Intent Analysis | N224: =IF(J224<=20,"Easy",IF(J224<=40,"Moderate",IF(J224<=70,"Competitive","Very Competitive"))) -> Easy | O224: Competitor's own site; Facebook; Yelp | P224: 1 | Q224: 3 | R224: 5 | S224: 2 | T224: 1 | U224: 1 | V224: =ROUND((P224*'Business Analysis'!$B$35+Q224*'Business Analysis'!$B$36+R224*'Business Analysis'!$B$37+S224*'Business Analysis'!$B$38+T224*'Business Analysis'!$B$39+U224*'Business Analysis'!$B$40)/5*100,0) -> 45 | W224: =IF(V224>=90,"Critical",IF(V224>=75,"High",IF(V224>=60,"Medium",IF(V224>=40,"Low","Optional")))) -> Low | Y224: Monitor | Z224: Competitor brand - monitor only; no dedicated page | AA224: Local
A225: best affordable dentist in gadsden alabama | B225: AI Search (Conversational) | C225: AI Search Visibility | D225: AI Search - Conversational Queries | E225: Commercial | F225: MOFU | G225: Secondary | H225: 20 | I225: SEO Market Estimate | J225: 12 | K225: SERP Competition Analysis | L225: 6.2 | M225: Commercial Intent Analysis | N225: =IF(J225<=20,"Easy",IF(J225<=40,"Moderate",IF(J225<=70,"Competitive","Very Competitive"))) -> Easy | O225: Aspen Dental; Coosa Family Dentistry; Alabama Family Dentistry | P225: 4 | Q225: 2 | R225: 5 | S225: 4 | T225: 4 | U225: 4 | V225: =ROUND((P225*'Business Analysis'!$B$35+Q225*'Business Analysis'!$B$36+R225*'Business Analysis'!$B$37+S225*'Business Analysis'!$B$38+T225*'Business Analysis'!$B$39+U225*'Business Analysis'!$B$40)/5*100,0) -> 78 | W225: =IF(V225>=90,"Critical",IF(V225>=75,"High",IF(V225>=60,"Medium",IF(V225>=40,"Low","Optional")))) -> High | X225: /affordable-dentist-gadsden-al/ | Y225: Create | Z225: Local research query - support with reviews and transparent pricing | AA225: Local
A226: where can i get dentures in one day in alabama | B226: AI Search (Conversational) | C226: AI Search Visibility | D226: AI Search - Conversational Queries | E226: Transactional | F226: BOFU | G226: Secondary | H226: 30 | I226: SEO Market Estimate | J226: 18 | K226: SERP Competition Analysis | L226: 9.1 | M226: Commercial Intent Analysis | N226: =IF(J226<=20,"Easy",IF(J226<=40,"Moderate",IF(J226<=70,"Competitive","Very Competitive"))) -> Easy | O226: Aspen Dental; Coosa Family Dentistry; Alabama Family Dentistry | P226: 4 | Q226: 2 | R226: 4 | S226: 5 | T226: 4 | U226: 4 | V226: =ROUND((P226*'Business Analysis'!$B$35+Q226*'Business Analysis'!$B$36+R226*'Business Analysis'!$B$37+S226*'Business Analysis'!$B$38+T226*'Business Analysis'!$B$39+U226*'Business Analysis'!$B$40)/5*100,0) -> 77 | W226: =IF(V226>=90,"Critical",IF(V226>=75,"High",IF(V226>=60,"Medium",IF(V226>=40,"Low","Optional")))) -> High | X226: /same-day-dentures-gadsden-al/ | Y226: Create | Z226: Regional high-intent term - supports same-day denture positioning | AA226: Regional
A227: who makes same day dentures near gadsden al | B227: AI Search (Conversational) | C227: AI Search Visibility | D227: AI Search - Conversational Queries | E227: Transactional | F227: BOFU | G227: Secondary | H227: 20 | I227: SEO Market Estimate | J227: 12 | K227: SERP Competition Analysis | L227: 9 | M227: Commercial Intent Analysis | N227: =IF(J227<=20,"Easy",IF(J227<=40,"Moderate",IF(J227<=70,"Competitive","Very Competitive"))) -> Easy | O227: Aspen Dental; Coosa Family Dentistry; Alabama Family Dentistry | P227: 4 | Q227: 2 | R227: 5 | S227: 5 | T227: 5 | U227: 4 | V227: =ROUND((P227*'Business Analysis'!$B$35+Q227*'Business Analysis'!$B$36+R227*'Business Analysis'!$B$37+S227*'Business Analysis'!$B$38+T227*'Business Analysis'!$B$39+U227*'Business Analysis'!$B$40)/5*100,0) -> 84 | W227: =IF(V227>=90,"Critical",IF(V227>=75,"High",IF(V227>=60,"Medium",IF(V227>=40,"Low","Optional")))) -> High | X227: /same-day-dentures-gadsden-al/ | Y227: Create | Z227: High-intent local conversion keyword | AA227: Local
A228: how much do same day dentures cost in alabama | B228: AI Search (Conversational) | C228: AI Search Visibility | D228: AI Search - Conversational Queries | E228: Commercial | F228: MOFU | G228: Secondary | H228: 40 | I228: SEO Market Estimate | J228: 20 | K228: SERP Competition Analysis | L228: 8.2 | M228: Commercial Intent Analysis | N228: =IF(J228<=20,"Easy",IF(J228<=40,"Moderate",IF(J228<=70,"Competitive","Very Competitive"))) -> Easy | O228: Aspen Dental; Coosa Family Dentistry; Alabama Family Dentistry | P228: 4 | Q228: 2 | R228: 4 | S228: 3 | T228: 3 | U228: 4 | V228: =ROUND((P228*'Business Analysis'!$B$35+Q228*'Business Analysis'!$B$36+R228*'Business Analysis'!$B$37+S228*'Business Analysis'!$B$38+T228*'Business Analysis'!$B$39+U228*'Business Analysis'!$B$40)/5*100,0) -> 68 | W228: =IF(V228>=90,"Critical",IF(V228>=75,"High",IF(V228>=60,"Medium",IF(V228>=40,"Low","Optional")))) -> Medium | X228: /denture-cost-gadsden-al/ | Y228: Create | Z228: Cost/comparison research - answer with Gadsden-specific pricing context | AA228: Regional
A229: is there a dentist in gadsden that makes dentures on site | B229: AI Search (Conversational) | C229: AI Search Visibility | D229: AI Search - Conversational Queries | E229: Transactional | F229: BOFU | G229: Secondary | H229: 10 | I229: SEO Market Estimate | J229: 8 | K229: SERP Competition Analysis | L229: 8.4 | M229: Commercial Intent Analysis | N229: =IF(J229<=20,"Easy",IF(J229<=40,"Moderate",IF(J229<=70,"Competitive","Very Competitive"))) -> Easy | O229: Aspen Dental; Coosa Family Dentistry; Alabama Family Dentistry | P229: 4 | Q229: 1 | R229: 5 | S229: 5 | T229: 5 | U229: 4 | V229: =ROUND((P229*'Business Analysis'!$B$35+Q229*'Business Analysis'!$B$36+R229*'Business Analysis'!$B$37+S229*'Business Analysis'!$B$38+T229*'Business Analysis'!$B$39+U229*'Business Analysis'!$B$40)/5*100,0) -> 81 | W229: =IF(V229>=90,"Critical",IF(V229>=75,"High",IF(V229>=60,"Medium",IF(V229>=40,"Low","Optional")))) -> High | X229: /dentures-gadsden-al/ | Y229: Create | Z229: High-intent local conversion keyword | AA229: Local
A230: dentist in gadsden al that takes insurance and offers dentures | B230: AI Search (Conversational) | C230: AI Search Visibility | D230: AI Search - Conversational Queries | E230: Transactional | F230: BOFU | G230: Secondary | H230: 10 | I230: SEO Market Estimate | J230: 9 | K230: SERP Competition Analysis | L230: 8.6 | M230: Commercial Intent Analysis | N230: =IF(J230<=20,"Easy",IF(J230<=40,"Moderate",IF(J230<=70,"Competitive","Very Competitive"))) -> Easy | O230: Aspen Dental; Coosa Family Dentistry; Alabama Family Dentistry | P230: 4 | Q230: 1 | R230: 5 | S230: 5 | T230: 5 | U230: 4 | V230: =ROUND((P230*'Business Analysis'!$B$35+Q230*'Business Analysis'!$B$36+R230*'Business Analysis'!$B$37+S230*'Business Analysis'!$B$38+T230*'Business Analysis'!$B$39+U230*'Business Analysis'!$B$40)/5*100,0) -> 81 | W230: =IF(V230>=90,"Critical",IF(V230>=75,"High",IF(V230>=60,"Medium",IF(V230>=40,"Low","Optional")))) -> High | X230: /dental-insurance-accepted-gadsden-al/ | Y230: Create | Z230: High-intent local conversion keyword | AA230: Local
A231: which dentist near me can pull teeth and fit dentures same day | B231: AI Search (Conversational) | C231: AI Search Visibility | D231: AI Search - Conversational Queries | E231: Transactional | F231: BOFU | G231: Secondary | H231: 20 | I231: SEO Market Estimate | J231: 11 | K231: SERP Competition Analysis | L231: 9 | M231: Commercial Intent Analysis | N231: =IF(J231<=20,"Easy",IF(J231<=40,"Moderate",IF(J231<=70,"Competitive","Very Competitive"))) -> Easy | O231: Aspen Dental; Coosa Family Dentistry; Alabama Family Dentistry | P231: 4 | Q231: 2 | R231: 5 | S231: 5 | T231: 5 | U231: 4 | V231: =ROUND((P231*'Business Analysis'!$B$35+Q231*'Business Analysis'!$B$36+R231*'Business Analysis'!$B$37+S231*'Business Analysis'!$B$38+T231*'Business Analysis'!$B$39+U231*'Business Analysis'!$B$40)/5*100,0) -> 84 | W231: =IF(V231>=90,"Critical",IF(V231>=75,"High",IF(V231>=60,"Medium",IF(V231>=40,"Low","Optional")))) -> High | X231: /immediate-dentures-gadsden-al/ | Y231: Create | Z231: High-intent local conversion keyword | AA231: Local
A232: are denture adjustments free | B232: AI Search (Conversational) | C232: AI Search Visibility | D232: AI Search - Conversational Queries | E232: Informational | F232: MOFU | G232: Secondary | H232: 70 | I232: SEO Market Estimate | J232: 14 | K232: SERP Competition Analysis | L232: 2.8 | M232: Commercial Intent Analysis | N232: =IF(J232<=20,"Easy",IF(J232<=40,"Moderate",IF(J232<=70,"Competitive","Very Competitive"))) -> Easy | O232: Healthline; WebMD; Cleveland Clinic; Colgate | P232: 1 | Q232: 1 | R232: 5 | S232: 1 | T232: 1 | U232: 4 | V232: =ROUND((P232*'Business Analysis'!$B$35+Q232*'Business Analysis'!$B$36+R232*'Business Analysis'!$B$37+S232*'Business Analysis'!$B$38+T232*'Business Analysis'!$B$39+U232*'Business Analysis'!$B$40)/5*100,0) -> 42 | W232: =IF(V232>=90,"Critical",IF(V232>=75,"High",IF(V232>=60,"Medium",IF(V232>=40,"Low","Optional")))) -> Low | X232: /denture-repair-adjustments-gadsden-al/ | Y232: Create | Z232: Educational query - supporting content for topical authority and AI citations | AA232: National
A233: what dental services are available in gadsden al | B233: AI Search (Conversational) | C233: AI Search Visibility | D233: AI Search - Conversational Queries | E233: Informational | F233: MOFU | G233: Secondary | H233: 20 | I233: SEO Market Estimate | J233: 9 | K233: SERP Competition Analysis | L233: 3 | M233: Commercial Intent Analysis | N233: =IF(J233<=20,"Easy",IF(J233<=40,"Moderate",IF(J233<=70,"Competitive","Very Competitive"))) -> Easy | O233: Aspen Dental; Coosa Family Dentistry; Alabama Family Dentistry | P233: 2 | Q233: 2 | R233: 5 | S233: 1 | T233: 2 | U233: 4 | V233: =ROUND((P233*'Business Analysis'!$B$35+Q233*'Business Analysis'!$B$36+R233*'Business Analysis'!$B$37+S233*'Business Analysis'!$B$38+T233*'Business Analysis'!$B$39+U233*'Business Analysis'!$B$40)/5*100,0) -> 53 | W233: =IF(V233>=90,"Critical",IF(V233>=75,"High",IF(V233>=60,"Medium",IF(V233>=40,"Low","Optional")))) -> Low | X233: /faq/ | Y233: Create | Z233: Educational query - supporting content for topical authority and AI citations | AA233: Local
A234: gadsden dentist faq | B234: AI Search (Conversational) | C234: AI Search Visibility | D234: AI Search - Conversational Queries | E234: Informational | F234: TOFU | G234: Primary | H234: 10 | I234: SEO Market Estimate | J234: 5 | K234: SERP Competition Analysis | L234: 1.9 | M234: Commercial Intent Analysis | N234: =IF(J234<=20,"Easy",IF(J234<=40,"Moderate",IF(J234<=70,"Competitive","Very Competitive"))) -> Easy | O234: Aspen Dental; Coosa Family Dentistry; Alabama Family Dentistry | P234: 2 | Q234: 1 | R234: 5 | S234: 1 | T234: 2 | U234: 4 | V234: =ROUND((P234*'Business Analysis'!$B$35+Q234*'Business Analysis'!$B$36+R234*'Business Analysis'!$B$37+S234*'Business Analysis'!$B$38+T234*'Business Analysis'!$B$39+U234*'Business Analysis'!$B$40)/5*100,0) -> 50 | W234: =IF(V234>=90,"Critical",IF(V234>=75,"High",IF(V234>=60,"Medium",IF(V234>=40,"Low","Optional")))) -> Low | X234: /faq/ | Y234: Create | Z234: Educational query - supporting content for topical authority and AI citations | AA234: Local
A235: how to choose a dentist for dentures | B235: AI Search (Conversational) | C235: AI Search Visibility | D235: AI Search - Conversational Queries | E235: Commercial | F235: MOFU | G235: Primary | H235: 590 | I235: SEO Market Estimate | J235: 32 | K235: SERP Competition Analysis | L235: 3.9 | M235: Commercial Intent Analysis | N235: =IF(J235<=20,"Easy",IF(J235<=40,"Moderate",IF(J235<=70,"Competitive","Very Competitive"))) -> Moderate | O235: Aspen Dental; Healthline; Delta Dental; Colgate | P235: 2 | Q235: 2 | R235: 3 | S235: 3 | T235: 2 | U235: 4 | V235: =ROUND((P235*'Business Analysis'!$B$35+Q235*'Business Analysis'!$B$36+R235*'Business Analysis'!$B$37+S235*'Business Analysis'!$B$38+T235*'Business Analysis'!$B$39+U235*'Business Analysis'!$B$40)/5*100,0) -> 51 | W235: =IF(V235>=90,"Critical",IF(V235>=75,"High",IF(V235>=60,"Medium",IF(V235>=40,"Low","Optional")))) -> Low | X235: /blog/how-to-choose-a-denture-dentist/ | Y235: Create | Z235: Cost/comparison research - answer with Gadsden-specific pricing context | AA235: National
A236: best dentist for dentures near me | B236: AI Search (Conversational) | C236: AI Search Visibility | D236: AI Search - Conversational Queries | E236: Commercial | F236: MOFU | G236: Secondary | H236: 1300 | I236: SEO Market Estimate | J236: 46 | K236: SERP Competition Analysis | L236: 8.5 | M236: Commercial Intent Analysis | N236: =IF(J236<=20,"Easy",IF(J236<=40,"Moderate",IF(J236<=70,"Competitive","Very Competitive"))) -> Competitive | O236: Aspen Dental; Healthline; Delta Dental; Colgate | P236: 2 | Q236: 3 | R236: 2 | S236: 3 | T236: 2 | U236: 4 | V236: =ROUND((P236*'Business Analysis'!$B$35+Q236*'Business Analysis'!$B$36+R236*'Business Analysis'!$B$37+S236*'Business Analysis'!$B$38+T236*'Business Analysis'!$B$39+U236*'Business Analysis'!$B$40)/5*100,0) -> 50 | W236: =IF(V236>=90,"Critical",IF(V236>=75,"High",IF(V236>=60,"Medium",IF(V236>=40,"Low","Optional")))) -> Low | X236: /blog/how-to-choose-a-denture-dentist/ | Y236: Create | Z236: Cost/comparison research - answer with Gadsden-specific pricing context | AA236: National
... A242: how to sleep with new dentures | B242: Informational | C242: Dental Education | D242: Dental Health Education (TOFU) | E242: Informational | F242: TOFU | G242: Secondary | H242: 1900 | I242: SEO Market Estimate | J242: 28 | K242: SERP Competition Analysis | L242: 1.2 | M242: Commercial Intent Analysis | N242: =IF(J242<=20,"Easy",IF(J242<=40,"Moderate",IF(J242<=70,"Competitive","Very Competitive"))) -> Moderate | O242: Healthline; WebMD; Cleveland Clinic; Colgate | P242: 1 | Q242: 3 | R242: 3 | S242: 1 | T242: 1 | U242: 3 | V242: =ROUND((P242*'Business Analysis'!$B$35+Q242*'Business Analysis'!$B$36+R242*'Business Analysis'!$B$37+S242*'Business Analysis'!$B$38+T242*'Business Analysis'!$B$39+U242*'Business Analysis'!$B$40)/5*100,0) -> 38 | W242: =IF(V242>=90,"Critical",IF(V242>=75,"High",IF(V242>=60,"Medium",IF(V242>=40,"Low","Optional")))) -> Optional | X242: /blog/how-to-get-used-to-new-dentures/ | Y242: Create | Z242: Educational query - supporting content for topical authority and AI citations | AA242: National

Sheet Keyword Clusters
A1: Cluster Name | B1: Primary Keyword | C1: Secondary Keywords | D1: Questions | E1: Entities | F1: Intent | G1: Funnel Stage | H1: Recommended Page | I1: Page Type | J1: Keyword Count | K1: Est. Total Volume
A2: Local Dentist - Gadsden (Core) | B2: dentist gadsden al | C2: gadsden dentist; dental office gadsden al; dentist in gadsden alabama; general dentist gadsden al; dentist accepting new patients gadsden al; dental clinic gadsden al | D2: Who is the best dentist in Gadsden, AL?; Is there a dentist accepting new patients near me?; What dental services are available in Etowah County? | E2: Etowah County; Gadsden AL 35901; Dr. Morrison; 315 N 3rd St; Google Business Profile | F2: Transactional | G2: BOFU | H2: Homepage | I2: Homepage | J2: =COUNTIF('Keyword Master Database'!$D$2:$D$242,A2) -> 15 | K2: =SUMIF('Keyword Master Database'!$D$2:$D$242,A2,'Keyword Master Database'!$H$2:$H$242) -> 1831940
A3: Affordable & No-Insurance Dentistry | B3: affordable dentist gadsden al | C3: dentist no insurance gadsden al; dental prices gadsden al; cheap dentist gadsden al; low cost dental care gadsden al; affordable dental care alabama; cheap dental work near me | D3: How much is a dentist visit without insurance?; Where can I find an affordable dentist in Gadsden?; Is cheap dental care lower quality? | E3: Self-pay patients; fee schedule; dental insurance; affordable dentistry | F3: Commercial | G3: MOFU | H3: Affordable Dentist Gadsden AL (Hub) | I3: Hub Page | J3: =COUNTIF('Keyword Master Database'!$D$2:$D$242,A3) -> 11 | K3: =SUMIF('Keyword Master Database'!$D$2:$D$242,A3,'Keyword Master Database'!$H$2:$H$242) -> 38200
A4: Dentures - Core | B4: dentures gadsden al | C4: dentures near me gadsden al; denture dentist gadsden al; denture clinic gadsden al; full dentures gadsden al; custom dentures gadsden al; dentures alabama | D4: Where can I get dentures in Gadsden, AL?; What types of dentures are available?; Who makes dentures on-site? | E4: Full denture; acrylic; on-site denture lab; impressions; gum tissue | F4: Transactional | G4: BOFU | H4: Dentures Gadsden AL (Hub) | I4: Hub Page | J4: =COUNTIF('Keyword Master Database'!$D$2:$D$242,A4) -> 10 | K4: =SUMIF('Keyword Master Database'!$D$2:$D$242,A4,'Keyword Master Database'!$H$2:$H$242) -> 87570
A5: Same-Day Dentures | B5: same day dentures gadsden al | C5: dentures in one day gadsden al; same day dentures alabama; one day dentures alabama; same day dentures near me; 1 day dentures near me; are same day dentures good | D5: Can you really get dentures in one day?; How does the same-day denture process work?; Are same-day dentures as good as traditional? | E5: On-site dental lab; impressions; shade & mold; fitting appointment; follow-up adjustments | F5: Transactional | G5: BOFU | H5: Same-Day Dentures Gadsden AL | I5: Service Page | J5: =COUNTIF('Keyword Master Database'!$D$2:$D$242,A5) -> 10 | K5: =SUMIF('Keyword Master Database'!$D$2:$D$242,A5,'Keyword Master Database'!$H$2:$H$242) -> 18730
A6: Denture Cost & Pricing | B6: denture cost gadsden al | C6: same day dentures cost alabama; cheap dentures gadsden al; affordable dentures gadsden al; full set of dentures cost; how much do dentures cost; cheapest place to get dentures near me | D6: How much do dentures cost in Alabama?; Do dentures cost less without insurance?; What is the difference between standard, deluxe and custom dentures? | E6: Standard / deluxe / custom dentures; price per arch; insurance; adjustments included | F6: Transactional | G6: BOFU | H6: Denture Cost & Pricing Gadsden AL | I6: Service Page | J6: =COUNTIF('Keyword Master Database'!$D$2:$D$242,A6) -> 10 | K6: =SUMIF('Keyword Master Database'!$D$2:$D$242,A6,'Keyword Master Database'!$H$2:$H$242) -> 49310
A7: Partial Dentures | B7: partial dentures gadsden al | C7: partials dentist gadsden al; partial dentures near me; cast metal partial denture; partial denture cost; flexible partial dentures; flipper tooth cost | D7: What is a partial denture?; Flexible vs. cast metal partials?; Are acrylic flipper partials temporary? | E7: Cast metal partial; flexible partial; acrylic (flipper) partial; clasps; abutment teeth | F7: Transactional | G7: BOFU | H7: Partial Dentures Gadsden AL | I7: Service Page | J7: =COUNTIF('Keyword Master Database'!$D$2:$D$242,A7) -> 10 | K7: =SUMIF('Keyword Master Database'!$D$2:$D$242,A7,'Keyword Master Database'!$H$2:$H$242) -> 35690
A8: Immediate Dentures & Extraction + Dentures | B8: immediate dentures gadsden al | C8: teeth extraction and dentures same day gadsden al; immediate dentures near me; full mouth extraction and dentures same day; full mouth extraction cost; immediate dentures cost; what to expect with immediate dentures | D8: What is an immediate denture?; Can I get dentures the same day my teeth are pulled?; How long does healing take? | E8: Extractions; immediate dentures; gum healing; reline; surgical extraction | F8: Transactional | G8: BOFU | H8: Immediate Dentures & Extractions | I8: Service Page | J8: =COUNTIF('Keyword Master Database'!$D$2:$D$242,A8) -> 8 | K8: =SUMIF('Keyword Master Database'!$D$2:$D$242,A8,'Keyword Master Database'!$H$2:$H$242) -> 23050
A9: Denture Repair, Reline & Adjustments | B9: denture repair gadsden al | C9: denture reline gadsden al; denture adjustment gadsden al; free denture adjustments gadsden al; same day denture repair near me; denture repair near me; denture reline cost | D9: Are denture adjustments free?; How do I fix loose or broken dentures?; How much does a reline cost? | E9: Reline; rebase; repair; adjustment; on-site lab | F9: Transactional | G9: BOFU | H9: Denture Repair, Reline & Free Adjustments | I9: Service Page | J9: =COUNTIF('Keyword Master Database'!$D$2:$D$242,A9) -> 10 | K9: =SUMIF('Keyword Master Database'!$D$2:$D$242,A9,'Keyword Master Database'!$H$2:$H$242) -> 27980
A10: Denture Education & Comparisons | B10: how long do dentures last | C10: dentures vs implants; do i need dentures; how long does it take to get used to dentures; foods to eat with new dentures; how to clean dentures | D10: How long do dentures last?; How do I clean dentures?; Dentures or implants? | E10: Denture adhesive; denture cleaner; implants; bone loss; sore spots | F10: Informational | G10: TOFU | H10: Supporting blog posts under /blog/ (linked to parent service pages) | I10: Blog Cluster | J10: =COUNTIF('Keyword Master Database'!$D$2:$D$242,A10) -> 6 | K10: =SUMIF('Keyword Master Database'!$D$2:$D$242,A10,'Keyword Master Database'!$H$2:$H$242) -> 56900
A11: Dental Crowns | B11: dental crowns gadsden al | C11: dental crown cost gadsden al; crown dentist gadsden al; restorative dentistry gadsden al; dental crown near me; crown vs filling; how much does a dental crown cost | D11: How much is a dental crown?; What if my crown falls off?; Porcelain vs. zirconia crowns? | E11: Porcelain; zirconia; metal; tooth preparation; impression; temporary crown | F11: Transactional | G11: BOFU | H11: Dental Crowns Gadsden AL | I11: Service Page | J11: =COUNTIF('Keyword Master Database'!$D$2:$D$242,A11) -> 11 | K11: =SUMIF('Keyword Master Database'!$D$2:$D$242,A11,'Keyword Master Database'!$H$2:$H$242) -> 72390
A12: Dental Bridges | B12: dental bridge gadsden al | C12: replace missing tooth gadsden al; dental bridges near me; dental bridge vs implant; dental bridge cost; how much does a dental bridge cost; bridge vs partial denture | D12: Bridge vs. implant vs. partial denture?; How long do bridges last?; How much does a bridge cost? | E12: Pontic; abutment teeth; missing tooth; fixed bridge | F12: Transactional | G12: BOFU | H12: Dental Bridges Gadsden AL | I12: Service Page | J12: =COUNTIF('Keyword Master Database'!$D$2:$D$242,A12) -> 9 | K12: =SUMIF('Keyword Master Database'!$D$2:$D$242,A12,'Keyword Master Database'!$H$2:$H$242) -> 45160
A13: Root Canal Treatment | B13: root canal gadsden al | C13: root canal cost gadsden al; root canal dentist gadsden al; root canal near me; root canal vs extraction; root canal cost; root canal symptoms | D13: Is a root canal painful?; Root canal vs. extraction?; How long does a root canal take? | E13: Pulp; infection; abscess; endodontic treatment; crown after root canal | F13: Transactional | G13: BOFU | H13: Root Canal Treatment Gadsden AL | I13: Service Page | J13: =COUNTIF('Keyword Master Database'!$D$2:$D$242,A13) -> 11 | K13: =SUMIF('Keyword Master Database'!$D$2:$D$242,A13,'Keyword Master Database'!$H$2:$H$242) -> 135720
... A27: Dental Health Education (TOFU) | B27: how often should you go to the dentist | C27: how to prepare for a tooth extraction; how to sleep with new dentures; what causes tooth decay | D27: How often should I go to the dentist?; What causes tooth decay?; How do I prepare for an extraction? | E27: Tooth decay; plaque; extraction; recovery | F27: Informational | G27: TOFU | H27: Supporting blog posts under /blog/ (linked to parent service pages) | I27: Blog Cluster | J27: =COUNTIF('Keyword Master Database'!$D$2:$D$242,A27) -> 4 | K27: =SUMIF('Keyword Master Database'!$D$2:$D$242,A27,'Keyword Master Database'!$H$2:$H$242) -> 32300

Sheet Competitor Analysis
A1: Competitor | B1: URL | C1: Ranking Topics | D1: Strong Pages | E1: Weakness | F1: Content Gap | G1: Opportunity
A2: Gadsden Dental - K. Clay Ellis Jr., DMD | B2: https://gadsdenaldentist.com/ | C2: General & preventive dentistry; pediatric; fillings; crowns & bridges; root canals; extractions/oral surgery; implants; bite guards; Botox; insurance acceptance | D2: Single long page with three dentist bios (UAB/Auburn credentials, community free-clinic service) and a 16-plan insurance list - strong trust and insurance signals. | E2: Single-URL site on a dated theme; no separate service or location pages; no pricing; no blog/FAQ; Facebook link points to a different practice name. | F2: No denture, same-day denture, denture repair, cost/pricing or clear-aligner content; no location or FAQ pages. | G2: Out-rank with dedicated service pages for dentures, crowns, root canals and extractions; copy the trust pattern (provider credentials + insurance list) and add transparent pricing.
A3: Gadsden Family Dentistry | B3: https://www.gadsdenfamilydentist.com/ | C3: Family dentist Gadsden; teeth cleaning; dental implants; crowns; tooth extractions; emergency dental; cosmetic dentist; dentures (meta keywords). The parent Alabama Family Dentistry site has dedicated immediate-denture pages that mention Gadsden. | D3: Visible 5-star patient reviews on page, click-to-call, hours table; parent-brand denture pages give authority. | E3: Gadsden site is a one-page template with thin copy; no pricing; no location pages; limited unique local content. | F3: No same-day denture detail for Gadsden, no cost guides, no insurance page, no FAQs, no town pages. | G3: Create richer Gadsden-specific denture, extraction and emergency content; use local proof (on-site lab, free adjustments) that a network site cannot match.
A4: Legacy Dental Alabama | B4: https://legacydentalalabama.com/ | C4: General dentistry and orthodontic treatment for adolescents to seniors; new-patient forms | D4: Clear structure (About, Services, New Patients, Contact); mentions orthodontics. | E4: Homepage still displays an outdated COVID-19 limited-hours notice (through April 9th) - signals neglected content; thin copy; no pricing. | F4: No denture/same-day content, no cost or insurance pages, no blog/FAQ, no local-town pages visible. | G4: Very low content freshness - an easy competitor to out-rank with updated, specific local pages. Confirm its location relevance in a live SERP check.
A5: southernsmilesdentalcenter.com | B5: http://southernsmilesdentalcenter.com/ | C5: Brand name; price sheet: crowns, root canals from, extractions, surgical extractions, routine cleaning incl. X-ray & exam, Six Month Smiles clear braces/aligners, same-day dentures (standard/deluxe/custom), partials, no-charge adjustments, insurance filing | D5: Transparent price list and insurance carriers (Humana, Delta Dental, Cigna, BCBS) - the kind of BOFU content the main site lacks. | E5: Same address and phone as the client (duplicate NAP); one page built with a site-builder tool; splits brand authority between two domains. | F5: Not a competitor - overlaps the client entirely. | G5: 301-redirect to southernsmilesgadsden.com after migrating verified pricing/insurance content into new pages (confirm current prices first).
A6: Aspen Dental - Gadsden | B6: https://www.aspendental.com/dentist/al/gadsden/508-e-meighan-blvd-ste-b2/ | C6: Dentures (full, partial, implant dentures), same-day denture starts, denture repair/reline, immediate dentures, general dentistry, periodontal care, walk-ins and same-day appointments | D6: Dedicated location + service URLs (dentures, implant dentures, etc.); FAQ blocks; ~1,100 listed reviews (per search snippet); extended availability. | E6: Corporate template with little local or provider-specific storytelling; walk-in language is conditional; cost details appear generic. | F6: No Gadsden-specific price transparency or on-site-lab/free-adjustment story visible in reviewed pages; limited small-town (Rainbow City, Attalla, etc.) coverage. | G6: Compete on local trust, price transparency and speed: same-day dentures made on-site, free adjustments, town pages, reviews and FAQ answers.
A7: Coosa Family Dentistry & Same Day Dentures | B7: https://coosadentistry.com/ | C7: General dentistry and same-day dentures in Gadsden (104 Cherry St) - direct overlap with the client's core money keywords | D7: Brand name includes 'Same Day Dentures'; directory listings show financing and a 4.5 rating (8 reviews, third-party data). | E7: Few reviews per directory data; very limited published hours per directory listings; site not audited directly. | F7: Likely light on denture education, cost guides, FAQs and town pages (to be verified). | G7: Build the strongest same-day denture page and supporting guide cluster in Gadsden; accumulate reviews faster; use pricing + free adjustments as proof points.

Sheet Keyword Mapping
A1: URL | B1: Page Name | C1: Primary Keyword | D1: Secondary Keywords | E1: Intent | F1: Funnel Stage | G1: Existing/New | H1: Action | I1: Cannibalization Risk | J1: Keyword Count | K1: Est. Page Volume
A2: / | B2: Homepage | C2: dentist gadsden al | D2: gadsden dentist; dental office gadsden al; dentist in gadsden alabama; general dentist gadsden al; dental clinic gadsden al | E2: {=INDEX('Keyword Master Database'!$E$2:$E$242,MATCH(C2,'Keyword Master Database'!$A$2:$A$242,0))} -> Transactional | F2: {=INDEX('Keyword Master Database'!$F$2:$F$242,MATCH(C2,'Keyword Master Database'!$A$2:$A$242,0))} -> BOFU | G2: Existing | H2: Optimize | I2: Medium - homepage currently mixes same-day dentures + affordable dentist; move depth to dedicated pages and keep homepage on 'dentist gadsden al' | J2: =COUNTIF('Keyword Master Database'!$X$2:$X$242,A2) -> 14 | K2: =SUMIF('Keyword Master Database'!$X$2:$X$242,A2,'Keyword Master Database'!$H$2:$H$242) -> 1831990
A3: /contact/ | B3: Contact / Book Appointment | C3: southern smiles dental center phone number | D3: dentist open today gadsden al; southern smiles dental center hours; 315 n 3rd st gadsden al dentist | E3: {=INDEX('Keyword Master Database'!$E$2:$E$242,MATCH(C3,'Keyword Master Database'!$A$2:$A$242,0))} -> Navigational | F3: {=INDEX('Keyword Master Database'!$F$2:$F$242,MATCH(C3,'Keyword Master Database'!$A$2:$A$242,0))} -> BOFU | G3: Existing | H3: Optimize | I3: Low | J3: =COUNTIF('Keyword Master Database'!$X$2:$X$242,A3) -> 4 | K3: =SUMIF('Keyword Master Database'!$X$2:$X$242,A3,'Keyword Master Database'!$H$2:$H$242) -> 90
A4: /dentures-gadsden-al/ | B4: Dentures Gadsden AL (Hub) | C4: dentures gadsden al | D4: dentures near me gadsden al; denture dentist gadsden al; denture clinic gadsden al; full dentures gadsden al; custom dentures gadsden al | E4: {=INDEX('Keyword Master Database'!$E$2:$E$242,MATCH(C4,'Keyword Master Database'!$A$2:$A$242,0))} -> Transactional | F4: {=INDEX('Keyword Master Database'!$F$2:$F$242,MATCH(C4,'Keyword Master Database'!$A$2:$A$242,0))} -> BOFU | G4: New | H4: Create | I4: Medium - hub vs. same-day page; hub = overview + links, same-day page = process, pricing teaser | J4: =COUNTIF('Keyword Master Database'!$X$2:$X$242,A4) -> 11 | K4: =SUMIF('Keyword Master Database'!$X$2:$X$242,A4,'Keyword Master Database'!$H$2:$H$242) -> 87580
A5: /same-day-dentures-gadsden-al/ | B5: Same-Day Dentures Gadsden AL | C5: same day dentures gadsden al | D5: dentures in one day gadsden al; same day dentures alabama; one day dentures alabama; who makes same day dentures near gadsden al; where can i get dentures in one day in alabama | E5: {=INDEX('Keyword Master Database'!$E$2:$E$242,MATCH(C5,'Keyword Master Database'!$A$2:$A$242,0))} -> Transactional | F5: {=INDEX('Keyword Master Database'!$F$2:$F$242,MATCH(C5,'Keyword Master Database'!$A$2:$A$242,0))} -> BOFU | G5: New | H5: Create | I5: Medium - overlaps /dentures-gadsden-al/ and /immediate-dentures-gadsden-al/; keep hub generic, this page process/benefits | J5: =COUNTIF('Keyword Master Database'!$X$2:$X$242,A5) -> 8 | K5: =SUMIF('Keyword Master Database'!$X$2:$X$242,A5,'Keyword Master Database'!$H$2:$H$242) -> 15290
