Workbook

Sheet Cover
A2: SEO KEYWORD RESEARCH & STRATEGY WORKBOOK
A3: Carter Family Dentistry, LLC | Rainsville, Alabama | United States Of America
A5: Prepared by Md. Abdul Alim – Dental SEO & AI Search Optimization Consultant
B8: Headline Numbers
B9: Keywords researched | C9: =COUNTA('Keyword Master Database'!$A$2:$A$137) -> 136
B10: Keyword clusters | C10: =COUNTA('Keyword Clusters'!A2:A20) -> 19
B11: Est. monthly volume – local + regional keywords | C11: =SUMIFS('Keyword Master Database'!$H$2:$H$137,'Keyword Master Database'!$Z$2:$Z$137,"<>National") -> 2570
B12: National benchmark keywords (excluded from volume) | C12: =COUNTIF('Keyword Master Database'!$Z$2:$Z$137,"National") -> 77
B13: Avg. est. KD – local + regional keywords | C13: =ROUND(SUMPRODUCT(('Keyword Master Database'!$Z$2:$Z$137<>"National")*'Keyword Master Database'!$I$2:$I$137)/(COUNTA('Keyword Master Database'!$A$2:$A$137)-COUNTIF('Keyword Master Database'!$Z$2:$Z$137,"National")),0) -> 11
B14: Critical + High priority keywords | C14: =COUNTIF('Keyword Master Database'!$V$2:$V$137,"Critical")+COUNTIF('Keyword Master Database'!$V$2:$V$137,"High") -> 70
B15: Pages mapped (existing + new) | C15: =COUNTA('Keyword Mapping'!A2:A51) -> 50
B16: New pages to create | C16: =COUNTIF('Keyword Mapping'!G2:G51,"New") -> 31
B17: Internal links planned | C17: =COUNTA('Internal Linking Blueprint'!A2:A129) -> 128
B18: Content roadmap items | C18: =COUNTA('Content Roadmap'!A2:A49) -> 48
B20: Search Intent Mix
B21: Informational | C21: =COUNTIF('Keyword Master Database'!$E$2:$E$137,B21) -> 30
B22: Navigational | C22: =COUNTIF('Keyword Master Database'!$E$2:$E$137,B22) -> 9
B23: Commercial | C23: =COUNTIF('Keyword Master Database'!$E$2:$E$137,B23) -> 37
B24: Transactional | C24: =COUNTIF('Keyword Master Database'!$E$2:$E$137,B24) -> 60
B26: Funnel Stage Mix
B27: TOFU | C27: =COUNTIF('Keyword Master Database'!$F$2:$F$137,B27) -> 30
B28: MOFU | C28: =COUNTIF('Keyword Master Database'!$F$2:$F$137,B28) -> 41
B29: BOFU | C29: =COUNTIF('Keyword Master Database'!$F$2:$F$137,B29) -> 65
B31: Priority Level Mix
B32: Critical | C32: =COUNTIF('Keyword Master Database'!$V$2:$V$137,B32) -> 6
B33: High | C33: =COUNTIF('Keyword Master Database'!$V$2:$V$137,B33) -> 64
B34: Medium | C34: =COUNTIF('Keyword Master Database'!$V$2:$V$137,B34) -> 42
B35: Low | C35: =COUNTIF('Keyword Master Database'!$V$2:$V$137,B35) -> 24
B36: Optional | C36: =COUNTIF('Keyword Master Database'!$V$2:$V$137,B36) -> 0
B38: Workbook Contents
B39: Business Analysis | C39: Client profile and live website review
B40: Keyword Master Database | C40: Keywords with intent, funnel, volume, KD, CPC and priority
B41: Keyword Clusters | C41: Keyword groups with questions and entities
B42: Competitor Analysis | C42: Client competitors and SERP competitor types
B43: Keyword Mapping | C43: One primary keyword per URL; cannibalization risk
B44: Topical Authority Map | C44: Topic depth for each service
B45: SEO Silo Architecture | C45: Proposed site structure
B46: Internal Linking Blueprint | C46: Planned links, anchors and purpose
B47: Content Roadmap | C47: Six-month publishing and optimization plan
B48: Quick Wins | C48: First-30-day opportunities
...

Sheet Business Analysis
A1: Business Analysis
A4: Field | B4: Detail
A5: Business Name | B5: Carter Family Dentistry, LLC
A6: Website | B6: https://www.carterdentistry.com/
A7: Industry | B7: Dental Clinic (general, restorative and cosmetic dentistry)
A8: Country | B8: United States
A9: Location | B9: 20 Bartlett Ave, Rainsville, AL 35986 – serves DeKalb County, Jackson County and surrounding areas
A10: Services | B10: Dental Exams; Emergency Exam; Digital Imaging; Fillings; Silver Diamine Fluoride (SDF); Crowns; Veneers; Bridges; Root Canals; Extractions; Implants; Dentures; Partial Dentures
A11: Products | B11: None – service business (no retail products)
A12: Primary Business Goals | B12: Generate more local leads; increase organic traffic; improve service page rankings; build topical authority
A13: Primary SEO Focus | B13: Local SEO
A14: Contact (per website) | B14: (256) 638-2121; info@carterdentistry.com; Mon–Fri 8am–5pm, closed Sat/Sun
A15: Provider | B15: Dr. Emily Carter
A17: Website Analysis – Current SEO Position
A18: Area | B18: Finding | C18: SEO Implication / Opportunity | D18: Type
A19: Title tag | B19: Homepage title: "Carter Family Dentistry, LLC | Dentist in Rainsville, AL | Dentist Near Me | Female Dentist" (91 characters). | C19: Strength: city and 'female dentist' differentiator are present. Gap: too long (truncates in search results) and 'Dentist Near Me' looks stuffed. Shorten to under ~60 characters, e.g. 'Dentist in Rainsville, AL | Carter Family Dentistry'. | D19: Observation
A20: Meta description | B20: Mentions Dr. Emily Carter, comprehensive general, restorative and cosmetic care, Rainsville, and the whole family. No phone number or call-to-action; appears longer than ~160 characters. | C20: Tighten to ~155 characters with a CTA and phone number. | D20: Observation
A21: Homepage H1 / copy | B21: The H1 is the brand name only. Most homepage text is short headings and images with little service or location copy. | C21: Add a keyword-led H1 (e.g. 'Family Dentist in Rainsville, AL') and 300–500 words covering services, towns served and insurance. | D21: Gap
A22: Service pages | B22: 13 dedicated service pages are linked in the navigation (exams, emergency exam, imaging, fillings, SDF, crowns, veneers, bridges, root canals, extractions, implants, dentures, partial dentures). | C22: Strong foundation for service-level targeting. Individual page copy was not audited in this version – review depth, headings and FAQs per page. | D22: Strength
A23: Service area | B23: Homepage says it serves DeKalb County, Jackson County and surrounding areas, but no dedicated service-area or town pages were found in the navigation. | C23: Create a service-area hub plus Fort Payne and Scottsboro pages. | D23: Gap
A24: Insurance | B24: Homepage states all major plans are accepted and the practice is in-network with Blue Cross Blue Shield of Alabama and Southland. No dedicated insurance/payment page in navigation. | C24: A dedicated insurance page targets high-intent 'dentist that accepts [insurance]' searches. | D24: Opportunity
A25: Content / blog | B25: No blog, resources or FAQ section appears in the main navigation. | C25: No TOFU/MOFU content exists to capture informational searches – see Content Roadmap. | D25: Gap
A26: Trust / E-E-A-T | B26: Meet Dr. Emily Carter, Meet the Team, Office Tour and Testimonials pages exist. | C26: Good trust assets; add credentials, reviewed-by bylines and review schema. | D26: Strength
A27: NAP & hours | B27: Name, address, phone, email and weekday hours (8am–5pm) are present on the homepage footer. | C27: Keep identical on GBP and directories; add LocalBusiness/Dentist schema. | D27: Strength
A28: Conversion path | B28: Appointment request page exists; new-patient forms are hosted on an external domain (patientviewer.com). | C28: Track clicks to the external form as a conversion event; add click-to-call tracking. | D28: Opportunity
A29: Freshness | B29: Footer copyright reads 2022, while the privacy notice link is dated 2026. | C29: Update the copyright year and publish new content to show the site is current. | D29: Observation
... A31: Brand collision | B31: A Boise, Idaho practice (carterfamilydds.com) shares the name 'Carter Family Dentistry'; Carter Braces (an orthodontist) is also in Rainsville. | C31: Always pair the brand with 'Rainsville, AL' and Dr. Emily Carter in titles, schema and citations to own the branded SERP. | D31: Risk

Sheet Keyword Master Database
A1: Keyword | B1: Keyword Type | C1: Parent Topic | D1: Cluster | E1: Search Intent | F1: Funnel Stage | G1: Primary / Secondary | H1: Search Volume (monthly) | I1: KD | J1: KD Source | K1: Estimated CPC (USD) | L1: CPC Source | M1: SERP Competition | N1: Ranking Competitors | O1: Business Value (1-5) | P1: Search Demand (1-5) | Q1: Ranking Opportunity (1-5) | R1: Intent Strength (1-5) | S1: Conversion Potential (1-5) | T1: Topical Importance (1-5) | U1: SEO Priority Score (0-100) | V1: Priority Level | W1: Target URL | X1: Recommended Action | Y1: Notes | Z1: Volume Scope
A2: carter family dentistry rainsville al | B2: Brand | C2: Carter Family Dentistry (Brand) | D2: Brand & Navigational | E2: Navigational | F2: BOFU | G2: Primary | H2: 90 | I2: 3 | J2: SERP Competition Analysis | K2: 1.2 | L2: Commercial Intent Analysis | M2: =LOOKUP(I2,Methodology!$B$46:$B$49,Methodology!$C$46:$C$49) -> Easy | N2: Own brand SERP; Facebook; directories; carterfamilydds.com (Boise, ID – name overlap) | O2: 4 | P2: =LOOKUP(H2,Methodology!$B$15:$B$19,Methodology!$C$15:$C$19) -> 3 | Q2: =LOOKUP(I2,Methodology!$B$23:$B$27,Methodology!$C$23:$C$27) -> 5 | R2: {=INDEX(Methodology!$C$31:$C$34,MATCH(E2,Methodology!$B$31:$B$34,0))} -> 3 | S2: 4 | T2: 3 | U2: =ROUND((O2*Methodology!$C$5+P2*Methodology!$C$6+Q2*Methodology!$C$7+R2*Methodology!$C$8+S2*Methodology!$C$9+T2*Methodology!$C$10)*20,0) -> 76 | V2: =LOOKUP(U2,Methodology!$B$38:$B$42,Methodology!$C$38:$C$42) -> High | W2: / | X2: Keep | Y2: Protect branded SERP; pair brand with city + Dr. Emily Carter in title/schema. | Z2: Local
A3: carter family dentistry | B3: Brand | C3: Carter Family Dentistry (Brand) | D3: Brand & Navigational | E3: Navigational | F3: BOFU | G3: Secondary | H3: 480 | I3: 8 | J3: SERP Competition Analysis | K3: 2.1 | L3: Commercial Intent Analysis | M3: =LOOKUP(I3,Methodology!$B$46:$B$49,Methodology!$C$46:$C$49) -> Easy | N3: Own brand SERP; Facebook; directories; carterfamilydds.com (Boise, ID – name overlap) | O3: 4 | P3: =LOOKUP(H3,Methodology!$B$15:$B$19,Methodology!$C$15:$C$19) -> 4 | Q3: =LOOKUP(I3,Methodology!$B$23:$B$27,Methodology!$C$23:$C$27) -> 5 | R3: {=INDEX(Methodology!$C$31:$C$34,MATCH(E3,Methodology!$B$31:$B$34,0))} -> 3 | S3: 4 | T3: 3 | U3: =ROUND((O3*Methodology!$C$5+P3*Methodology!$C$6+Q3*Methodology!$C$7+R3*Methodology!$C$8+S3*Methodology!$C$9+T3*Methodology!$C$10)*20,0) -> 79 | V3: =LOOKUP(U3,Methodology!$B$38:$B$42,Methodology!$C$38:$C$42) -> High | W3: / | X3: Optimize | Y3: Name overlap with a Boise, ID practice (carterfamilydds.com) – always disambiguate with Rainsville, AL. | Z3: National
A4: carterdentistry.com | B4: Brand | C4: Carter Family Dentistry (Brand) | D4: Brand & Navigational | E4: Navigational | F4: BOFU | G4: Secondary | H4: 40 | I4: 1 | J4: SERP Competition Analysis | K4: 0.5 | L4: Commercial Intent Analysis | M4: =LOOKUP(I4,Methodology!$B$46:$B$49,Methodology!$C$46:$C$49) -> Easy | N4: Own brand SERP; Facebook; directories; carterfamilydds.com (Boise, ID – name overlap) | O4: 4 | P4: =LOOKUP(H4,Methodology!$B$15:$B$19,Methodology!$C$15:$C$19) -> 2 | Q4: =LOOKUP(I4,Methodology!$B$23:$B$27,Methodology!$C$23:$C$27) -> 5 | R4: {=INDEX(Methodology!$C$31:$C$34,MATCH(E4,Methodology!$B$31:$B$34,0))} -> 3 | S4: 4 | T4: 3 | U4: =ROUND((O4*Methodology!$C$5+P4*Methodology!$C$6+Q4*Methodology!$C$7+R4*Methodology!$C$8+S4*Methodology!$C$9+T4*Methodology!$C$10)*20,0) -> 73 | V4: =LOOKUP(U4,Methodology!$B$38:$B$42,Methodology!$C$38:$C$42) -> Medium | W4: / | X4: Keep | Z4: Local
A5: carter family dentistry reviews | B5: Brand | C5: Carter Family Dentistry (Brand) | D5: Brand & Navigational | E5: Navigational | F5: MOFU | G5: Secondary | H5: 40 | I5: 6 | J5: SERP Competition Analysis | K5: 1.6 | L5: Commercial Intent Analysis | M5: =LOOKUP(I5,Methodology!$B$46:$B$49,Methodology!$C$46:$C$49) -> Easy | N5: Own brand SERP; Facebook; directories; carterfamilydds.com (Boise, ID – name overlap) | O5: 4 | P5: =LOOKUP(H5,Methodology!$B$15:$B$19,Methodology!$C$15:$C$19) -> 2 | Q5: =LOOKUP(I5,Methodology!$B$23:$B$27,Methodology!$C$23:$C$27) -> 5 | R5: {=INDEX(Methodology!$C$31:$C$34,MATCH(E5,Methodology!$B$31:$B$34,0))} -> 3 | S5: 4 | T5: 3 | U5: =ROUND((O5*Methodology!$C$5+P5*Methodology!$C$6+Q5*Methodology!$C$7+R5*Methodology!$C$8+S5*Methodology!$C$9+T5*Methodology!$C$10)*20,0) -> 73 | V5: =LOOKUP(U5,Methodology!$B$38:$B$42,Methodology!$C$38:$C$42) -> Medium | W5: /testimonials | X5: Optimize | Y5: Add review schema and embed Google reviews. | Z5: Local
A6: carter family dentistry phone number | B6: Brand | C6: Carter Family Dentistry (Brand) | D6: Brand & Navigational | E6: Navigational | F6: BOFU | G6: Secondary | H6: 30 | I6: 2 | J6: SERP Competition Analysis | K6: 1.1 | L6: Commercial Intent Analysis | M6: =LOOKUP(I6,Methodology!$B$46:$B$49,Methodology!$C$46:$C$49) -> Easy | N6: Own brand SERP; Facebook; directories; carterfamilydds.com (Boise, ID – name overlap) | O6: 4 | P6: =LOOKUP(H6,Methodology!$B$15:$B$19,Methodology!$C$15:$C$19) -> 2 | Q6: =LOOKUP(I6,Methodology!$B$23:$B$27,Methodology!$C$23:$C$27) -> 5 | R6: {=INDEX(Methodology!$C$31:$C$34,MATCH(E6,Methodology!$B$31:$B$34,0))} -> 3 | S6: 4 | T6: 3 | U6: =ROUND((O6*Methodology!$C$5+P6*Methodology!$C$6+Q6*Methodology!$C$7+R6*Methodology!$C$8+S6*Methodology!$C$9+T6*Methodology!$C$10)*20,0) -> 73 | V6: =LOOKUP(U6,Methodology!$B$38:$B$42,Methodology!$C$38:$C$42) -> Medium | W6: /contact | X6: Optimize | Y6: Click-to-call + NAP consistency: (256) 638-2121. | Z6: Local
A7: carter family dentistry hours | B7: Brand | C7: Carter Family Dentistry (Brand) | D7: Brand & Navigational | E7: Navigational | F7: BOFU | G7: Secondary | H7: 30 | I7: 2 | J7: SERP Competition Analysis | K7: 0.9 | L7: Commercial Intent Analysis | M7: =LOOKUP(I7,Methodology!$B$46:$B$49,Methodology!$C$46:$C$49) -> Easy | N7: Own brand SERP; Facebook; directories; carterfamilydds.com (Boise, ID – name overlap) | O7: 4 | P7: =LOOKUP(H7,Methodology!$B$15:$B$19,Methodology!$C$15:$C$19) -> 2 | Q7: =LOOKUP(I7,Methodology!$B$23:$B$27,Methodology!$C$23:$C$27) -> 5 | R7: {=INDEX(Methodology!$C$31:$C$34,MATCH(E7,Methodology!$B$31:$B$34,0))} -> 3 | S7: 4 | T7: 3 | U7: =ROUND((O7*Methodology!$C$5+P7*Methodology!$C$6+Q7*Methodology!$C$7+R7*Methodology!$C$8+S7*Methodology!$C$9+T7*Methodology!$C$10)*20,0) -> 73 | V7: =LOOKUP(U7,Methodology!$B$38:$B$42,Methodology!$C$38:$C$42) -> Medium | W7: /contact | X7: Optimize | Y7: Website lists Mon–Fri 8am–5pm; keep identical on GBP. | Z7: Local
A8: carter family dentistry insurance | B8: Brand | C8: Carter Family Dentistry (Brand) | D8: Brand & Navigational | E8: Navigational | F8: MOFU | G8: Secondary | H8: 20 | I8: 4 | J8: SERP Competition Analysis | K8: 1.8 | L8: Commercial Intent Analysis | M8: =LOOKUP(I8,Methodology!$B$46:$B$49,Methodology!$C$46:$C$49) -> Easy | N8: Own brand SERP; Facebook; directories; carterfamilydds.com (Boise, ID – name overlap) | O8: 4 | P8: =LOOKUP(H8,Methodology!$B$15:$B$19,Methodology!$C$15:$C$19) -> 2 | Q8: =LOOKUP(I8,Methodology!$B$23:$B$27,Methodology!$C$23:$C$27) -> 5 | R8: {=INDEX(Methodology!$C$31:$C$34,MATCH(E8,Methodology!$B$31:$B$34,0))} -> 3 | S8: 4 | T8: 3 | U8: =ROUND((O8*Methodology!$C$5+P8*Methodology!$C$6+Q8*Methodology!$C$7+R8*Methodology!$C$8+S8*Methodology!$C$9+T8*Methodology!$C$10)*20,0) -> 73 | V8: =LOOKUP(U8,Methodology!$B$38:$B$42,Methodology!$C$38:$C$42) -> Medium | W8: /dental-insurance-payment | X8: Create | Z8: Local
A9: dentist in rainsville al | B9: Local Service | C9: Dentist in Rainsville, AL | D9: Local Dentist – Rainsville & DeKalb | E9: Transactional | F9: BOFU | G9: Primary | H9: 110 | I9: 14 | J9: SERP Competition Analysis | K9: 6.4 | L9: Commercial Intent Analysis | M9: =LOOKUP(I9,Methodology!$B$46:$B$49,Methodology!$C$46:$C$49) -> Easy | N9: Local GBP pack; nearby dental practices (Fort Payne / Scottsboro area); Yelp; Healthgrades | O9: 5 | P9: =LOOKUP(H9,Methodology!$B$15:$B$19,Methodology!$C$15:$C$19) -> 3 | Q9: =LOOKUP(I9,Methodology!$B$23:$B$27,Methodology!$C$23:$C$27) -> 5 | R9: {=INDEX(Methodology!$C$31:$C$34,MATCH(E9,Methodology!$B$31:$B$34,0))} -> 5 | S9: 5 | T9: 5 | U9: =ROUND((O9*Methodology!$C$5+P9*Methodology!$C$6+Q9*Methodology!$C$7+R9*Methodology!$C$8+S9*Methodology!$C$9+T9*Methodology!$C$10)*20,0) -> 94 | V9: =LOOKUP(U9,Methodology!$B$38:$B$42,Methodology!$C$38:$C$42) -> Critical | W9: / | X9: Optimize | Y9: Core money keyword – homepage H1/title/body. | Z9: Local
A10: dentist rainsville alabama | B10: Location | C10: Dentist in Rainsville, AL | D10: Local Dentist – Rainsville & DeKalb | E10: Transactional | F10: BOFU | G10: Secondary | H10: 40 | I10: 12 | J10: SERP Competition Analysis | K10: 6.1 | L10: Commercial Intent Analysis | M10: =LOOKUP(I10,Methodology!$B$46:$B$49,Methodology!$C$46:$C$49) -> Easy | N10: Local GBP pack; nearby dental practices (Fort Payne / Scottsboro area); Yelp; Healthgrades | O10: 5 | P10: =LOOKUP(H10,Methodology!$B$15:$B$19,Methodology!$C$15:$C$19) -> 2 | Q10: =LOOKUP(I10,Methodology!$B$23:$B$27,Methodology!$C$23:$C$27) -> 5 | R10: {=INDEX(Methodology!$C$31:$C$34,MATCH(E10,Methodology!$B$31:$B$34,0))} -> 5 | S10: 5 | T10: 5 | U10: =ROUND((O10*Methodology!$C$5+P10*Methodology!$C$6+Q10*Methodology!$C$7+R10*Methodology!$C$8+S10*Methodology!$C$9+T10*Methodology!$C$10)*20,0) -> 91 | V10: =LOOKUP(U10,Methodology!$B$38:$B$42,Methodology!$C$38:$C$42) -> Critical | W10: / | X10: Optimize | Z10: Local
A11: dental office rainsville al | B11: Location | C11: Dentist in Rainsville, AL | D11: Local Dentist – Rainsville & DeKalb | E11: Transactional | F11: BOFU | G11: Secondary | H11: 30 | I11: 10 | J11: SERP Competition Analysis | K11: 5.4 | L11: Commercial Intent Analysis | M11: =LOOKUP(I11,Methodology!$B$46:$B$49,Methodology!$C$46:$C$49) -> Easy | N11: Local GBP pack; nearby dental practices (Fort Payne / Scottsboro area); Yelp; Healthgrades | O11: 5 | P11: =LOOKUP(H11,Methodology!$B$15:$B$19,Methodology!$C$15:$C$19) -> 2 | Q11: =LOOKUP(I11,Methodology!$B$23:$B$27,Methodology!$C$23:$C$27) -> 5 | R11: {=INDEX(Methodology!$C$31:$C$34,MATCH(E11,Methodology!$B$31:$B$34,0))} -> 5 | S11: 5 | T11: 5 | U11: =ROUND((O11*Methodology!$C$5+P11*Methodology!$C$6+Q11*Methodology!$C$7+R11*Methodology!$C$8+S11*Methodology!$C$9+T11*Methodology!$C$10)*20,0) -> 91 | V11: =LOOKUP(U11,Methodology!$B$38:$B$42,Methodology!$C$38:$C$42) -> Critical | W11: / | X11: Optimize | Z11: Local
A12: general dentist rainsville al | B12: Core Service | C12: Dentist in Rainsville, AL | D12: Local Dentist – Rainsville & DeKalb | E12: Transactional | F12: BOFU | G12: Secondary | H12: 30 | I12: 11 | J12: SERP Competition Analysis | K12: 6 | L12: Commercial Intent Analysis | M12: =LOOKUP(I12,Methodology!$B$46:$B$49,Methodology!$C$46:$C$49) -> Easy | N12: Local GBP pack; nearby dental practices (Fort Payne / Scottsboro area); Yelp; Healthgrades | O12: 5 | P12: =LOOKUP(H12,Methodology!$B$15:$B$19,Methodology!$C$15:$C$19) -> 2 | Q12: =LOOKUP(I12,Methodology!$B$23:$B$27,Methodology!$C$23:$C$27) -> 5 | R12: {=INDEX(Methodology!$C$31:$C$34,MATCH(E12,Methodology!$B$31:$B$34,0))} -> 5 | S12: 5 | T12: 5 | U12: =ROUND((O12*Methodology!$C$5+P12*Methodology!$C$6+Q12*Methodology!$C$7+R12*Methodology!$C$8+S12*Methodology!$C$9+T12*Methodology!$C$10)*20,0) -> 91 | V12: =LOOKUP(U12,Methodology!$B$38:$B$42,Methodology!$C$38:$C$42) -> Critical | W12: /services | X12: Optimize | Y12: Services hub page. | Z12: Local
A13: best dentist in rainsville al | B13: Commercial | C13: Dentist in Rainsville, AL | D13: Local Dentist – Rainsville & DeKalb | E13: Commercial | F13: MOFU | G13: Secondary | H13: 20 | I13: 13 | J13: SERP Competition Analysis | K13: 5.8 | L13: Commercial Intent Analysis | M13: =LOOKUP(I13,Methodology!$B$46:$B$49,Methodology!$C$46:$C$49) -> Easy | N13: Local GBP pack; nearby dental practices (Fort Payne / Scottsboro area); Yelp; Healthgrades | O13: 5 | P13: =LOOKUP(H13,Methodology!$B$15:$B$19,Methodology!$C$15:$C$19) -> 2 | Q13: =LOOKUP(I13,Methodology!$B$23:$B$27,Methodology!$C$23:$C$27) -> 5 | R13: {=INDEX(Methodology!$C$31:$C$34,MATCH(E13,Methodology!$B$31:$B$34,0))} -> 4 | S13: 3 | T13: 5 | U13: =ROUND((O13*Methodology!$C$5+P13*Methodology!$C$6+Q13*Methodology!$C$7+R13*Methodology!$C$8+S13*Methodology!$C$9+T13*Methodology!$C$10)*20,0) -> 82 | V13: =LOOKUP(U13,Methodology!$B$38:$B$42,Methodology!$C$38:$C$42) -> High | W13: / | X13: Optimize | Y13: Support with reviews / testimonials block. | Z13: Local
A14: affordable dentist rainsville al | B14: Commercial | C14: Dentist in Rainsville, AL | D14: Local Dentist – Rainsville & DeKalb | E14: Commercial | F14: MOFU | G14: Secondary | H14: 20 | I14: 10 | J14: SERP Competition Analysis | K14: 5.1 | L14: Commercial Intent Analysis | M14: =LOOKUP(I14,Methodology!$B$46:$B$49,Methodology!$C$46:$C$49) -> Easy | N14: Cost guides (Delta Dental, Colgate, Healthline); regional practices; directories | O14: 5 | P14: =LOOKUP(H14,Methodology!$B$15:$B$19,Methodology!$C$15:$C$19) -> 2 | Q14: =LOOKUP(I14,Methodology!$B$23:$B$27,Methodology!$C$23:$C$27) -> 5 | R14: {=INDEX(Methodology!$C$31:$C$34,MATCH(E14,Methodology!$B$31:$B$34,0))} -> 4 | S14: 3 | T14: 5 | U14: =ROUND((O14*Methodology!$C$5+P14*Methodology!$C$6+Q14*Methodology!$C$7+R14*Methodology!$C$8+S14*Methodology!$C$9+T14*Methodology!$C$10)*20,0) -> 82 | V14: =LOOKUP(U14,Methodology!$B$38:$B$42,Methodology!$C$38:$C$42) -> High | W14: /dental-insurance-payment | X14: Create | Y14: Website promises affordable pricing – back it with an insurance/payment page. | Z14: Local
A15: new patient dentist rainsville al | B15: Transactional | C15: Dentist in Rainsville, AL | D15: Local Dentist – Rainsville & DeKalb | E15: Transactional | F15: BOFU | G15: Secondary | H15: 20 | I15: 9 | J15: SERP Competition Analysis | K15: 6.5 | L15: Commercial Intent Analysis | M15: =LOOKUP(I15,Methodology!$B$46:$B$49,Methodology!$C$46:$C$49) -> Easy | N15: Local GBP pack; nearby dental practices (Fort Payne / Scottsboro area); Yelp; Healthgrades | O15: 5 | P15: =LOOKUP(H15,Methodology!$B$15:$B$19,Methodology!$C$15:$C$19) -> 2 | Q15: =LOOKUP(I15,Methodology!$B$23:$B$27,Methodology!$C$23:$C$27) -> 5 | R15: {=INDEX(Methodology!$C$31:$C$34,MATCH(E15,Methodology!$B$31:$B$34,0))} -> 5 | S15: 5 | T15: 5 | U15: =ROUND((O15*Methodology!$C$5+P15*Methodology!$C$6+Q15*Methodology!$C$7+R15*Methodology!$C$8+S15*Methodology!$C$9+T15*Methodology!$C$10)*20,0) -> 91 | V15: =LOOKUP(U15,Methodology!$B$38:$B$42,Methodology!$C$38:$C$42) -> Critical | W15: /appointment | X15: Optimize | Z15: Local
A16: dentist accepting new patients rainsville al | B16: Transactional | C16: Dentist in Rainsville, AL | D16: Local Dentist – Rainsville & DeKalb | E16: Transactional | F16: BOFU | G16: Secondary | H16: 20 | I16: 9 | J16: SERP Competition Analysis | K16: 6.5 | L16: Commercial Intent Analysis | M16: =LOOKUP(I16,Methodology!$B$46:$B$49,Methodology!$C$46:$C$49) -> Easy | N16: Local GBP pack; nearby dental practices (Fort Payne / Scottsboro area); Yelp; Healthgrades | O16: 5 | P16: =LOOKUP(H16,Methodology!$B$15:$B$19,Methodology!$C$15:$C$19) -> 2 | Q16: =LOOKUP(I16,Methodology!$B$23:$B$27,Methodology!$C$23:$C$27) -> 5 | R16: {=INDEX(Methodology!$C$31:$C$34,MATCH(E16,Methodology!$B$31:$B$34,0))} -> 5 | S16: 5 | T16: 5 | U16: =ROUND((O16*Methodology!$C$5+P16*Methodology!$C$6+Q16*Methodology!$C$7+R16*Methodology!$C$8+S16*Methodology!$C$9+T16*Methodology!$C$10)*20,0) -> 91 | V16: =LOOKUP(U16,Methodology!$B$38:$B$42,Methodology!$C$38:$C$42) -> Critical | W16: /appointment | X16: Optimize | Z16: Local
A17: dentist near me | B17: Transactional | C17: Dentist in Rainsville, AL | D17: Local Dentist – Rainsville & DeKalb | E17: Transactional | F17: BOFU | G17: Secondary | H17: 1220000 | I17: 78 | J17: SERP Competition Analysis | K17: 5.8 | L17: Commercial Intent Analysis | M17: =LOOKUP(I17,Methodology!$B$46:$B$49,Methodology!$C$46:$C$49) -> Very Competitive | N17: Local GBP pack; nearby dental practices (Fort Payne / Scottsboro area); Yelp; Healthgrades | O17: 5 | P17: =LOOKUP(H17,Methodology!$B$15:$B$19,Methodology!$C$15:$C$19) -> 5 | Q17: =LOOKUP(I17,Methodology!$B$23:$B$27,Methodology!$C$23:$C$27) -> 1 | R17: {=INDEX(Methodology!$C$31:$C$34,MATCH(E17,Methodology!$B$31:$B$34,0))} -> 5 | S17: 5 | T17: 5 | U17: =ROUND((O17*Methodology!$C$5+P17*Methodology!$C$6+Q17*Methodology!$C$7+R17*Methodology!$C$8+S17*Methodology!$C$9+T17*Methodology!$C$10)*20,0) -> 84 | V17: =LOOKUP(U17,Methodology!$B$38:$B$42,Methodology!$C$38:$C$42) -> High | W17: / | X17: Keep | Y17: Benchmark head term only – win via GBP proximity, reviews and NAP, not on-page targeting. | Z17: National
A18: dental exam rainsville al | B18: Core Service | C18: Dental Exams & Cleanings | D18: Exams & Preventive Care | E18: Transactional | F18: BOFU | G18: Primary | H18: 20 | I18: 9 | J18: SERP Competition Analysis | K18: 6.2 | L18: Commercial Intent Analysis | M18: =LOOKUP(I18,Methodology!$B$46:$B$49,Methodology!$C$46:$C$49) -> Easy | N18: Local GBP pack; nearby dental practices (Fort Payne / Scottsboro area); Yelp; Healthgrades | O18: 4 | P18: =LOOKUP(H18,Methodology!$B$15:$B$19,Methodology!$C$15:$C$19) -> 2 | Q18: =LOOKUP(I18,Methodology!$B$23:$B$27,Methodology!$C$23:$C$27) -> 5 | R18: {=INDEX(Methodology!$C$31:$C$34,MATCH(E18,Methodology!$B$31:$B$34,0))} -> 5 | S18: 5 | T18: 4 | U18: =ROUND((O18*Methodology!$C$5+P18*Methodology!$C$6+Q18*Methodology!$C$7+R18*Methodology!$C$8+S18*Methodology!$C$9+T18*Methodology!$C$10)*20,0) -> 84 | V18: =LOOKUP(U18,Methodology!$B$38:$B$42,Methodology!$C$38:$C$42) -> High | W18: /dental-exams | X18: Optimize | Z18: Local
A19: dental cleaning rainsville al | B19: Core Service | C19: Dental Exams & Cleanings | D19: Exams & Preventive Care | E19: Transactional | F19: BOFU | G19: Secondary | H19: 30 | I19: 10 | J19: SERP Competition Analysis | K19: 5.9 | L19: Commercial Intent Analysis | M19: =LOOKUP(I19,Methodology!$B$46:$B$49,Methodology!$C$46:$C$49) -> Easy | N19: Local GBP pack; nearby dental practices (Fort Payne / Scottsboro area); Yelp; Healthgrades | O19: 4 | P19: =LOOKUP(H19,Methodology!$B$15:$B$19,Methodology!$C$15:$C$19) -> 2 | Q19: =LOOKUP(I19,Methodology!$B$23:$B$27,Methodology!$C$23:$C$27) -> 5 | R19: {=INDEX(Methodology!$C$31:$C$34,MATCH(E19,Methodology!$B$31:$B$34,0))} -> 5 | S19: 5 | T19: 4 | U19: =ROUND((O19*Methodology!$C$5+P19*Methodology!$C$6+Q19*Methodology!$C$7+R19*Methodology!$C$8+S19*Methodology!$C$9+T19*Methodology!$C$10)*20,0) -> 84 | V19: =LOOKUP(U19,Methodology!$B$38:$B$42,Methodology!$C$38:$C$42) -> High | W19: /dental-exams | X19: Optimize | Z19: Local
A20: new patient dental exam | B20: Commercial | C20: Dental Exams & Cleanings | D20: Exams & Preventive Care | E20: Commercial | F20: MOFU | G20: Secondary | H20: 880 | I20: 38 | J20: SERP Competition Analysis | K20: 7.4 | L20: Commercial Intent Analysis | M20: =LOOKUP(I20,Methodology!$B$46:$B$49,Methodology!$C$46:$C$49) -> Moderate | N20: WebMD; Colgate; Healthline; Mayo Clinic; ADA MouthHealthy | O20: 4 | P20: =LOOKUP(H20,Methodology!$B$15:$B$19,Methodology!$C$15:$C$19) -> 4 | Q20: =LOOKUP(I20,Methodology!$B$23:$B$27,Methodology!$C$23:$C$27) -> 3 | R20: {=INDEX(Methodology!$C$31:$C$34,MATCH(E20,Methodology!$B$31:$B$34,0))} -> 4 | S20: 3 | T20: 4 | U20: =ROUND((O20*Methodology!$C$5+P20*Methodology!$C$6+Q20*Methodology!$C$7+R20*Methodology!$C$8+S20*Methodology!$C$9+T20*Methodology!$C$10)*20,0) -> 73 | V20: =LOOKUP(U20,Methodology!$B$38:$B$42,Methodology!$C$38:$C$42) -> Medium | W20: /dental-exams | X20: Optimize | Z20: National
A21: dental checkup near me | B21: Transactional | C21: Dental Exams & Cleanings | D21: Exams & Preventive Care | E21: Transactional | F21: BOFU | G21: Secondary | H21: 9900 | I21: 62 | J21: SERP Competition Analysis | K21: 6.8 | L21: Commercial Intent Analysis | M21: =LOOKUP(I21,Methodology!$B$46:$B$49,Methodology!$C$46:$C$49) -> Competitive | N21: Local GBP pack; nearby dental practices (Fort Payne / Scottsboro area); Yelp; Healthgrades | O21: 4 | P21: =LOOKUP(H21,Methodology!$B$15:$B$19,Methodology!$C$15:$C$19) -> 5 | Q21: =LOOKUP(I21,Methodology!$B$23:$B$27,Methodology!$C$23:$C$27) -> 1 | R21: {=INDEX(Methodology!$C$31:$C$34,MATCH(E21,Methodology!$B$31:$B$34,0))} -> 5 | S21: 5 | T21: 4 | U21: =ROUND((O21*Methodology!$C$5+P21*Methodology!$C$6+Q21*Methodology!$C$7+R21*Methodology!$C$8+S21*Methodology!$C$9+T21*Methodology!$C$10)*20,0) -> 77 | V21: =LOOKUP(U21,Methodology!$B$38:$B$42,Methodology!$C$38:$C$42) -> High | W21: /dental-exams | X21: Optimize | Z21: National
A22: teeth cleaning near me | B22: Transactional | C22: Dental Exams & Cleanings | D22: Exams & Preventive Care | E22: Transactional | F22: BOFU | G22: Secondary | H22: 33100 | I22: 66 | J22: SERP Competition Analysis | K22: 6.2 | L22: Commercial Intent Analysis | M22: =LOOKUP(I22,Methodology!$B$46:$B$49,Methodology!$C$46:$C$49) -> Competitive | N22: Local GBP pack; nearby dental practices (Fort Payne / Scottsboro area); Yelp; Healthgrades | O22: 4 | P22: =LOOKUP(H22,Methodology!$B$15:$B$19,Methodology!$C$15:$C$19) -> 5 | Q22: =LOOKUP(I22,Methodology!$B$23:$B$27,Methodology!$C$23:$C$27) -> 1 | R22: {=INDEX(Methodology!$C$31:$C$34,MATCH(E22,Methodology!$B$31:$B$34,0))} -> 5 | S22: 5 | T22: 4 | U22: =ROUND((O22*Methodology!$C$5+P22*Methodology!$C$6+Q22*Methodology!$C$7+R22*Methodology!$C$8+S22*Methodology!$C$9+T22*Methodology!$C$10)*20,0) -> 77 | V22: =LOOKUP(U22,Methodology!$B$38:$B$42,Methodology!$C$38:$C$42) -> High | W22: /dental-exams | X22: Optimize | Z22: National
A23: what happens at a dental exam | B23: Informational | C23: Dental Exams & Cleanings | D23: Exams & Preventive Care | E23: Informational | F23: TOFU | G23: Secondary | H23: 1600 | I23: 30 | J23: SERP Competition Analysis | K23: 2.1 | L23: Commercial Intent Analysis | M23: =LOOKUP(I23,Methodology!$B$46:$B$49,Methodology!$C$46:$C$49) -> Moderate | N23: WebMD; Colgate; Healthline; Mayo Clinic; ADA MouthHealthy | O23: 3 | P23: =LOOKUP(H23,Methodology!$B$15:$B$19,Methodology!$C$15:$C$19) -> 5 | Q23: =LOOKUP(I23,Methodology!$B$23:$B$27,Methodology!$C$23:$C$27) -> 3 | R23: {=INDEX(Methodology!$C$31:$C$34,MATCH(E23,Methodology!$B$31:$B$34,0))} -> 2 | S23: 1 | T23: 3 | U23: =ROUND((O23*Methodology!$C$5+P23*Methodology!$C$6+Q23*Methodology!$C$7+R23*Methodology!$C$8+S23*Methodology!$C$9+T23*Methodology!$C$10)*20,0) -> 57 | V23: =LOOKUP(U23,Methodology!$B$38:$B$42,Methodology!$C$38:$C$42) -> Low | W23: /blog/what-happens-at-a-dental-exam | X23: Create | Z23: National
A24: family dentist rainsville al | B24: Local Service | C24: Dental Exams & Cleanings | D24: Exams & Preventive Care | E24: Transactional | F24: BOFU | G24: Secondary | H24: 50 | I24: 12 | J24: SERP Competition Analysis | K24: 6 | L24: Commercial Intent Analysis | M24: =LOOKUP(I24,Methodology!$B$46:$B$49,Methodology!$C$46:$C$49) -> Easy | N24: Local GBP pack; nearby dental practices (Fort Payne / Scottsboro area); Yelp; Healthgrades | O24: 4 | P24: =LOOKUP(H24,Methodology!$B$15:$B$19,Methodology!$C$15:$C$19) -> 3 | Q24: =LOOKUP(I24,Methodology!$B$23:$B$27,Methodology!$C$23:$C$27) -> 5 | R24: {=INDEX(Methodology!$C$31:$C$34,MATCH(E24,Methodology!$B$31:$B$34,0))} -> 5 | S24: 5 | T24: 4 | U24: =ROUND((O24*Methodology!$C$5+P24*Methodology!$C$6+Q24*Methodology!$C$7+R24*Methodology!$C$8+S24*Methodology!$C$9+T24*Methodology!$C$10)*20,0) -> 87 | V24: =LOOKUP(U24,Methodology!$B$38:$B$42,Methodology!$C$38:$C$42) -> High | W24: /family-dentistry | X24: Create | Y24: Family-care page – keep distinct from homepage. | Z24: Local
A25: kids dentist rainsville al | B25: Local Service | C25: Dental Exams & Cleanings | D25: Exams & Preventive Care | E25: Transactional | F25: BOFU | G25: Secondary | H25: 20 | I25: 10 | J25: SERP Competition Analysis | K25: 5.8 | L25: Commercial Intent Analysis | M25: =LOOKUP(I25,Methodology!$B$46:$B$49,Methodology!$C$46:$C$49) -> Easy | N25: Local GBP pack; nearby dental practices (Fort Payne / Scottsboro area); Yelp; Healthgrades | O25: 4 | P25: =LOOKUP(H25,Methodology!$B$15:$B$19,Methodology!$C$15:$C$19) -> 2 | Q25: =LOOKUP(I25,Methodology!$B$23:$B$27,Methodology!$C$23:$C$27) -> 5 | R25: {=INDEX(Methodology!$C$31:$C$34,MATCH(E25,Methodology!$B$31:$B$34,0))} -> 5 | S25: 5 | T25: 4 | U25: =ROUND((O25*Methodology!$C$5+P25*Methodology!$C$6+Q25*Methodology!$C$7+R25*Methodology!$C$8+S25*Methodology!$C$9+T25*Methodology!$C$10)*20,0) -> 84 | V25: =LOOKUP(U25,Methodology!$B$38:$B$42,Methodology!$C$38:$C$42) -> High | W25: /family-dentistry | X25: Create | Y25: Confirm pediatric age range before publishing. | Z25: Local
A26: emergency dentist rainsville al | B26: Local Service | C26: Emergency Dentist | D26: Emergency Dental Care | E26: Transactional | F26: BOFU | G26: Primary | H26: 40 | I26: 14 | J26: SERP Competition Analysis | K26: 9.8 | L26: Commercial Intent Analysis | M26: =LOOKUP(I26,Methodology!$B$46:$B$49,Methodology!$C$46:$C$49) -> Easy | N26: Local GBP pack; nearby dental practices (Fort Payne / Scottsboro area); Yelp; Healthgrades | O26: 5 | P26: =LOOKUP(H26,Methodology!$B$15:$B$19,Methodology!$C$15:$C$19) -> 2 | Q26: =LOOKUP(I26,Methodology!$B$23:$B$27,Methodology!$C$23:$C$27) -> 5 | R26: {=INDEX(Methodology!$C$31:$C$34,MATCH(E26,Methodology!$B$31:$B$34,0))} -> 5 | S26: 5 | T26: 4 | U26: =ROUND((O26*Methodology!$C$5+P26*Methodology!$C$6+Q26*Methodology!$C$7+R26*Methodology!$C$8+S26*Methodology!$C$9+T26*Methodology!$C$10)*20,0) -> 89 | V26: =LOOKUP(U26,Methodology!$B$38:$B$42,Methodology!$C$38:$C$42) -> High | W26: /emergency-exam | X26: Optimize | Y26: Highest-urgency local lead keyword. | Z26: Local
A27: emergency dentist dekalb county al | B27: Location | C27: Emergency Dentist | D27: Emergency Dental Care | E27: Transactional | F27: BOFU | G27: Secondary | H27: 20 | I27: 15 | J27: SERP Competition Analysis | K27: 9.2 | L27: Commercial Intent Analysis | M27: =LOOKUP(I27,Methodology!$B$46:$B$49,Methodology!$C$46:$C$49) -> Easy | N27: Local GBP pack; nearby town practices; directories (Yelp / Healthgrades / Vitals) | O27: 5 | P27: =LOOKUP(H27,Methodology!$B$15:$B$19,Methodology!$C$15:$C$19) -> 2 | Q27: =LOOKUP(I27,Methodology!$B$23:$B$27,Methodology!$C$23:$C$27) -> 5 | R27: {=INDEX(Methodology!$C$31:$C$34,MATCH(E27,Methodology!$B$31:$B$34,0))} -> 5 | S27: 5 | T27: 4 | U27: =ROUND((O27*Methodology!$C$5+P27*Methodology!$C$6+Q27*Methodology!$C$7+R27*Methodology!$C$8+S27*Methodology!$C$9+T27*Methodology!$C$10)*20,0) -> 89 | V27: =LOOKUP(U27,Methodology!$B$38:$B$42,Methodology!$C$38:$C$42) -> High | W27: /emergency-exam | X27: Optimize | Z27: Regional
A28: dentist for tooth pain rainsville al | B28: Problem-Based | C28: Emergency Dentist | D28: Emergency Dental Care | E28: Transactional | F28: BOFU | G28: Secondary | H28: 10 | I28: 10 | J28: SERP Competition Analysis | K28: 8.4 | L28: Commercial Intent Analysis | M28: =LOOKUP(I28,Methodology!$B$46:$B$49,Methodology!$C$46:$C$49) -> Easy | N28: Local GBP pack; nearby dental practices (Fort Payne / Scottsboro area); Yelp; Healthgrades | O28: 5 | P28: =LOOKUP(H28,Methodology!$B$15:$B$19,Methodology!$C$15:$C$19) -> 1 | Q28: =LOOKUP(I28,Methodology!$B$23:$B$27,Methodology!$C$23:$C$27) -> 5 | R28: {=INDEX(Methodology!$C$31:$C$34,MATCH(E28,Methodology!$B$31:$B$34,0))} -> 5 | S28: 5 | T28: 4 | U28: =ROUND((O28*Methodology!$C$5+P28*Methodology!$C$6+Q28*Methodology!$C$7+R28*Methodology!$C$8+S28*Methodology!$C$9+T28*Methodology!$C$10)*20,0) -> 86 | V28: =LOOKUP(U28,Methodology!$B$38:$B$42,Methodology!$C$38:$C$42) -> High | W28: /emergency-exam | X28: Optimize | Z28: Local
A29: emergency dentist near me | B29: Transactional | C29: Emergency Dentist | D29: Emergency Dental Care | E29: Transactional | F29: BOFU | G29: Secondary | H29: 74000 | I29: 70 | J29: SERP Competition Analysis | K29: 11.4 | L29: Commercial Intent Analysis | M29: =LOOKUP(I29,Methodology!$B$46:$B$49,Methodology!$C$46:$C$49) -> Competitive | N29: Local GBP pack; nearby dental practices (Fort Payne / Scottsboro area); Yelp; Healthgrades | O29: 5 | P29: =LOOKUP(H29,Methodology!$B$15:$B$19,Methodology!$C$15:$C$19) -> 5 | Q29: =LOOKUP(I29,Methodology!$B$23:$B$27,Methodology!$C$23:$C$27) -> 1 | R29: {=INDEX(Methodology!$C$31:$C$34,MATCH(E29,Methodology!$B$31:$B$34,0))} -> 5 | S29: 5 | T29: 4 | U29: =ROUND((O29*Methodology!$C$5+P29*Methodology!$C$6+Q29*Methodology!$C$7+R29*Methodology!$C$8+S29*Methodology!$C$9+T29*Methodology!$C$10)*20,0) -> 82 | V29: =LOOKUP(U29,Methodology!$B$38:$B$42,Methodology!$C$38:$C$42) -> High | W29: /emergency-exam | X29: Optimize | Y29: Benchmark head term. | Z29: National
A30: same day dentist appointment near me | B30: Transactional | C30: Emergency Dentist | D30: Emergency Dental Care | E30: Transactional | F30: BOFU | G30: Secondary | H30: 5400 | I30: 48 | J30: SERP Competition Analysis | K30: 9.2 | L30: Commercial Intent Analysis | M30: =LOOKUP(I30,Methodology!$B$46:$B$49,Methodology!$C$46:$C$49) -> Competitive | N30: Local GBP pack; nearby dental practices (Fort Payne / Scottsboro area); Yelp; Healthgrades | O30: 5 | P30: =LOOKUP(H30,Methodology!$B$15:$B$19,Methodology!$C$15:$C$19) -> 5 | Q30: =LOOKUP(I30,Methodology!$B$23:$B$27,Methodology!$C$23:$C$27) -> 2 | R30: {=INDEX(Methodology!$C$31:$C$34,MATCH(E30,Methodology!$B$31:$B$34,0))} -> 5 | S30: 5 | T30: 4 | U30: =ROUND((O30*Methodology!$C$5+P30*Methodology!$C$6+Q30*Methodology!$C$7+R30*Methodology!$C$8+S30*Methodology!$C$9+T30*Methodology!$C$10)*20,0) -> 86 | V30: =LOOKUP(U30,Methodology!$B$38:$B$42,Methodology!$C$38:$C$42) -> High | W30: /emergency-exam | X30: Optimize | Z30: National
A31: what to do for a toothache at night | B31: Problem-Based | C31: Emergency Dentist | D31: Emergency Dental Care | E31: Informational | F31: TOFU | G31: Secondary | H31: 1900 | I31: 28 | J31: SERP Competition Analysis | K31: 1.4 | L31: Commercial Intent Analysis | M31: =LOOKUP(I31,Methodology!$B$46:$B$49,Methodology!$C$46:$C$49) -> Moderate | N31: WebMD; Colgate; Healthline; Mayo Clinic; ADA MouthHealthy | O31: 4 | P31: =LOOKUP(H31,Methodology!$B$15:$B$19,Methodology!$C$15:$C$19) -> 5 | Q31: =LOOKUP(I31,Methodology!$B$23:$B$27,Methodology!$C$23:$C$27) -> 3 | R31: {=INDEX(Methodology!$C$31:$C$34,MATCH(E31,Methodology!$B$31:$B$34,0))} -> 2 | S31: 1 | T31: 3 | U31: =ROUND((O31*Methodology!$C$5+P31*Methodology!$C$6+Q31*Methodology!$C$7+R31*Methodology!$C$8+S31*Methodology!$C$9+T31*Methodology!$C$10)*20,0) -> 62 | V31: =LOOKUP(U31,Methodology!$B$38:$B$42,Methodology!$C$38:$C$42) -> Medium | W31: /blog/toothache-at-night-what-to-do | X31: Create | Z31: National
A32: chipped tooth what to do | B32: Problem-Based | C32: Emergency Dentist | D32: Emergency Dental Care | E32: Informational | F32: TOFU | G32: Secondary | H32: 6600 | I32: 40 | J32: SERP Competition Analysis | K32: 3.1 | L32: Commercial Intent Analysis | M32: =LOOKUP(I32,Methodology!$B$46:$B$49,Methodology!$C$46:$C$49) -> Moderate | N32: WebMD; Colgate; Healthline; Mayo Clinic; ADA MouthHealthy | O32: 4 | P32: =LOOKUP(H32,Methodology!$B$15:$B$19,Methodology!$C$15:$C$19) -> 5 | Q32: =LOOKUP(I32,Methodology!$B$23:$B$27,Methodology!$C$23:$C$27) -> 3 | R32: {=INDEX(Methodology!$C$31:$C$34,MATCH(E32,Methodology!$B$31:$B$34,0))} -> 2 | S32: 1 | T32: 3 | U32: =ROUND((O32*Methodology!$C$5+P32*Methodology!$C$6+Q32*Methodology!$C$7+R32*Methodology!$C$8+S32*Methodology!$C$9+T32*Methodology!$C$10)*20,0) -> 62 | V32: =LOOKUP(U32,Methodology!$B$38:$B$42,Methodology!$C$38:$C$42) -> Medium | W32: /blog/dental-emergencies-chipped-or-knocked-out-tooth | X32: Create | Z32: National
A33: knocked out tooth what to do | B33: Problem-Based | C33: Emergency Dentist | D33: Emergency Dental Care | E33: Informational | F33: TOFU | G33: Secondary | H33: 2900 | I33: 36 | J33: SERP Competition Analysis | K33: 3.4 | L33: Commercial Intent Analysis | M33: =LOOKUP(I33,Methodology!$B$46:$B$49,Methodology!$C$46:$C$49) -> Moderate | N33: WebMD; Colgate; Healthline; Mayo Clinic; ADA MouthHealthy | O33: 4 | P33: =LOOKUP(H33,Methodology!$B$15:$B$19,Methodology!$C$15:$C$19) -> 5 | Q33: =LOOKUP(I33,Methodology!$B$23:$B$27,Methodology!$C$23:$C$27) -> 3 | R33: {=INDEX(Methodology!$C$31:$C$34,MATCH(E33,Methodology!$B$31:$B$34,0))} -> 2 | S33: 1 | T33: 3 | U33: =ROUND((O33*Methodology!$C$5+P33*Methodology!$C$6+Q33*Methodology!$C$7+R33*Methodology!$C$8+S33*Methodology!$C$9+T33*Methodology!$C$10)*20,0) -> 62 | V33: =LOOKUP(U33,Methodology!$B$38:$B$42,Methodology!$C$38:$C$42) -> Medium | W33: /blog/dental-emergencies-chipped-or-knocked-out-tooth | X33: Create | Z33: National
A34: dental abscess symptoms | B34: Problem-Based | C34: Emergency Dentist | D34: Emergency Dental Care | E34: Informational | F34: TOFU | G34: Secondary | H34: 8100 | I34: 48 | J34: SERP Competition Analysis | K34: 2.2 | L34: Commercial Intent Analysis | M34: =LOOKUP(I34,Methodology!$B$46:$B$49,Methodology!$C$46:$C$49) -> Competitive | N34: WebMD; Colgate; Healthline; Mayo Clinic; ADA MouthHealthy | O34: 4 | P34: =LOOKUP(H34,Methodology!$B$15:$B$19,Methodology!$C$15:$C$19) -> 5 | Q34: =LOOKUP(I34,Methodology!$B$23:$B$27,Methodology!$C$23:$C$27) -> 2 | R34: {=INDEX(Methodology!$C$31:$C$34,MATCH(E34,Methodology!$B$31:$B$34,0))} -> 2 | S34: 1 | T34: 3 | U34: =ROUND((O34*Methodology!$C$5+P34*Methodology!$C$6+Q34*Methodology!$C$7+R34*Methodology!$C$8+S34*Methodology!$C$9+T34*Methodology!$C$10)*20,0) -> 58 | V34: =LOOKUP(U34,Methodology!$B$38:$B$42,Methodology!$C$38:$C$42) -> Low | W34: /blog/dental-abscess-symptoms-when-to-seek-care | X34: Create | Z34: National
A35: dental fillings rainsville al | B35: Core Service | C35: Dental Fillings | D35: Fillings & Cavity Care | E35: Transactional | F35: BOFU | G35: Primary | H35: 20 | I35: 10 | J35: SERP Competition Analysis | K35: 5.7 | L35: Commercial Intent Analysis | M35: =LOOKUP(I35,Methodology!$B$46:$B$49,Methodology!$C$46:$C$49) -> Easy | N35: Local GBP pack; nearby dental practices (Fort Payne / Scottsboro area); Yelp; Healthgrades | O35: 3 | P35: =LOOKUP(H35,Methodology!$B$15:$B$19,Methodology!$C$15:$C$19) -> 2 | Q35: =LOOKUP(I35,Methodology!$B$23:$B$27,Methodology!$C$23:$C$27) -> 5 | R35: {=INDEX(Methodology!$C$31:$C$34,MATCH(E35,Methodology!$B$31:$B$34,0))} -> 5 | S35: 5 | T35: 4 | U35: =ROUND((O35*Methodology!$C$5+P35*Methodology!$C$6+Q35*Methodology!$C$7+R35*Methodology!$C$8+S35*Methodology!$C$9+T35*Methodology!$C$10)*20,0) -> 79 | V35: =LOOKUP(U35,Methodology!$B$38:$B$42,Methodology!$C$38:$C$42) -> High | W35: /fillings | X35: Optimize | Z35: Local
A36: tooth filling near me | B36: Transactional | C36: Dental Fillings | D36: Fillings & Cavity Care | E36: Transactional | F36: BOFU | G36: Secondary | H36: 8100 | I36: 55 | J36: SERP Competition Analysis | K36: 6.5 | L36: Commercial Intent Analysis | M36: =LOOKUP(I36,Methodology!$B$46:$B$49,Methodology!$C$46:$C$49) -> Competitive | N36: Local GBP pack; nearby dental practices (Fort Payne / Scottsboro area); Yelp; Healthgrades | O36: 3 | P36: =LOOKUP(H36,Methodology!$B$15:$B$19,Methodology!$C$15:$C$19) -> 5 | Q36: =LOOKUP(I36,Methodology!$B$23:$B$27,Methodology!$C$23:$C$27) -> 2 | R36: {=INDEX(Methodology!$C$31:$C$34,MATCH(E36,Methodology!$B$31:$B$34,0))} -> 5 | S36: 5 | T36: 4 | U36: =ROUND((O36*Methodology!$C$5+P36*Methodology!$C$6+Q36*Methodology!$C$7+R36*Methodology!$C$8+S36*Methodology!$C$9+T36*Methodology!$C$10)*20,0) -> 76 | V36: =LOOKUP(U36,Methodology!$B$38:$B$42,Methodology!$C$38:$C$42) -> High | W36: /fillings | X36: Optimize | Z36: National
A37: cavity filling cost | B37: Commercial | C37: Dental Fillings | D37: Fillings & Cavity Care | E37: Commercial | F37: MOFU | G37: Secondary | H37: 4400 | I37: 45 | J37: SERP Competition Analysis | K37: 5.6 | L37: Commercial Intent Analysis | M37: =LOOKUP(I37,Methodology!$B$46:$B$49,Methodology!$C$46:$C$49) -> Competitive | N37: Cost guides (Delta Dental, Colgate, Healthline); regional practices; directories | O37: 3 | P37: =LOOKUP(H37,Methodology!$B$15:$B$19,Methodology!$C$15:$C$19) -> 5 | Q37: =LOOKUP(I37,Methodology!$B$23:$B$27,Methodology!$C$23:$C$27) -> 2 | R37: {=INDEX(Methodology!$C$31:$C$34,MATCH(E37,Methodology!$B$31:$B$34,0))} -> 4 | S37: 3 | T37: 4 | U37: =ROUND((O37*Methodology!$C$5+P37*Methodology!$C$6+Q37*Methodology!$C$7+R37*Methodology!$C$8+S37*Methodology!$C$9+T37*Methodology!$C$10)*20,0) -> 67 | V37: =LOOKUP(U37,Methodology!$B$38:$B$42,Methodology!$C$38:$C$42) -> Medium | W37: /fillings | X37: Optimize | Z37: National
A38: white fillings | B38: Commercial | C38: Dental Fillings | D38: Fillings & Cavity Care | E38: Commercial | F38: MOFU | G38: Secondary | H38: 3600 | I38: 40 | J38: SERP Competition Analysis | K38: 3.9 | L38: Commercial Intent Analysis | M38: =LOOKUP(I38,Methodology!$B$46:$B$49,Methodology!$C$46:$C$49) -> Moderate | N38: WebMD; Colgate; Healthline; Mayo Clinic; ADA MouthHealthy | O38: 3 | P38: =LOOKUP(H38,Methodology!$B$15:$B$19,Methodology!$C$15:$C$19) -> 5 | Q38: =LOOKUP(I38,Methodology!$B$23:$B$27,Methodology!$C$23:$C$27) -> 3 | R38: {=INDEX(Methodology!$C$31:$C$34,MATCH(E38,Methodology!$B$31:$B$34,0))} -> 4 | S38: 3 | T38: 4 | U38: =ROUND((O38*Methodology!$C$5+P38*Methodology!$C$6+Q38*Methodology!$C$7+R38*Methodology!$C$8+S38*Methodology!$C$9+T38*Methodology!$C$10)*20,0) -> 71 | V38: =LOOKUP(U38,Methodology!$B$38:$B$42,Methodology!$C$38:$C$42) -> Medium | W38: /fillings | X38: Optimize | Z38: National
A39: composite vs amalgam fillings | B39: Comparison | C39: Dental Fillings | D39: Fillings & Cavity Care | E39: Commercial | F39: MOFU | G39: Secondary | H39: 1900 | I39: 38 | J39: SERP Competition Analysis | K39: 2.4 | L39: Commercial Intent Analysis | M39: =LOOKUP(I39,Methodology!$B$46:$B$49,Methodology!$C$46:$C$49) -> Moderate | N39: WebMD; Colgate; Healthline; Mayo Clinic; ADA MouthHealthy | O39: 3 | P39: =LOOKUP(H39,Methodology!$B$15:$B$19,Methodology!$C$15:$C$19) -> 5 | Q39: =LOOKUP(I39,Methodology!$B$23:$B$27,Methodology!$C$23:$C$27) -> 3 | R39: {=INDEX(Methodology!$C$31:$C$34,MATCH(E39,Methodology!$B$31:$B$34,0))} -> 4 | S39: 3 | T39: 4 | U39: =ROUND((O39*Methodology!$C$5+P39*Methodology!$C$6+Q39*Methodology!$C$7+R39*Methodology!$C$8+S39*Methodology!$C$9+T39*Methodology!$C$10)*20,0) -> 71 | V39: =LOOKUP(U39,Methodology!$B$38:$B$42,Methodology!$C$38:$C$42) -> Medium | W39: /blog/composite-vs-amalgam-fillings | X39: Create | Z39: National
A40: signs of a cavity | B40: Problem-Based | C40: Dental Fillings | D40: Fillings & Cavity Care | E40: Informational | F40: TOFU | G40: Secondary | H40: 6600 | I40: 42 | J40: SERP Competition Analysis | K40: 1.9 | L40: Commercial Intent Analysis | M40: =LOOKUP(I40,Methodology!$B$46:$B$49,Methodology!$C$46:$C$49) -> Competitive | N40: WebMD; Colgate; Healthline; Mayo Clinic; ADA MouthHealthy | O40: 2 | P40: =LOOKUP(H40,Methodology!$B$15:$B$19,Methodology!$C$15:$C$19) -> 5 | Q40: =LOOKUP(I40,Methodology!$B$23:$B$27,Methodology!$C$23:$C$27) -> 2 | R40: {=INDEX(Methodology!$C$31:$C$34,MATCH(E40,Methodology!$B$31:$B$34,0))} -> 2 | S40: 1 | T40: 3 | U40: =ROUND((O40*Methodology!$C$5+P40*Methodology!$C$6+Q40*Methodology!$C$7+R40*Methodology!$C$8+S40*Methodology!$C$9+T40*Methodology!$C$10)*20,0) -> 48 | V40: =LOOKUP(U40,Methodology!$B$38:$B$42,Methodology!$C$38:$C$42) -> Low | W40: /blog/signs-of-a-cavity | X40: Create | Z40: National
...

Sheet Keyword Clusters
A1: Cluster Name | B1: Primary Keyword | C1: Secondary Keywords | D1: Questions | E1: Entities | F1: Intent | G1: Funnel Stage | H1: Recommended Page | I1: Page Type | J1: # Keywords in Cluster | K1: Est. Local + Regional Monthly Volume
A2: Brand & Navigational | B2: carter family dentistry rainsville al | C2: carter family dentistry; carterdentistry.com; carter family dentistry reviews; carter family dentistry phone number; carter family dentistry hours | D2: Where is Carter Family Dentistry in Rainsville? What are Carter Family Dentistry's hours? | E2: Carter Family Dentistry, LLC; Rainsville AL; 20 Bartlett Ave; (256) 638-2121 | F2: Navigational | G2: BOFU | H2: / | I2: Homepage | J2: =COUNTIF('Keyword Master Database'!$D$2:$D$137,A2) -> 7 | K2: =SUMIFS('Keyword Master Database'!$H$2:$H$137,'Keyword Master Database'!$D$2:$D$137,A2,'Keyword Master Database'!$Z$2:$Z$137,"<>National") -> 250
A3: Local Dentist – Rainsville & DeKalb | B3: dentist in rainsville al | C3: dentist rainsville alabama; dental office rainsville al; general dentist rainsville al; best dentist in rainsville al; dentist near me | D3: Who is the best dentist in Rainsville, AL? Is there a dentist near me accepting new patients? | E3: Rainsville; DeKalb County; Sand Mountain; Google Business Profile | F3: Transactional | G3: BOFU | H3: / | I3: Homepage | J3: =COUNTIF('Keyword Master Database'!$D$2:$D$137,A3) -> 9 | K3: =SUMIFS('Keyword Master Database'!$H$2:$H$137,'Keyword Master Database'!$D$2:$D$137,A3,'Keyword Master Database'!$Z$2:$Z$137,"<>National") -> 290
A4: Exams & Preventive Care | B4: dental exam rainsville al | C4: dental cleaning rainsville al; new patient dental exam; dental checkup near me; family dentist rainsville al; kids dentist rainsville al | D4: What happens at a dental exam? How often should I get a cleaning? | E4: Dental exam; prophylaxis; oral cancer screening; hygienist | F4: Transactional | G4: BOFU | H4: /dental-exams | I4: Service Page | J4: =COUNTIF('Keyword Master Database'!$D$2:$D$137,A4) -> 8 | K4: =SUMIFS('Keyword Master Database'!$H$2:$H$137,'Keyword Master Database'!$D$2:$D$137,A4,'Keyword Master Database'!$Z$2:$Z$137,"<>National") -> 120
A5: Emergency Dental Care | B5: emergency dentist rainsville al | C5: emergency dentist dekalb county al; dentist for tooth pain rainsville al; same day dentist appointment near me; dental abscess symptoms; chipped tooth what to do | D5: What counts as a dental emergency? What do I do about a toothache at night? | E5: Toothache; abscess; broken tooth; swelling; emergency exam | F5: Transactional | G5: BOFU | H5: /emergency-exam | I5: Service Page | J5: =COUNTIF('Keyword Master Database'!$D$2:$D$137,A5) -> 9 | K5: =SUMIFS('Keyword Master Database'!$H$2:$H$137,'Keyword Master Database'!$D$2:$D$137,A5,'Keyword Master Database'!$Z$2:$Z$137,"<>National") -> 70
A6: Fillings & Cavity Care | B6: dental fillings rainsville al | C6: tooth filling near me; cavity filling cost; white fillings; composite vs amalgam fillings; signs of a cavity | D6: How much does a filling cost? Are white fillings better than silver? | E6: Composite resin; amalgam; tooth decay; cavity | F6: Transactional | G6: BOFU | H6: /fillings | I6: Service Page | J6: =COUNTIF('Keyword Master Database'!$D$2:$D$137,A6) -> 7 | K6: =SUMIFS('Keyword Master Database'!$H$2:$H$137,'Keyword Master Database'!$D$2:$D$137,A6,'Keyword Master Database'!$Z$2:$Z$137,"<>National") -> 20
A7: Silver Diamine Fluoride (SDF) | B7: silver diamine fluoride rainsville al | C7: silver diamine fluoride; silver diamine fluoride for adults; silver diamine fluoride cost; silver diamine fluoride side effects | D7: What is silver diamine fluoride? Does SDF stain teeth? | E7: SDF; fluoride; non-invasive cavity arrest; tooth decay | F7: Transactional | G7: BOFU | H7: /silver-diamine-fluoride | I7: Service Page | J7: =COUNTIF('Keyword Master Database'!$D$2:$D$137,A7) -> 5 | K7: =SUMIFS('Keyword Master Database'!$H$2:$H$137,'Keyword Master Database'!$D$2:$D$137,A7,'Keyword Master Database'!$Z$2:$Z$137,"<>National") -> 10
A8: Dental Crowns | B8: dental crowns rainsville al | C8: dental crown cost; crown vs filling; tooth crown procedure; how long do dental crowns last; same day crowns near me | D8: How much does a dental crown cost? How long do crowns last? | E8: Porcelain; ceramic; zirconia; cap; tooth restoration | F8: Transactional | G8: BOFU | H8: /crowns | I8: Service Page | J8: =COUNTIF('Keyword Master Database'!$D$2:$D$137,A8) -> 6 | K8: =SUMIFS('Keyword Master Database'!$H$2:$H$137,'Keyword Master Database'!$D$2:$D$137,A8,'Keyword Master Database'!$Z$2:$Z$137,"<>National") -> 20
A9: Dental Bridges | B9: dental bridges rainsville al | C9: dental bridge cost; how long does a dental bridge last; dental bridge vs implant | D9: Is a bridge or an implant better? How long does a bridge last? | E9: Pontic; abutment teeth; fixed bridge; tooth replacement | F9: Transactional | G9: BOFU | H9: /bridges | I9: Service Page | J9: =COUNTIF('Keyword Master Database'!$D$2:$D$137,A9) -> 4 | K9: =SUMIFS('Keyword Master Database'!$H$2:$H$137,'Keyword Master Database'!$D$2:$D$137,A9,'Keyword Master Database'!$Z$2:$Z$137,"<>National") -> 10
A10: Root Canals | B10: root canal rainsville al | C10: root canal near me; root canal cost; root canal symptoms; is a root canal painful; root canal vs extraction | D10: Is a root canal painful? How much does a root canal cost? | E10: Endodontic therapy; pulp; infection; crown after root canal | F10: Transactional | G10: BOFU | H10: /root-canals | I10: Service Page | J10: =COUNTIF('Keyword Master Database'!$D$2:$D$137,A10) -> 7 | K10: =SUMIFS('Keyword Master Database'!$H$2:$H$137,'Keyword Master Database'!$D$2:$D$137,A10,'Keyword Master Database'!$Z$2:$Z$137,"<>National") -> 30
A11: Tooth Extractions | B11: tooth extraction rainsville al | C11: tooth extraction near me; tooth extraction cost; wisdom tooth removal rainsville al; tooth extraction aftercare; dry socket symptoms | D11: How long does extraction healing take? What is dry socket? | E11: Simple extraction; surgical extraction; wisdom teeth; socket | F11: Transactional | G11: BOFU | H11: /extractions | I11: Service Page | J11: =COUNTIF('Keyword Master Database'!$D$2:$D$137,A11) -> 6 | K11: =SUMIFS('Keyword Master Database'!$H$2:$H$137,'Keyword Master Database'!$D$2:$D$137,A11,'Keyword Master Database'!$Z$2:$Z$137,"<>National") -> 30
A12: Dental Implants | B12: dental implants rainsville al | C12: dental implants near me; dental implant cost; dental implants vs dentures; are dental implants worth it; single tooth implant cost | D12: How much do dental implants cost in Alabama? Are implants better than dentures? | E12: Titanium post; abutment; osseointegration; implant crown | F12: Transactional | G12: BOFU | H12: /implants | I12: Service Page | J12: =COUNTIF('Keyword Master Database'!$D$2:$D$137,A12) -> 10 | K12: =SUMIFS('Keyword Master Database'!$H$2:$H$137,'Keyword Master Database'!$D$2:$D$137,A12,'Keyword Master Database'!$Z$2:$Z$137,"<>National") -> 250
A13: Dentures | B13: dentures rainsville al | C13: dentures near me; how much do dentures cost; affordable dentures alabama; immediate dentures; full dentures vs partial dentures | D13: How much do dentures cost? How long do dentures last? | E13: Full dentures; immediate dentures; denture fitting; edentulism | F13: Transactional | G13: BOFU | H13: /dentures | I13: Service Page | J13: =COUNTIF('Keyword Master Database'!$D$2:$D$137,A13) -> 6 | K13: =SUMIFS('Keyword Master Database'!$H$2:$H$137,'Keyword Master Database'!$D$2:$D$137,A13,'Keyword Master Database'!$Z$2:$Z$137,"<>National") -> 350
... A20: Dr. Emily Carter & Female Dentist | B20: female dentist rainsville al | C20: dr emily carter rainsville al; dr emily carter dentist; female dentist near me | D20: Is there a female dentist in Rainsville? Who is Dr. Emily Carter? | E20: Dr. Emily Carter; female dentist; credentials; patient care philosophy | F20: Transactional | G20: BOFU | H20: /meet-dr-emily-carter | I20: Trust / E-E-A-T Page | J20: =COUNTIF('Keyword Master Database'!$D$2:$D$137,A20) -> 4 | K20: =SUMIFS('Keyword Master Database'!$H$2:$H$137,'Keyword Master Database'!$D$2:$D$137,A20,'Keyword Master Database'!$Z$2:$Z$137,"<>National") -> 130

Sheet Competitor Analysis
A1: Competitor | B1: URL | C1: Ranking Topics | D1: Strong Pages | E1: Weakness | F1: Content Gap | G1: Opportunity | H1: Verification Status
A2: Carter Family Dentistry (Boise, ID) | B2: carterfamilydds.com | C2: Branded 'Carter Family Dentistry' queries; Boise / Treasure Valley general dentistry, cosmetic, Invisalign and veneers (per public listings). | D2: Not audited – organic data unavailable. Public listings show a family-owned practice established 1973 with strong Google ratings. | E2: Located in Boise, Idaho – no local-pack overlap with Rainsville, AL. Competes only for the shared brand name. | F2: No Alabama relevance; Rainsville-specific, DeKalb/Jackson County content is entirely absent. | G2: Own the branded SERP with city + Dr. Emily Carter in titles, LocalBusiness schema, consistent NAP and GBP. Always use 'Rainsville, AL' in brand anchors. | H2: Partially verified (public listings). Organic keywords to be pulled in Semrush.
A3: Dr. Tara's Dental Village | B3: drtarasdentalvillage.com | C3: To be validated in Semrush Organic Research. | D3: To be validated. | E3: Could not be confirmed as a Rainsville-area practice through public search – location/relevance unverified. | F3: To be determined after Semrush export. | G3: If confirmed local, mine its ranking service pages for keyword gaps (implants, dentures, emergency). | H3: Unverified – client-supplied. Confirm location and organic footprint.
A4: Carter Orthodontics / Carter Braces (Rainsville, AL) | B4: carterbraces.com | C4: Orthodontics / braces in Rainsville, AL (practice of Dr. Jared Carter, DMD, MS, per AAO and directory listings). | D4: Not audited. | E4: Specialty orthodontic practice – little overlap with general, restorative and emergency services. Similar Carter name can cause local brand confusion. | F4: General dentistry, restorative and tooth-replacement content is outside its scope. | G4: Differentiate on general/family/restorative care; keep branded SERP clean; consider a referral relationship for ortho cases. | H4: Partially verified (AAO / directory listings). Organic data to be pulled.
A5: Fort Payne & Scottsboro general dental practices | B5: (identify in Semrush / local-pack check) | C5: dentist fort payne al; dentist scottsboro al; implants, dentures and emergency dentist in nearby towns. | D5: Typically service pages and location pages for the larger towns. | E5: Pattern-based: many small-practice sites have thin service pages and no FAQ/blog content. | F5: Rainsville and smaller-town (Henagar, Valley Head, Sylvania, Section) demand is often under-served. | G5: Create Fort Payne / Scottsboro pages and a service-area hub to capture overflow demand. | H5: Pattern-based estimate – named competitors not verified.
A6: Dental directories (Healthgrades, Vitals, WebMD Care, Yelp) | B6: healthgrades.com / vitals.com / doctor.webmd.com / yelp.com | C6: Provider and practice name searches; 'dentist in [town]' directory pages. | D6: Practice and provider profile pages. | E6: Generic profiles, no service depth, no conversion path owned by the practice. | F6: Detailed service, cost and insurance information. | G6: Claim and complete profiles with consistent NAP; use reviews and service lists to feed citation signals. | H6: Observed in public search results for Carter-name dentist queries.
A7: Practice-finder / AI-profile aggregators | B7: local.newpatientsinc.com / lantern.llc | C7: Practice-name and 'dentist in [city]' queries. | D7: Auto-generated practice pages. | E7: Third-party data may be incomplete or outdated. | F7: Accurate hours, services and insurance details. | G7: Keep website facts identical to listings; add structured data so AI search tools read accurate details. | H7: Observed in public search results.
A8: National dental education publishers (Colgate, Healthline, Delta Dental, Mayo Clinic, ADA MouthHealthy) | B8: colgate.com / healthline.com / deltadental.com / mayoclinic.org | C8: Informational and problem keywords: root canal symptoms, dry socket, implant procedure, x-ray safety. | D8: Long-form guides with high domain authority. | E8: Not local, no appointment path, no Alabama pricing or insurance context. | F8: Local cost context (Alabama), BCBS of Alabama / Southland insurance questions, Dr. Emily Carter's expert voice. | G8: Publish concise, locally framed answers with FAQ schema; target the lowest-KD questions first. | H8: Pattern-based estimate for these SERPs.

Sheet Keyword Mapping
A1: URL | B1: Page Name | C1: Primary Keyword | D1: Secondary Keywords | E1: Intent | F1: Funnel Stage | G1: Existing / New | H1: Action | I1: Cannibalization Risk
