Workbook

Sheet Business Analysis
B2: SEO KEYWORD RESEARCH & STRATEGY WORKBOOK
B3: Dental Office of Tampa | Tampa, Florida | United States Of America
B5: Prepared by Md. Abdul Alim – Dental SEO & AI Search Optimization Consultant
B8: Field | C8: Detail
B9: Business Name | C9: Dental Office of Tampa
B10: Website | C10: https://www.dentalofficeoftampa.com/
B11: Industry | C11: Dental Clinic (general / family dentistry)
B12: Country | C12: United States
B13: Location | C13: 3955 Moran Rd Ste 101, Tampa, FL 33618
B14: Services | C14: Dental Sealants; Clear Braces - Invisalign; Fillings & Restorations; Dentures; Dental Bridges; Dental Crowns
B15: Products | C15: N/A - service business (no e-commerce products)
B16: Goal | C16: 1) Generate more local leads 2) Increase organic traffic 3) Improve service page rankings 4) Build topical authority
B17: Primary SEO Focus | C17: Local SEO
B20: BUSINESS ANALYSIS | CURRENT SEO POSTION
B21: Area | C21: Finding | D21: Evidence Observed | E21: SEO Impact | F21: Recommendation | G21: Priority
B22: Title tag | C22: Repetitive, brand duplicated, keyword repeated | D22: Title reads 'Dental Office of Tampa Home - Dental Office of Tampa- Dentist in Tampa Dentist in Tampa'. | E22: Weak relevance signal and poor SERP appearance for the primary local keyword. | F22: Use e.g. 'Dentist in Tampa, FL | Dental Office of Tampa' (about 45 characters). | G22: Critical
B23: Meta description | C23: Present but long | D23: Description runs well beyond typical SERP display length (cleanings, Invisalign, crowns, dentures, restorative). | E23: Truncation reduces click-through. | F23: Shorten to about 150 characters; include phone number and free-cleaning offer. | G23: High
B24: H1 / on-page heading | C24: Brand tagline instead of keyword | D24: Hero heading is 'Tampa Bay's Smile Destination'; 'Dentist in Tampa' appears only in body copy. | E24: Primary keyword is not emphasized in the main heading. | F24: Make the H1 'Dentist in Tampa, FL' (tagline as subhead). | G24: High
B25: Service page URLs | C25: Nav and body links point to different slugs | D25: Nav: /dental-bridges-tampa/, /dental-cap-crown-tampa/; homepage body: /dental-bridges/, /dental-crowns/, /dentures/. Nav 'Dentures' links to /dental-implant-tampa/. | E25: Possible duplicate pages, split link equity, cannibalization. | F25: Pick one canonical URL per service, 301 the rest, align nav and body links. | G25: Critical
B26: Services coverage | C26: Core services have pages; supporting pages missing | D26: Nav lists 6 treatment pages. No pages for cleanings, emergency, root canal, extractions, whitening or dedicated implants seen. | E26: Missed local-intent searches with high CPC. | F26: Add cleaning, emergency (if offered), implants (separate), root canal and extraction pages in phases. | G26: High
B27: Offer visibility | C27: Strong offer without dedicated page | D27: Hero offer: free teeth cleaning with $140 exam and x-ray; tiles for free smile analysis and cost of treatment. | E27: Offer terms are a rankable, conversion-focused opportunity. | F27: Create /new-patient-special-tampa/ and consolidate pricing/free-analysis tiles into real pages. | G27: High
B28: Local signals | C28: NAP, hours and map link visible | D28: Address, phone (813) 450-1212, hours and Google Maps link on the homepage. | E28: Good foundation for local SEO. | F28: Add LocalBusiness / Dentist schema, embed map, keep NAP identical across GBP and citations. | G28: Medium
B29: Directions page | C29: 'Map & Directions' points to the booking form | D29: Nav item links to /appointment-form/. | E29: No proper location/directions content for local relevance. | F29: Create a real Directions section on /north-tampa-dentist/ and /our-office/. | G29: Medium
B30: Reviews | C30: Reviews reference other locations | D30: Homepage invites reviews on a 'new Google page' and cites five-star reviews from the Dunedin location. | E30: Tampa location review volume may be low - a local-pack ranking factor. | F30: Run a review-generation program; add on-site review block with Tampa reviews. | G30: High
B31: Blog / content | C31: No blog; news page has non-descriptive slug | D31: 'News and info' links to /1058-2/. | E31: No informational coverage for TOFU searches. | F31: Create /blog/ and publish the roadmap posts. | G31: Medium
B32: Copy quality | C32: Generic service copy, typos | D32: Homepage bridges text contains a duplicated word ('replace missing a missing tooth'). | E32: Thin/templated copy weakens relevance and trust. | F32: Rewrite service copy with local context, process, FAQs and doctor expertise. | G32: Medium
... B34: Strengths | C34: Positives to keep | D34: Geo-modified service slugs (-tampa), indexable robots tags, caching plugin (WP Rocket), doctor-led content, YouTube video, free-cleaning offer, FAQs and insurance pages. | E34: Good base to build on. | F34: Preserve URLs that are canonical; build topical clusters around them. | G34: Low
B37: FUNNEL & INTENT DISTRIBUTION
B38: Segment | C38: Description | D38: Keywords | E38: Share | F38: Est. Volume | G38: Remarks
B39: TOFU | C39: Awareness - educational / problem keywords | D39: =COUNTIF('Keyword Master Database'!$F$2:$F$224,B39) -> 44 | E39: =D39/COUNTA('Keyword Master Database'!$A$2:$A$224) -> 0.19730942 | F39: =SUMIF('Keyword Master Database'!$F$2:$F$224,B39,'Keyword Master Database'!$H$2:$H$224) -> 96250
B40: MOFU | C40: Consideration - comparisons, cost research, reviews | D40: =COUNTIF('Keyword Master Database'!$F$2:$F$224,B40) -> 48 | E40: =D40/COUNTA('Keyword Master Database'!$A$2:$A$224) -> 0.21524664 | F40: =SUMIF('Keyword Master Database'!$F$2:$F$224,B40,'Keyword Master Database'!$H$2:$H$224) -> 109180
B41: BOFU | C41: Decision - service + location, near me, brand | D41: =COUNTIF('Keyword Master Database'!$F$2:$F$224,B41) -> 131 | E41: =D41/COUNTA('Keyword Master Database'!$A$2:$A$224) -> 0.58744395 | F41: =SUMIF('Keyword Master Database'!$F$2:$F$224,B41,'Keyword Master Database'!$H$2:$H$224) -> 89060
B42: Informational | C42: Learning intent | D42: =COUNTIF('Keyword Master Database'!$E$2:$E$224,B42) -> 44 | E42: =D42/COUNTA('Keyword Master Database'!$A$2:$A$224) -> 0.19730942 | F42: =SUMIF('Keyword Master Database'!$E$2:$E$224,B42,'Keyword Master Database'!$H$2:$H$224) -> 96250
B43: Navigational | C43: Brand / specific site intent | D43: =COUNTIF('Keyword Master Database'!$E$2:$E$224,B43) -> 5 | E43: =D43/COUNTA('Keyword Master Database'!$A$2:$A$224) -> 0.022421525 | F43: =SUMIF('Keyword Master Database'!$E$2:$E$224,B43,'Keyword Master Database'!$H$2:$H$224) -> 570
B44: Commercial | C44: Researching options | D44: =COUNTIF('Keyword Master Database'!$E$2:$E$224,B44) -> 48 | E44: =D44/COUNTA('Keyword Master Database'!$A$2:$A$224) -> 0.21524664 | F44: =SUMIF('Keyword Master Database'!$E$2:$E$224,B44,'Keyword Master Database'!$H$2:$H$224) -> 109180
B45: Transactional | C45: Ready to book / call | D45: =COUNTIF('Keyword Master Database'!$E$2:$E$224,B45) -> 126 | E45: =D45/COUNTA('Keyword Master Database'!$A$2:$A$224) -> 0.56502242 | F45: =SUMIF('Keyword Master Database'!$E$2:$E$224,B45,'Keyword Master Database'!$H$2:$H$224) -> 88490
B47: TOP 15 PRIORITY KEYWORDS
B48: Keyword | C48: Target URL | D48: Est. Volume | E48: Est. KD | F48: Priority Score | G48: Priority Level
B49: free teeth cleaning tampa | C49: {=INDEX('Keyword Master Database'!$R$2:$R$224,MATCH($B49,'Keyword Master Database'!$A$2:$A$224,0))} -> /new-patient-special-tampa/ | D49: {=INDEX('Keyword Master Database'!$H$2:$H$224,MATCH($B49,'Keyword Master Database'!$A$2:$A$224,0))} -> 210 | E49: {=INDEX('Keyword Master Database'!$I$2:$I$224,MATCH($B49,'Keyword Master Database'!$A$2:$A$224,0))} -> 20 | F49: {=INDEX('Keyword Master Database'!$P$2:$P$224,MATCH($B49,'Keyword Master Database'!$A$2:$A$224,0))} -> 94 | G49: {=INDEX('Keyword Master Database'!$Q$2:$Q$224,MATCH($B49,'Keyword Master Database'!$A$2:$A$224,0))} -> Critical
B50: dentures tampa | C50: {=INDEX('Keyword Master Database'!$R$2:$R$224,MATCH($B50,'Keyword Master Database'!$A$2:$A$224,0))} -> /dentures/ | D50: {=INDEX('Keyword Master Database'!$H$2:$H$224,MATCH($B50,'Keyword Master Database'!$A$2:$A$224,0))} -> 1000 | E50: {=INDEX('Keyword Master Database'!$I$2:$I$224,MATCH($B50,'Keyword Master Database'!$A$2:$A$224,0))} -> 48 | F50: {=INDEX('Keyword Master Database'!$P$2:$P$224,MATCH($B50,'Keyword Master Database'!$A$2:$A$224,0))} -> 92 | G50: {=INDEX('Keyword Master Database'!$Q$2:$Q$224,MATCH($B50,'Keyword Master Database'!$A$2:$A$224,0))} -> Critical
...

Sheet Keyword Master Database
A1: Keyword | B1: Keyword Type | C1: Parent Topic | D1: Cluster | E1: Search Intent | F1: Funnel Stage | G1: Primary/Secondary | H1: Search Volume | I1: KD | J1: KD Source | K1: Estimated CPC | L1: CPC Source | M1: SERP Competition | N1: Ranking Competitors | O1: Business Value | P1: Priority Score | Q1: Priority Level | R1: Target URL | S1: Recommended Action | T1: Notes
A2: dentist in tampa | B2: Location | C2: Local Dentistry - Tampa | D2: Local Core - Dentist in Tampa | E2: Transactional | F2: BOFU | G2: Primary | H2: 5400 | I2: 62 | J2: SERP Competition Analysis | K2: 9.8 | L2: Commercial Intent Analysis | M2: =IF(I2<=20,"Easy",IF(I2<=40,"Moderate",IF(I2<=70,"Competitive","Very Competitive"))) -> Competitive | N2: Gassler Dental; Tampa Bay Dental Team; Jackson Dental; Yelp / Healthgrades | O2: ='Priority Scoring'!B2 -> 5 | P2: ='Priority Scoring'!I2 -> 88 | Q2: ='Priority Scoring'!J2 -> High | R2: / | S2: Optimize | T2: Anchor local keyword; homepage title currently repeats brand and phrase - rewrite title/H1.
A3: tampa dentist | B3: Location | C3: Local Dentistry - Tampa | D3: Local Core - Dentist in Tampa | E3: Transactional | F3: BOFU | G3: Secondary | H3: 4400 | I3: 60 | J3: SERP Competition Analysis | K3: 9.2 | L3: Commercial Intent Analysis | M3: =IF(I3<=20,"Easy",IF(I3<=40,"Moderate",IF(I3<=70,"Competitive","Very Competitive"))) -> Competitive | N3: Gassler Dental; Tampa Bay Dental Team; Jackson Dental; Yelp / Healthgrades | O3: ='Priority Scoring'!B3 -> 5 | P3: ='Priority Scoring'!I3 -> 88 | Q3: ='Priority Scoring'!J3 -> High | R3: / | S3: Optimize | T3: Tampa-area volume estimate.
A4: dentist tampa fl | B4: Location | C4: Local Dentistry - Tampa | D4: Local Core - Dentist in Tampa | E4: Transactional | F4: BOFU | G4: Secondary | H4: 1900 | I4: 58 | J4: SERP Competition Analysis | K4: 9.4 | L4: Commercial Intent Analysis | M4: =IF(I4<=20,"Easy",IF(I4<=40,"Moderate",IF(I4<=70,"Competitive","Very Competitive"))) -> Competitive | N4: Gassler Dental; Tampa Bay Dental Team; Jackson Dental; Yelp / Healthgrades | O4: ='Priority Scoring'!B4 -> 5 | P4: ='Priority Scoring'!I4 -> 88 | Q4: ='Priority Scoring'!J4 -> High | R4: / | S4: Optimize | T4: Tampa-area volume estimate.
A5: dentists in tampa fl | B5: Location | C5: Local Dentistry - Tampa | D5: Local Core - Dentist in Tampa | E5: Transactional | F5: BOFU | G5: Secondary | H5: 1300 | I5: 57 | J5: SERP Competition Analysis | K5: 8.9 | L5: Commercial Intent Analysis | M5: =IF(I5<=20,"Easy",IF(I5<=40,"Moderate",IF(I5<=70,"Competitive","Very Competitive"))) -> Competitive | N5: Gassler Dental; Tampa Bay Dental Team; Jackson Dental; Yelp / Healthgrades | O5: ='Priority Scoring'!B5 -> 5 | P5: ='Priority Scoring'!I5 -> 88 | Q5: ='Priority Scoring'!J5 -> High | R5: / | S5: Optimize | T5: Tampa-area volume estimate.
A6: family dentist tampa | B6: Core Service | C6: Local Dentistry - Tampa | D6: Local Core - Dentist in Tampa | E6: Transactional | F6: BOFU | G6: Secondary | H6: 1000 | I6: 55 | J6: SERP Competition Analysis | K6: 9 | L6: Commercial Intent Analysis | M6: =IF(I6<=20,"Easy",IF(I6<=40,"Moderate",IF(I6<=70,"Competitive","Very Competitive"))) -> Competitive | N6: Gassler Dental; Tampa Bay Dental Team; Jackson Dental; Yelp / Healthgrades | O6: ='Priority Scoring'!B6 -> 5 | P6: ='Priority Scoring'!I6 -> 88 | Q6: ='Priority Scoring'!J6 -> High | R6: / | S6: Optimize | T6: Tampa-area volume estimate.
A7: general dentist tampa | B7: Core Service | C7: Local Dentistry - Tampa | D7: Local Core - Dentist in Tampa | E7: Transactional | F7: BOFU | G7: Secondary | H7: 590 | I7: 50 | J7: SERP Competition Analysis | K7: 8.4 | L7: Commercial Intent Analysis | M7: =IF(I7<=20,"Easy",IF(I7<=40,"Moderate",IF(I7<=70,"Competitive","Very Competitive"))) -> Competitive | N7: Gassler Dental; Tampa Bay Dental Team; Jackson Dental; Yelp / Healthgrades | O7: ='Priority Scoring'!B7 -> 5 | P7: ='Priority Scoring'!I7 -> 89 | Q7: ='Priority Scoring'!J7 -> High | R7: / | S7: Optimize | T7: Tampa-area volume estimate.
A8: dental office tampa | B8: Core Service | C8: Local Dentistry - Tampa | D8: Local Core - Dentist in Tampa | E8: Transactional | F8: BOFU | G8: Secondary | H8: 880 | I8: 52 | J8: SERP Competition Analysis | K8: 8 | L8: Commercial Intent Analysis | M8: =IF(I8<=20,"Easy",IF(I8<=40,"Moderate",IF(I8<=70,"Competitive","Very Competitive"))) -> Competitive | N8: Gassler Dental; Tampa Bay Dental Team; Jackson Dental; Yelp / Healthgrades | O8: ='Priority Scoring'!B8 -> 5 | P8: ='Priority Scoring'!I8 -> 85 | Q8: ='Priority Scoring'!J8 -> High | R8: / | S8: Optimize | T8: Tampa-area volume estimate.
A9: dentist near me | B9: Location | C9: Local Dentistry - Tampa | D9: Local Core - Dentist in Tampa | E9: Transactional | F9: BOFU | G9: Secondary | H9: 9900 | I9: 78 | J9: SERP Competition Analysis | K9: 8.5 | L9: Commercial Intent Analysis | M9: =IF(I9<=20,"Easy",IF(I9<=40,"Moderate",IF(I9<=70,"Competitive","Very Competitive"))) -> Very Competitive | N9: Gassler Dental; Tampa Bay Dental Team; Jackson Dental; Yelp / Healthgrades | O9: ='Priority Scoring'!B9 -> 5 | P9: ='Priority Scoring'!I9 -> 84 | Q9: ='Priority Scoring'!J9 -> High | R9: / | S9: Optimize | T9: Local-pack driven; ranking depends mainly on Google Business Profile proximity, reviews and categories - treat as GBP + homepage goal.
A10: best dentist in tampa | B10: Commercial | C10: Local Dentistry - Tampa | D10: Local Core - Dentist in Tampa | E10: Commercial | F10: MOFU | G10: Secondary | H10: 1600 | I10: 64 | J10: SERP Competition Analysis | K10: 10.5 | L10: Commercial Intent Analysis | M10: =IF(I10<=20,"Easy",IF(I10<=40,"Moderate",IF(I10<=70,"Competitive","Very Competitive"))) -> Competitive | N10: Gassler Dental; Tampa Bay Dental Team; Jackson Dental; Yelp / Healthgrades | O10: ='Priority Scoring'!B10 -> 5 | P10: ='Priority Scoring'!I10 -> 79 | Q10: ='Priority Scoring'!J10 -> High | R10: / | S10: Optimize | T10: Tampa-area volume estimate.
A11: top rated dentist tampa | B11: Commercial | C11: Local Dentistry - Tampa | D11: Local Core - Dentist in Tampa | E11: Commercial | F11: MOFU | G11: Secondary | H11: 480 | I11: 52 | J11: SERP Competition Analysis | K11: 9.1 | L11: Commercial Intent Analysis | M11: =IF(I11<=20,"Easy",IF(I11<=40,"Moderate",IF(I11<=70,"Competitive","Very Competitive"))) -> Competitive | N11: Gassler Dental; Tampa Bay Dental Team; Jackson Dental; Yelp / Healthgrades | O11: ='Priority Scoring'!B11 -> 5 | P11: ='Priority Scoring'!I11 -> 73 | Q11: ='Priority Scoring'!J11 -> Medium | R11: / | S11: Optimize | T11: Tampa-area volume estimate.
A12: dentist reviews tampa | B12: Commercial | C12: Local Dentistry - Tampa | D12: Local Core - Dentist in Tampa | E12: Commercial | F12: MOFU | G12: Secondary | H12: 210 | I12: 38 | J12: SERP Competition Analysis | K12: 6.8 | L12: Commercial Intent Analysis | M12: =IF(I12<=20,"Easy",IF(I12<=40,"Moderate",IF(I12<=70,"Competitive","Very Competitive"))) -> Moderate | N12: Gassler Dental; Tampa Bay Dental Team; Jackson Dental; Yelp / Healthgrades | O12: ='Priority Scoring'!B12 -> 5 | P12: ='Priority Scoring'!I12 -> 77 | Q12: ='Priority Scoring'!J12 -> High | R12: / | S12: Optimize | T12: Tampa-area volume estimate.
A13: dentist accepting new patients tampa | B13: Transactional | C13: Local Dentistry - Tampa | D13: Local Core - Dentist in Tampa | E13: Transactional | F13: BOFU | G13: Secondary | H13: 720 | I13: 46 | J13: SERP Competition Analysis | K13: 7.6 | L13: Commercial Intent Analysis | M13: =IF(I13<=20,"Easy",IF(I13<=40,"Moderate",IF(I13<=70,"Competitive","Very Competitive"))) -> Competitive | N13: Gassler Dental; Tampa Bay Dental Team; Jackson Dental; Yelp / Healthgrades | O13: ='Priority Scoring'!B13 -> 5 | P13: ='Priority Scoring'!I13 -> 89 | Q13: ='Priority Scoring'!J13 -> High | R13: / | S13: Optimize | T13: Tampa-area volume estimate.
... A224: routine dental care tampa | B224: Core Service | C224: Preventive Dentistry | D224: Preventive Dentistry Hub | E224: Transactional | F224: BOFU | G224: Secondary | H224: 60 | I224: 20 | J224: SERP Competition Analysis | K224: 5.5 | L224: Commercial Intent Analysis | M224: =IF(I224<=20,"Easy",IF(I224<=40,"Moderate",IF(I224<=70,"Competitive","Very Competitive"))) -> Easy | N224: General dentist sites | O224: ='Priority Scoring'!B224 -> 3 | P224: ='Priority Scoring'!I224 -> 76 | Q224: ='Priority Scoring'!J224 -> High | R224: /preventive-dentistry-tampa/ | S224: Create | T224: Tampa-area volume estimate.

Sheet Keyword Clusters
A1: Cluster Name | B1: Primary Keyword | C1: Secondary Keywords | D1: Questions | E1: Entities | F1: Intent | G1: Funnel Stage | H1: Recommended Page | I1: Page Type
A2: Local Core - Dentist in Tampa | B2: dentist in tampa | C2: dentist near me; tampa dentist; dentist tampa fl; best dentist in tampa; dentists in tampa fl; family dentist tampa; dental office tampa | D2: Is Dental Office of Tampa accepting new patients?; Where is the office located? | E2: Tampa, Hillsborough County, family dentist, general dentistry, new patients | F2: Transactional | G2: BOFU | H2: / | I2: Homepage
A3: Brand & Navigational | B3: dental office of tampa | C3: dr jackson dentist tampa; dentalofficeoftampa.com; dental office of tampa reviews; dental office of tampa phone number; dental office of tampa moran rd | D3: Add 'People Also Ask' FAQ block (service page) | E3: Dental Office of Tampa, Dr. Jackson, Moran Rd, Google Business Profile | F3: Navigational | G3: BOFU | H3: / | I3: Homepage
A4: North Tampa & ZIP 33618 | B4: dentist in north tampa | C4: north tampa dentist; dentist 33618; dentist 33624; dentist near dale mabry tampa; dentist 33625; dentist moran rd tampa | D4: Add 'People Also Ask' FAQ block (service page) | E4: 33618, 33624, 33625, Moran Rd, Dale Mabry Hwy, North Tampa | F4: Transactional | G4: BOFU | H4: /north-tampa-dentist/ | I4: Location Page
A5: Carrollwood Dentist | B5: dentist carrollwood tampa | C5: carrollwood dentist; dentist in carrollwood fl; dental office carrollwood | D5: Add 'People Also Ask' FAQ block (service page) | E5: Carrollwood, Dale Mabry Hwy, Hillsborough County | F5: Transactional | G5: BOFU | H5: /carrollwood-dentist/ | I5: Location Page
A6: Northdale Dentist | B6: dentist northdale tampa | C6: northdale dentist; dentist in northdale fl | D6: Add 'People Also Ask' FAQ block (service page) | E6: Northdale, Citrus Park Dr, Hillsborough County | F6: Transactional | G6: BOFU | H6: /northdale-dentist/ | I6: Location Page
A7: Lutz Dentist | B7: dentist lutz fl | C7: lutz dentist; dentist in lutz florida | D7: Add 'People Also Ask' FAQ block (service page) | E7: Lutz, Van Dyke Rd, Pasco/Hillsborough border | F7: Transactional | G7: BOFU | H7: /lutz-dentist/ | I7: Location Page
A8: Citrus Park Dentist | B8: dentist citrus park tampa | C8: citrus park dentist; dentist citrus park fl | D8: Add 'People Also Ask' FAQ block (service page) | E8: Citrus Park, Citrus Park Mall area, Sheldon Rd | F8: Transactional | G8: BOFU | H8: /citrus-park-dentist/ | I8: Location Page
A9: New Patient & Free Cleaning Offer | B9: new patient dentist tampa | C9: free dental cleaning near me; free teeth cleaning tampa; dentist new patient offer; free dental exam and x-rays tampa; new patient dental special tampa; book dentist appointment online tampa | D9: What is included in the free cleaning offer?; Who qualifies as a new patient? | E9: Free teeth cleaning, $140 exam and x-ray, free smile analysis | F9: Transactional | G9: BOFU | H9: /new-patient-special-tampa/ | I9: Offer / Landing Page
A10: First Visit Information | B10: first dental visit what to expect | C10: dentist after years of not going | D10: What to expect at first dentist appointment adult?; Haven't been to the dentist in years?; What happens at a dental exam and x-ray? | E10: First appointment, exam, x-rays, patient forms | F10: Informational | G10: TOFU | H10: /first-visit/ | I10: Info Page
A11: Insurance & Affordable Dentistry | B11: dentist that accepts insurance tampa | C11: affordable dentist tampa; low cost dentist tampa; cheap dentist in tampa; delta dental dentist tampa; dentist no insurance tampa; dentist payment plans tampa; cigna dentist tampa | D11: Which insurance plans are accepted?; Are payment options available? | E11: Delta Dental, Cigna, PPO, payment plans, self-pay | F11: Transactional | G11: BOFU | H11: /insurance-information/ | I11: Info Page
A12: Emergency Dentist | B12: emergency dentist tampa | C12: emergency dentist near me; toothache relief what to do; 24 hour emergency dentist tampa; emergency dental care tampa; same day dentist appointment tampa; tooth pain dentist tampa; broken tooth dentist tampa | D12: What counts as a dental emergency?; Can I be seen the same day? | E12: Toothache, broken tooth, chipped tooth, same-day appointment | F12: Transactional | G12: BOFU | H12: /emergency-dentist-tampa/ | I12: Service Page
... A33: Comfort-Focused Care | B33: gentle dentist tampa | C33: dentist for nervous patients near me; painless dentist tampa; dentist for anxious patients tampa; comfortable dental care tampa | D33: Add 'People Also Ask' FAQ block (service page) | E33: Painless dentistry, blankets, headphones, anxious patients | F33: Commercial | G33: MOFU | H33: /comfortable-dental-care-tampa/ | I33: Service Page
A34: Dental Anxiety - Education | B34: dental anxiety tips | D34: How to calm nerves before dentist?; Afraid of the dentist what to do? | E34: Dental anxiety, fear of dentist, relaxation | F34: Informational | G34: TOFU | H34: /blog/dental-anxiety-tips/ | I34: Blog Post
A35: Restorative Dentistry Hub | B35: restorative dentistry tampa | C35: restorative dentist tampa; dental restoration services tampa | D35: Add 'People Also Ask' FAQ block (service page) | E35: Fillings, crowns, bridges, dentures, implants | F35: Transactional | G35: BOFU | H35: /restorative-dentistry-tampa/ | I35: Hub Page
A36: Preventive Dentistry Hub | B36: preventive dentistry tampa | C36: preventive dental care tampa; routine dental care tampa | D36: Add 'People Also Ask' FAQ block (service page) | E36: Cleanings, exams, sealants, x-rays, fluoride | F36: Transactional | G36: BOFU | H36: /preventive-dentistry-tampa/ | I36: Hub Page

Sheet Competitor Analysis
A1: Competitor | B1: URL | C1: Ranking Topics | D1: Strong Pages | E1: Weakness | F1: Content Gap | G1: Opportunity
A2: Tampa Bay Dental Team | B2: https://tampabaydentalteam.com/ | C2: Family dentistry; cosmetic dentistry; periodontics; same-day emergency care; kids; new-patient special ($175); two offices (N. Dale Mabry 33618 and Van Dyke/Lutz). | D2: Cosmetic Dentistry, Family Dentistry, Periodontics, Dental Health section, Reviews, separate pages per office location. | E2: Dated-looking site (footer copyright 2018, slider layout); title tag leads with a doctor's name and the meta description is a person's name rather than services; Invisalign, dentures, bridges and crowns are grouped under 'Additional Dental Services' rather than own pages. | F2: No dedicated Invisalign, dentures, bridges, crowns or sealants pages seen in main navigation; no cost/pricing content; no neighborhood pages beyond the two office pages. | G2: Closest geographic rival (same 33618 ZIP). Win service-specific queries (crowns, bridges, dentures, Invisalign) with dedicated pages; match their emergency and new-patient positioning with /emergency-dentist-tampa/ and /new-patient-special-tampa/.
A3: Jackson Dental | B3: https://jacksondentaltampa.com/ | C3: Cosmetic dentistry (smile makeovers, bonding, veneers); dental implants (All-on-4/X, single tooth); Invisalign; insurance, payment options, Medicare Advantage; Downtown Tampa location (33602). | D3: Individual implant pages, Invisalign treatment page, Insurance and Payment Options pages, What to Expect page. | E3: Downtown location (101 E Kennedy Blvd) is distant from 33618; templated multi-practice platform content; meta description is only 'Home | Jackson Dental | Tampa FL'. | F3: Homepage does not feature fillings, crowns, dentures or sealants; no neighborhood content for North Tampa/Carrollwood/Northdale. | G3: Own the North Tampa catchment and restorative services. Copy their strength in insurance/payment transparency (insurance page, payment plans, cost guide).
A4: Gassler Dental | B4: https://gasslerdentaltampa.com/ | C4: Downtown Tampa / 33602 dentist; cosmetic; implants; emergency; Invisalign; full service list (ceramic and same-day crowns, bridges, dentures, fillings, extractions, night guards, whitening, veneers); privately-owned positioning. | D4: Broad service-page library, Dental Health library, blog, reviews, smile gallery, Emergency Treatment page. | E4: Downtown focus (507 E Jackson St); office open Monday-Thursday only per site hours; homepage copy is generic; no obvious cost/pricing content. | F4: North Tampa, Carrollwood, Northdale, Lutz and Citrus Park neighborhood coverage; pricing transparency; modern conversion offers (free cleaning, free consultation). | G4: Closest on-page service coverage - match service breadth (emergency, cleaning, crowns) and beat them locally with neighborhood pages, Friday hours, Thursday/Friday 7:30 AM opening and a free-cleaning offer page.
A5: Tampa Dentistry | B5: https://mytampadentistry.com/ | C5: Dentist in Tampa; cosmetic (smile makeovers, bonding, veneers); Invisalign; restorative (dentures, root canal, bridges); insurance and payment options; W. Busch Blvd location (33612). | D5: Dentures, Dental Bridges, Root Canal Treatment, Invisalign Treatment, Insurance and Payment Options pages. | E5: Same templated multi-practice platform as Jackson Dental; thin meta description ('Home | Tampa Dentistry | Tampa FL'); no blog link in homepage navigation. | F5: Crowns, fillings and sealants not featured on homepage; no emergency page seen in nav; no neighborhood-specific content. | G5: Direct competitor on dentures and bridges - out-rank with deeper service pages (types, process, FAQs) plus supporting cost/care guides; add root canal page to neutralise their advantage.
A6: GO Orthodontics Tampa | B6: https://goorthotampa.com/ | C6: Invisalign (adult, teen, first); braces types; clear braces; retainers; Invisalign and braces cost; virtual consultation; board-certified orthodontist. | D6: Invisalign page family, Treatment Cost page (/invisalign-braces-cost/), Before & After, Testimonials, Virtual Consultation, Blog. | E6: Orthodontic specialist only - no general or restorative dentistry; limited hours (Tue-Fri); Invisalign SERPs are specialist-dominated and hard for a general dentist to outrank on head terms. | F6: Not a general dentist - cannot compete for fillings, crowns, bridges, dentures or sealants; no emergency or general-care content. | G6: Not a like-for-like rival except Invisalign. Compete on long-tail (Invisalign + Tampa cost, free consultation, 'Invisalign dentist') and position as one-office convenience; build /invisalign-cost-tampa/ to match their cost page.

Sheet Keyword Mapping
A1: URL | B1: Page Name | C1: Primary Keyword | D1: Secondary Keywords | E1: Intent | F1: Funnel Stage | G1: Existing/New | H1: Action | I1: Cannibalization Risk
A2: / | B2: Homepage | C2: dentist in tampa | D2: dentist near me; tampa dentist; dentist tampa fl; best dentist in tampa; dentists in tampa fl; family dentist tampa | E2: Transactional | F2: BOFU | G2: Existing | H2: Optimize | I2: Medium - homepage competes with location pages for 'dentist in tampa' variants; keep neighborhood terms off the homepage.
A3: /north-tampa-dentist/ | B3: North Tampa / 33618 Dentist | C3: dentist in north tampa | D3: north tampa dentist; dentist 33618; dentist 33624; dentist near dale mabry tampa; dentist 33625; dentist moran rd tampa | E3: Transactional | F3: BOFU | G3: New | H3: Create | I3: Medium - overlaps homepage for generic Tampa terms; focus on ZIP and North Tampa modifiers only.
A4: /carrollwood-dentist/ | B4: Carrollwood Dentist | C4: dentist carrollwood tampa | D4: carrollwood dentist; dentist in carrollwood fl; dental office carrollwood | E4: Transactional | F4: BOFU | G4: New | H4: Create | I4: Low - unique neighborhood modifier; needs distinct local content.
A5: /northdale-dentist/ | B5: Northdale Dentist | C5: dentist northdale tampa | D5: northdale dentist; dentist in northdale fl | E5: Transactional | F5: BOFU | G5: New | H5: Create | I5: Low - unique neighborhood modifier.
A6: /lutz-dentist/ | B6: Lutz Dentist | C6: dentist lutz fl | D6: lutz dentist; dentist in lutz florida | E6: Transactional | F6: BOFU | G6: New | H6: Create | I6: Low - unique neighborhood modifier.
A7: /citrus-park-dentist/ | B7: Citrus Park Dentist | C7: dentist citrus park tampa | D7: citrus park dentist; dentist citrus park fl | E7: Transactional | F7: BOFU | G7: New | H7: Create | I7: Low - unique neighborhood modifier.
A8: /new-patient-special-tampa/ | B8: New Patient Special - Free Cleaning | C8: new patient dentist tampa | D8: free dental cleaning near me; free teeth cleaning tampa; dentist new patient offer; free dental exam and x-rays tampa; new patient dental special tampa; book dentist appointment online tampa | E8: Transactional | F8: BOFU | G8: New | H8: Create | I8: Medium - overlaps /first-visit/ and homepage offer banner; keep offer terms here, 'what to expect' on /first-visit/.
A9: /first-visit/ | B9: First Visit | C9: first dental visit what to expect | D9: what happens at a dental exam and x-ray; haven't been to the dentist in years; what to expect at first dentist appointment adult; dentist after years of not going | E9: Informational | F9: TOFU | G9: Existing | H9: Optimize | I9: Low - informational intent; link to offer page.
A10: /insurance-information/ | B10: Insurance Information | C10: dentist that accepts insurance tampa | D10: affordable dentist tampa; low cost dentist tampa; cheap dentist in tampa; delta dental dentist tampa; dentist no insurance tampa; dentist payment plans tampa | E10: Transactional | F10: BOFU | G10: Existing | H10: Optimize | I10: Low - distinct payment/insurance intent.
A11: /emergency-dentist-tampa/ | B11: Emergency Dentist Tampa | C11: emergency dentist tampa | D11: emergency dentist near me; toothache relief what to do; 24 hour emergency dentist tampa; emergency dental care tampa; same day dentist appointment tampa; tooth pain dentist tampa | E11: Transactional | F11: BOFU | G11: New | H11: Create | I11: Low - unique intent.
A12: /teeth-cleaning-tampa/ | B12: Teeth Cleaning & Dental Checkups | C12: teeth cleaning tampa | D12: dental cleaning near me; how often should you get teeth cleaned; what happens during a dental cleaning; dental cleaning tampa; dental checkup tampa; deep cleaning teeth tampa | E12: Transactional | F12: BOFU | G12: New | H12: Create | I12: Medium - overlaps free-cleaning offer page; differentiate cleaning service vs offer.
... A40: /blog/ | B40: Blog Hub | C40: dental care tips tampa | D40: Hub for all education posts; link to every service silo | E40: Informational | F40: TOFU | G40: New | H40: Create | I40: Low

Sheet Topical Authority Map
A1: Main Topic | B1: Sub Topics | C1: Supporting Content | D1: Entities | E1: Commercial Connection
A2: Restorative Dentistry (Fillings, Crowns, Bridges) | B2: Fillings; composite vs amalgam; crowns; porcelain vs zirconia; bridges; bridge vs implant; tooth decay stages | C2: Fillings guide; Dental crown cost guide; Dental bridge guide; restorative hub | D2: Tooth decay, enamel, composite resin, porcelain, zirconia, abutment teeth, pontic | E2: /dentist-filling-tampa/, /dental-cap-crown-tampa/, /dental-bridges-tampa/ - highest-ticket service pages
A3: Tooth Replacement (Dentures & Implants) | B3: Full vs partial dentures; dentures vs implants vs bridges; denture care; implant-supported dentures | C3: Denture cost & types guide; Denture care & adjustment; dentures vs implants comparison | D3: Edentulism, gums, prosthodontics, abutment, osseointegration, denture adhesive | E3: /dentures/, /dental-implant-tampa/ - tooth-replacement consultations
A4: Clear Aligners (Invisalign) | B4: Invisalign cost; vs braces; treatment time; attachments; retainers; teens; before/after | C4: Invisalign cost page; Invisalign vs braces; Invisalign FAQs | D4: Invisalign, clear aligners, malocclusion, overbite, retainers, digital scan | E4: /clear-mouth-braces-tampa/ and /invisalign-cost-tampa/ - free smile analysis leads
A5: Preventive Care (Cleanings & Sealants) | B5: Teeth cleaning; checkups; exam and x-ray; sealants for kids and adults; fluoride | C5: Teeth cleaning page; sealants guide; first-visit page; preventive hub | D5: Plaque, tartar, molars, pits and fissures, fluoride, digital x-rays | E5: /teeth-cleaning-tampa/, /dental-tooth-sealant-tampa/, /new-patient-special-tampa/ - new-patient acquisition
A6: Emergency & Pain | B6: Toothache; broken or chipped tooth; lost filling or crown; same-day appointments | C6: Emergency dentist page; toothache FAQ; lost crown/filling FAQ | D6: Abscess, fracture, pulp, pain relief, urgent care | E6: /emergency-dentist-tampa/ - high-CPC, high-intent calls (confirm capacity)
A7: Dental Costs, Insurance & Financing | B7: Cost without insurance; payment plans; accepted insurance; exam and x-ray pricing | C7: Dental costs hub; insurance page upgrades; service-page pricing blocks | D7: PPO, Delta Dental, Cigna, self-pay, payment plans, HSA/FSA | E7: /dental-costs-tampa/, /insurance-information/ - removes pricing friction before booking
A8: Patient Comfort & Anxiety | B8: Gentle dentistry; anxious patients; what to expect; comfort amenities (blankets, headphones) | C8: Comfortable dental care page; dental anxiety tips; first-visit page | D8: Dental anxiety, comfort, communication, relaxed visit | E8: /comfortable-dental-care-tampa/ - differentiates the practice (homepage comfort messaging)
A9: Local Tampa Authority | B9: North Tampa 33618; Carrollwood; Northdale; Lutz; Citrus Park; Dale Mabry; Moran Rd | C9: Location pages with unique local content; GBP posts; local citations; reviews page | D9: Tampa, Hillsborough County, 33618, Carrollwood, Northdale, Lutz, Citrus Park | E9: Home + location pages - drives local-pack visibility and calls

Sheet SEO Silo Architecture
A1: Silo | B1: Parent Page | C1: Child Pages | D1: Purpose | E1: Internal Linking Flow
A2: 1. Local & Conversion Hub | B2: / (Homepage) | C2: /north-tampa-dentist/; /carrollwood-dentist/; /northdale-dentist/; /lutz-dentist/; /citrus-park-dentist/; /new-patient-special-tampa/; /first-visit/; /insurance-information/; /emergency-dentist-tampa/; /dental-costs-tampa/; /comfortable-dental-care-tampa/ | D2: Capture local-intent searches, drive calls and bookings, feed Google Business Profile. | E2: Home -> every child (hub links); children -> Home and -> relevant service pages; all pages -> /appointment-form/ CTA.
A3: 2. Restorative Dentistry | B3: /restorative-dentistry-tampa/ (New hub) | C3: /dentist-filling-tampa/; /dental-cap-crown-tampa/; /dental-bridges-tampa/; /dentures/; /dental-implant-tampa/; /root-canal-tampa/; /tooth-extraction-tampa/; blogs: fillings guide, crown cost guide, bridge guide, denture cost & types, denture care | D3: Build topical authority for the highest-revenue treatments. | E3: Hub -> service pages; service <-> education blog (blog links to service with transactional anchor); sibling cross-links (crown<->bridge<->denture<->implant).
A4: 3. Clear Braces / Invisalign | B4: /clear-mouth-braces-tampa/ | C4: /invisalign-cost-tampa/; /blog/invisalign-vs-braces/; /blog/invisalign-faqs/ | D4: Compete for Invisalign long-tail and cost research. | E4: Parent -> cost page and blogs; blogs -> parent and cost page; cost page -> /appointment-form/ (free smile analysis).
A5: 4. Preventive & Family Care | B5: /preventive-dentistry-tampa/ (New hub) | C5: /teeth-cleaning-tampa/; /dental-tooth-sealant-tampa/; /blog/what-are-dental-sealants/; /first-visit/ | D5: Capture recurring-visit and family searches; support new-patient funnel. | E5: Hub -> children; cleaning <-> new-patient offer; sealant blog -> sealant service page.
A6: 5. Patient Education Blog | B6: /blog/ (rename of /1058-2/) | C6: All /blog/ posts including /blog/dental-anxiety-tips/ | D6: Feed TOFU traffic and topical coverage; capture People-Also-Ask queries. | E6: Blog hub -> posts; every post -> parent service page + CTA; service pages -> 2-3 relevant posts.

Sheet Internal Linking Blueprint
A1: Source Page | B1: Target Page | C1: Anchor Concept | D1: Purpose
A2: / | B2: /dental-tooth-sealant-tampa/ | C2: dental sealants in Tampa | D2: Pass homepage authority to money page
A3: / | B3: /clear-mouth-braces-tampa/ | C3: Invisalign / clear braces in Tampa | D3: Pass homepage authority to money page
A4: / | B4: /dentist-filling-tampa/ | C4: fillings and restorations in Tampa | D4: Pass homepage authority to money page
A5: / | B5: /dentures/ | C5: dentures in Tampa | D5: Pass homepage authority to money page
A6: / | B6: /dental-bridges-tampa/ | C6: dental bridges in Tampa | D6: Pass homepage authority to money page
A7: / | B7: /dental-cap-crown-tampa/ | C7: dental crowns in Tampa | D7: Pass homepage authority to money page
A8: / | B8: /emergency-dentist-tampa/ | C8: emergency dentist in Tampa | D8: Surface high-intent page
A9: / | B9: /new-patient-special-tampa/ | C9: free teeth cleaning for new patients | D9: Promote offer
A10: / | B10: /insurance-information/ | C10: insurance and payment options | D10: Reduce booking friction
A11: / | B11: /north-tampa-dentist/ | C11: dentist in North Tampa | D11: Local relevance
A12: /dental-tooth-sealant-tampa/ | B12: /appointment-form/ | C12: book a consultation | D12: Conversion path from every service page
... A59: /blog/ | B59: /clear-mouth-braces-tampa/ | C59: Invisalign | D59: Blog hub to silo parent

Sheet Content Roadmap
A1: Timeline | B1: Priority | C1: Content Type | D1: Title | E1: Target Keyword | F1: Search Intent | G1: Funnel Stage | H1: URL | I1: Business Goal
A2: Month 1 - Wk 1-2 | B2: Critical | C2: On-page optimization | D2: Rewrite homepage title, meta description and H1 around 'Dentist in Tampa, FL' | E2: dentist in tampa | F2: Transactional | G2: BOFU | H2: / | I2: Improve ranking + local leads
A3: Month 1 - Wk 1-2 | B3: Critical | C3: Technical SEO | D3: Resolve URL variants (nav vs body links) for dentures, bridges and crowns; canonicals and 301s | E3: n/a (technical) | F3: n/a | G3: n/a | H3: /dentures/; /dental-bridges-tampa/; /dental-cap-crown-tampa/ | I3: Remove cannibalization risk
A4: Month 1 - Wk 1-3 | B4: High | C4: Service page optimization | D4: Optimize Invisalign / Clear Braces page: H1, FAQs, free smile analysis CTA, schema | E4: invisalign tampa | F4: Transactional | G4: BOFU | H4: /clear-mouth-braces-tampa/ | I4: Improve service page rankings
A5: Month 1 - Wk 1-3 | B5: High | C5: Service page optimization | D5: Optimize Dental Crowns page (porcelain, same-day if offered, FAQs) | E5: dental crowns tampa | F5: Transactional | G5: BOFU | H5: /dental-cap-crown-tampa/ | I5: Improve service page rankings
A6: Month 1 - Wk 2-3 | B6: High | C6: Service page optimization | D6: Optimize Dentures page (full, partial, same-day if offered) | E6: dentures tampa | F6: Transactional | G6: BOFU | H6: /dentures/ | I6: Improve service page rankings
A7: Month 1 - Wk 2-3 | B7: High | C7: Service page optimization | D7: Optimize Dental Bridges page (types, process, bridge vs implant) | E7: dental bridges tampa | F7: Transactional | G7: BOFU | H7: /dental-bridges-tampa/ | I7: Improve service page rankings
A8: Month 1 - Wk 3-4 | B8: High | C8: Service page optimization | D8: Optimize Fillings & Restorations page (tooth-colored fillings, cavity, restoration) | E8: dental fillings tampa | F8: Transactional | G8: BOFU | H8: /dentist-filling-tampa/ | I8: Improve service page rankings
A9: Month 1 - Wk 3-4 | B9: High | C9: Service page optimization | D9: Optimize Dental Sealants page (kids and adults, cost block) | E9: dental sealants near me | F9: Transactional | G9: BOFU | H9: /dental-tooth-sealant-tampa/ | I9: Quick win - low competition
A10: Month 1 - Wk 3-4 | B10: Critical | C10: Landing page | D10: Create New Patient Special: Free Teeth Cleaning with $140 exam and x-ray | E10: new patient dentist tampa | F10: Transactional | G10: BOFU | H10: /new-patient-special-tampa/ | I10: Generate more local leads
A11: Month 1 - Wk 4 | B11: High | C11: Page optimization | D11: Upgrade Insurance Information page (accepted plans, payment options, FAQs) | E11: dentist that accepts insurance tampa | F11: Transactional | G11: BOFU | H11: /insurance-information/ | I11: Reduce friction, local leads
A12: Month 2 - Wk 5-6 | B12: High | C12: Location page | D12: North Tampa Dentist - ZIP 33618 (map, directions, Moran Rd, drive times, local reviews) | E12: dentist in north tampa | F12: Transactional | G12: BOFU | H12: /north-tampa-dentist/ | I12: Local pack + local leads
... A35: Month 6 - Wk 24 | B35: Medium | C35: Service page | D35: Root Canal Treatment in Tampa / Tooth Extraction in Tampa (phase-2 services) | E35: root canal tampa | F35: Transactional | G35: BOFU | H35: /root-canal-tampa/ | I35: Expand service coverage

Sheet Quick Wins
A1: Keyword | B1: Intent | C1: Funnel Stage | D1: Opportunity | E1: Reason | F1: Recommended Action
A2: free teeth cleaning tampa | B2: Transactional | C2: BOFU | D2: Own live offer, no dedicated page | E2: Offer already on the homepage; KD only 20 and high-intent for new patients. | F2: Create /new-patient-special-tampa/ with offer schema; promote through GBP posts.
A3: dentist 33618 | B3: Transactional | C3: BOFU | D3: Exact-ZIP match | E3: Practice sits in 33618; KD 22 and a ZIP the closest rival also shares. | F3: Create /north-tampa-dentist/ with NAP, map, directions and ZIP in title/H1.
A4: clear braces tampa | B4: Transactional | C4: BOFU | D4: Matches existing nav label | E4: Page already named 'Clear Braces - Invisalign'; moderate KD 40 and CPC above $12. | F4: Rewrite title/H1/meta around 'clear braces' + Invisalign; add FAQ + free smile analysis CTA.
A5: invisalign free consultation tampa | B5: Transactional | C5: BOFU | D5: Offer already marketed | E5: Homepage promotes a free smile analysis; KD 30 with high commercial value. | F5: Add consultation block and FAQ to the Invisalign page; track form conversions.
A6: dental sealants near me | B6: Transactional | C6: BOFU | D6: Low competition service | E6: Audited competitors give sealants little visibility; KD 28. | F6: Optimize sealant page, add kids/adult sections, internal links from cleaning page.
A7: dental fillings tampa | B7: Transactional | C7: BOFU | D7: Existing page, low KD | E7: Existing page; KD 34 with straightforward intent. | F7: Expand copy: tooth-colored fillings, process, FAQs; fix title and meta.
A8: tooth colored fillings tampa | B8: Transactional | C8: BOFU | D8: Long-tail variation | E8: KD 24; same page can capture it with a dedicated section. | F8: Add H2 section and FAQ 'Are tooth-colored fillings available?'.
A9: painless dentist tampa | B9: Commercial | C9: MOFU | D9: Comfort angle already on homepage | E9: Homepage already has 'Painless dental treatment' heading; KD 36. | F9: Create comfort page and avoid sedation claims unless offered.
A10: dentist northdale tampa | B10: Transactional | C10: BOFU | D10: Neighborhood low KD | E10: KD 30; weakly contested neighborhood term. | F10: Create unique Northdale page with landmarks, drive times and services.
A11: dentist citrus park tampa | B11: Transactional | C11: BOFU | D11: Neighborhood low KD | E11: KD 34; few practices target the term explicitly. | F11: Create unique Citrus Park page; link from Carrollwood and North Tampa pages.
A12: dentist carrollwood tampa | B12: Transactional | C12: BOFU | D12: Neighborhood term | E12: 480 est. searches/month at KD 40 near the practice. | F12: Create Carrollwood page with local proof (reviews, photos, directions).
... A16: same day dentures tampa | B16: Transactional | C16: BOFU | D16: High CPC, moderate KD | E16: KD 34 and CPC near $10 - only if the service is offered. | F16: Confirm service, then add section to the Dentures page.

Sheet Priority Scoring
A1: Keyword | B1: Business Value | C1: Search Demand | D1: Ranking Opportunity | E1: Intent Strength | F1: Conversion Potential | G1: Topical Importance | H1: Weighted Score (1-5) | I1: Priority Score (0-100) | J1: Priority Level | L1: Factor | M1: Weight | N1: How it is scored
A2: ='Keyword Master Database'!A2 -> dentist in tampa | B2: 5 | C2: =IF('Keyword Master Database'!H2>=1000,5,IF('Keyword Master Database'!H2>=500,4,IF('Keyword Master Database'!H2>=200,3,IF('Keyword Master Database'!H2>=80,2,1)))) -> 5 | D2: =IF('Keyword Master Database'!I2<=20,5,IF('Keyword Master Database'!I2<=35,4,IF('Keyword Master Database'!I2<=50,3,IF('Keyword Master Database'!I2<=65,2,1)))) -> 2 | E2: =IF('Keyword Master Database'!E2="Transactional",5,IF('Keyword Master Database'!E2="Commercial",4,IF('Keyword Master Database'!E2="Navigational",3,2))) -> 5 | F2: 5 | G2: 5 | H2: =B2*$M$2+C2*$M$3+D2*$M$4+E2*$M$5+F2*$M$6+G2*$M$7 -> 4.4 | I2: =ROUND(H2*20,0) -> 88 | J2: =IF(I2>=$M$11,"Critical",IF(I2>=$M$12,"High",IF(I2>=$M$13,"Medium",IF(I2>=$M$14,"Low","Optional")))) -> High | L2: Business Value | M2: 0.25 | N2: Input 1-5: revenue value of the service / cluster
A3: ='Keyword Master Database'!A3 -> tampa dentist | B3: 5 | C3: =IF('Keyword Master Database'!H3>=1000,5,IF('Keyword Master Database'!H3>=500,4,IF('Keyword Master Database'!H3>=200,3,IF('Keyword Master Database'!H3>=80,2,1)))) -> 5 | D3: =IF('Keyword Master Database'!I3<=20,5,IF('Keyword Master Database'!I3<=35,4,IF('Keyword Master Database'!I3<=50,3,IF('Keyword Master Database'!I3<=65,2,1)))) -> 2 | E3: =IF('Keyword Master Database'!E3="Transactional",5,IF('Keyword Master Database'!E3="Commercial",4,IF('Keyword Master Database'!E3="Navigational",3,2))) -> 5 | F3: 5 | G3: 5 | H3: =B3*$M$2+C3*$M$3+D3*$M$4+E3*$M$5+F3*$M$6+G3*$M$7 -> 4.4 | I3: =ROUND(H3*20,0) -> 88 | J3: =IF(I3>=$M$11,"Critical",IF(I3>=$M$12,"High",IF(I3>=$M$13,"Medium",IF(I3>=$M$14,"Low","Optional")))) -> High | L3: Search Demand | M3: 0.15 | N3: Formula from est. volume: >=1000=5, >=500=4, >=200=3, >=80=2, else 1
A4: ='Keyword Master Database'!A4 -> dentist tampa fl | B4: 5 | C4: =IF('Keyword Master Database'!H4>=1000,5,IF('Keyword Master Database'!H4>=500,4,IF('Keyword Master Database'!H4>=200,3,IF('Keyword Master Database'!H4>=80,2,1)))) -> 5 | D4: =IF('Keyword Master Database'!I4<=20,5,IF('Keyword Master Database'!I4<=35,4,IF('Keyword Master Database'!I4<=50,3,IF('Keyword Master Database'!I4<=65,2,1)))) -> 2 | E4: =IF('Keyword Master Database'!E4="Transactional",5,IF('Keyword Master Database'!E4="Commercial",4,IF('Keyword Master Database'!E4="Navigational",3,2))) -> 5 | F4: 5 | G4: 5 | H4: =B4*$M$2+C4*$M$3+D4*$M$4+E4*$M$5+F4*$M$6+G4*$M$7 -> 4.4 | I4: =ROUND(H4*20,0) -> 88 | J4: =IF(I4>=$M$11,"Critical",IF(I4>=$M$12,"High",IF(I4>=$M$13,"Medium",IF(I4>=$M$14,"Low","Optional")))) -> High | L4: Ranking Opportunity | M4: 0.2 | N4: Formula from est. KD: <=20=5, <=35=4, <=50=3, <=65=2, else 1
A5: ='Keyword Master Database'!A5 -> dentists in tampa fl | B5: 5 | C5: =IF('Keyword Master Database'!H5>=1000,5,IF('Keyword Master Database'!H5>=500,4,IF('Keyword Master Database'!H5>=200,3,IF('Keyword Master Database'!H5>=80,2,1)))) -> 5 | D5: =IF('Keyword Master Database'!I5<=20,5,IF('Keyword Master Database'!I5<=35,4,IF('Keyword Master Database'!I5<=50,3,IF('Keyword Master Database'!I5<=65,2,1)))) -> 2 | E5: =IF('Keyword Master Database'!E5="Transactional",5,IF('Keyword Master Database'!E5="Commercial",4,IF('Keyword Master Database'!E5="Navigational",3,2))) -> 5 | F5: 5 | G5: 5 | H5: =B5*$M$2+C5*$M$3+D5*$M$4+E5*$M$5+F5*$M$6+G5*$M$7 -> 4.4 | I5: =ROUND(H5*20,0) -> 88 | J5: =IF(I5>=$M$11,"Critical",IF(I5>=$M$12,"High",IF(I5>=$M$13,"Medium",IF(I5>=$M$14,"Low","Optional")))) -> High | L5: Intent Strength | M5: 0.15 | N5: Formula: Transactional 5, Commercial 4, Navigational 3, Informational 2
A6: ='Keyword Master Database'!A6 -> family dentist tampa | B6: 5 | C6: =IF('Keyword Master Database'!H6>=1000,5,IF('Keyword Master Database'!H6>=500,4,IF('Keyword Master Database'!H6>=200,3,IF('Keyword Master Database'!H6>=80,2,1)))) -> 5 | D6: =IF('Keyword Master Database'!I6<=20,5,IF('Keyword Master Database'!I6<=35,4,IF('Keyword Master Database'!I6<=50,3,IF('Keyword Master Database'!I6<=65,2,1)))) -> 2 | E6: =IF('Keyword Master Database'!E6="Transactional",5,IF('Keyword Master Database'!E6="Commercial",4,IF('Keyword Master Database'!E6="Navigational",3,2))) -> 5 | F6: 5 | G6: 5 | H6: =B6*$M$2+C6*$M$3+D6*$M$4+E6*$M$5+F6*$M$6+G6*$M$7 -> 4.4 | I6: =ROUND(H6*20,0) -> 88 | J6: =IF(I6>=$M$11,"Critical",IF(I6>=$M$12,"High",IF(I6>=$M$13,"Medium",IF(I6>=$M$14,"Low","Optional")))) -> High | L6: Conversion Potential | M6: 0.15 | N6: Input 1-5: BOFU=5, MOFU=3, TOFU=1, own-brand navigational=4
A7: ='Keyword Master Database'!A7 -> general dentist tampa | B7: 5 | C7: =IF('Keyword Master Database'!H7>=1000,5,IF('Keyword Master Database'!H7>=500,4,IF('Keyword Master Database'!H7>=200,3,IF('Keyword Master Database'!H7>=80,2,1)))) -> 4 | D7: =IF('Keyword Master Database'!I7<=20,5,IF('Keyword Master Database'!I7<=35,4,IF('Keyword Master Database'!I7<=50,3,IF('Keyword Master Database'!I7<=65,2,1)))) -> 3 | E7: =IF('Keyword Master Database'!E7="Transactional",5,IF('Keyword Master Database'!E7="Commercial",4,IF('Keyword Master Database'!E7="Navigational",3,2))) -> 5 | F7: 5 | G7: 5 | H7: =B7*$M$2+C7*$M$3+D7*$M$4+E7*$M$5+F7*$M$6+G7*$M$7 -> 4.45 | I7: =ROUND(H7*20,0) -> 89 | J7: =IF(I7>=$M$11,"Critical",IF(I7>=$M$12,"High",IF(I7>=$M$13,"Medium",IF(I7>=$M$14,"Low","Optional")))) -> High | L7: Topical Importance | M7: 0.1 | N7: Input 1-5: importance to topical authority for the silo
A8: ='Keyword Master Database'!A8 -> dental office tampa | B8: 5 | C8: =IF('Keyword Master Database'!H8>=1000,5,IF('Keyword Master Database'!H8>=500,4,IF('Keyword Master Database'!H8>=200,3,IF('Keyword Master Database'!H8>=80,2,1)))) -> 4 | D8: =IF('Keyword Master Database'!I8<=20,5,IF('Keyword Master Database'!I8<=35,4,IF('Keyword Master Database'!I8<=50,3,IF('Keyword Master Database'!I8<=65,2,1)))) -> 2 | E8: =IF('Keyword Master Database'!E8="Transactional",5,IF('Keyword Master Database'!E8="Commercial",4,IF('Keyword Master Database'!E8="Navigational",3,2))) -> 5 | F8: 5 | G8: 5 | H8: =B8*$M$2+C8*$M$3+D8*$M$4+E8*$M$5+F8*$M$6+G8*$M$7 -> 4.25 | I8: =ROUND(H8*20,0) -> 85 | J8: =IF(I8>=$M$11,"Critical",IF(I8>=$M$12,"High",IF(I8>=$M$13,"Medium",IF(I8>=$M$14,"Low","Optional")))) -> High | L8: Total weight | M8: =SUM(M2:M7) -> 1
A9: ='Keyword Master Database'!A9 -> dentist near me | B9: 5 | C9: =IF('Keyword Master Database'!H9>=1000,5,IF('Keyword Master Database'!H9>=500,4,IF('Keyword Master Database'!H9>=200,3,IF('Keyword Master Database'!H9>=80,2,1)))) -> 5 | D9: =IF('Keyword Master Database'!I9<=20,5,IF('Keyword Master Database'!I9<=35,4,IF('Keyword Master Database'!I9<=50,3,IF('Keyword Master Database'!I9<=65,2,1)))) -> 1 | E9: =IF('Keyword Master Database'!E9="Transactional",5,IF('Keyword Master Database'!E9="Commercial",4,IF('Keyword Master Database'!E9="Navigational",3,2))) -> 5 | F9: 5 | G9: 5 | H9: =B9*$M$2+C9*$M$3+D9*$M$4+E9*$M$5+F9*$M$6+G9*$M$7 -> 4.2 | I9: =ROUND(H9*20,0) -> 84 | J9: =IF(I9>=$M$11,"Critical",IF(I9>=$M$12,"High",IF(I9>=$M$13,"Medium",IF(I9>=$M$14,"Low","Optional")))) -> High
A10: ='Keyword Master Database'!A10 -> best dentist in tampa | B10: 5 | C10: =IF('Keyword Master Database'!H10>=1000,5,IF('Keyword Master Database'!H10>=500,4,IF('Keyword Master Database'!H10>=200,3,IF('Keyword Master Database'!H10>=80,2,1)))) -> 5 | D10: =IF('Keyword Master Database'!I10<=20,5,IF('Keyword Master Database'!I10<=35,4,IF('Keyword Master Database'!I10<=50,3,IF('Keyword Master Database'!I10<=65,2,1)))) -> 2 | E10: =IF('Keyword Master Database'!E10="Transactional",5,IF('Keyword Master Database'!E10="Commercial",4,IF('Keyword Master Database'!E10="Navigational",3,2))) -> 4 | F10: 3 | G10: 5 | H10: =B10*$M$2+C10*$M$3+D10*$M$4+E10*$M$5+F10*$M$6+G10*$M$7 -> 3.95 | I10: =ROUND(H10*20,0) -> 79 | J10: =IF(I10>=$M$11,"Critical",IF(I10>=$M$12,"High",IF(I10>=$M$13,"Medium",IF(I10>=$M$14,"Low","Optional")))) -> High | L10: Priority Level | M10: Min score
A11: ='Keyword Master Database'!A11 -> top rated dentist tampa | B11: 5 | C11: =IF('Keyword Master Database'!H11>=1000,5,IF('Keyword Master Database'!H11>=500,4,IF('Keyword Master Database'!H11>=200,3,IF('Keyword Master Database'!H11>=80,2,1)))) -> 3 | D11: =IF('Keyword Master Database'!I11<=20,5,IF('Keyword Master Database'!I11<=35,4,IF('Keyword Master Database'!I11<=50,3,IF('Keyword Master Database'!I11<=65,2,1)))) -> 2 | E11: =IF('Keyword Master Database'!E11="Transactional",5,IF('Keyword Master Database'!E11="Commercial",4,IF('Keyword Master Database'!E11="Navigational",3,2))) -> 4 | F11: 3 | G11: 5 | H11: =B11*$M$2+C11*$M$3+D11*$M$4+E11*$M$5+F11*$M$6+G11*$M$7 -> 3.65 | I11: =ROUND(H11*20,0) -> 73 | J11: =IF(I11>=$M$11,"Critical",IF(I11>=$M$12,"High",IF(I11>=$M$13,"Medium",IF(I11>=$M$14,"Low","Optional")))) -> Medium | L11: Critical | M11: 90
A12: ='Keyword Master Database'!A12 -> dentist reviews tampa | B12: 5 | C12: =IF('Keyword Master Database'!H12>=1000,5,IF('Keyword Master Database'!H12>=500,4,IF('Keyword Master Database'!H12>=200,3,IF('Keyword Master Database'!H12>=80,2,1)))) -> 3 | D12: =IF('Keyword Master Database'!I12<=20,5,IF('Keyword Master Database'!I12<=35,4,IF('Keyword Master Database'!I12<=50,3,IF('Keyword Master Database'!I12<=65,2,1)))) -> 3 | E12: =IF('Keyword Master Database'!E12="Transactional",5,IF('Keyword Master Database'!E12="Commercial",4,IF('Keyword Master Database'!E12="Navigational",3,2))) -> 4 | F12: 3 | G12: 5 | H12: =B12*$M$2+C12*$M$3+D12*$M$4+E12*$M$5+F12*$M$6+G12*$M$7 -> 3.85 | I12: =ROUND(H12*20,0) -> 77 | J12: =IF(I12>=$M$11,"Critical",IF(I12>=$M$12,"High",IF(I12>=$M$13,"Medium",IF(I12>=$M$14,"Low","Optional")))) -> High | L12: High | M12: 75
A13: ='Keyword Master Database'!A13 -> dentist accepting new patients tampa | B13: 5 | C13: =IF('Keyword Master Database'!H13>=1000,5,IF('Keyword Master Database'!H13>=500,4,IF('Keyword Master Database'!H13>=200,3,IF('Keyword Master Database'!H13>=80,2,1)))) -> 4 | D13: =IF('Keyword Master Database'!I13<=20,5,IF('Keyword Master Database'!I13<=35,4,IF('Keyword Master Database'!I13<=50,3,IF('Keyword Master Database'!I13<=65,2,1)))) -> 3 | E13: =IF('Keyword Master Database'!E13="Transactional",5,IF('Keyword Master Database'!E13="Commercial",4,IF('Keyword Master Database'!E13="Navigational",3,2))) -> 5 | F13: 5 | G13: 5 | H13: =B13*$M$2+C13*$M$3+D13*$M$4+E13*$M$5+F13*$M$6+G13*$M$7 -> 4.45 | I13: =ROUND(H13*20,0) -> 89 | J13: =IF(I13>=$M$11,"Critical",IF(I13>=$M$12,"High",IF(I13>=$M$13,"Medium",IF(I13>=$M$14,"Low","Optional")))) -> High | L13: Medium | M13: 60
A14: ='Keyword Master Database'!A14 -> comprehensive dentistry tampa | B14: 5 | C14: =IF('Keyword Master Database'!H14>=1000,5,IF('Keyword Master Database'!H14>=500,4,IF('Keyword Master Database'!H14>=200,3,IF('Keyword Master Database'!H14>=80,2,1)))) -> 2 | D14: =IF('Keyword Master Database'!I14<=20,5,IF('Keyword Master Database'!I14<=35,4,IF('Keyword Master Database'!I14<=50,3,IF('Keyword Master Database'!I14<=65,2,1)))) -> 4 | E14: =IF('Keyword Master Database'!E14="Transactional",5,IF('Keyword Master Database'!E14="Commercial",4,IF('Keyword Master Database'!E14="Navigational",3,2))) -> 4 | F14: 3 | G14: 5 | H14: =B14*$M$2+C14*$M$3+D14*$M$4+E14*$M$5+F14*$M$6+G14*$M$7 -> 3.9 | I14: =ROUND(H14*20,0) -> 78 | J14: =IF(I14>=$M$11,"Critical",IF(I14>=$M$12,"High",IF(I14>=$M$13,"Medium",IF(I14>=$M$14,"Low","Optional")))) -> High | L14: Low | M14: 40
A15: ='Keyword Master Database'!A15 -> dentist open now tampa | B15: 5 | C15: =IF('Keyword Master Database'!H15>=1000,5,IF('Keyword Master Database'!H15>=500,4,IF('Keyword Master Database'!H15>=200,3,IF('Keyword Master Database'!H15>=80,2,1)))) -> 4 | D15: =IF('Keyword Master Database'!I15<=20,5,IF('Keyword Master Database'!I15<=35,4,IF('Keyword Master Database'!I15<=50,3,IF('Keyword Master Database'!I15<=65,2,1)))) -> 3 | E15: =IF('Keyword Master Database'!E15="Transactional",5,IF('Keyword Master Database'!E15="Commercial",4,IF('Keyword Master Database'!E15="Navigational",3,2))) -> 5 | F15: 5 | G15: 5 | H15: =B15*$M$2+C15*$M$3+D15*$M$4+E15*$M$5+F15*$M$6+G15*$M$7 -> 4.45 | I15: =ROUND(H15*20,0) -> 89 | J15: =IF(I15>=$M$11,"Critical",IF(I15>=$M$12,"High",IF(I15>=$M$13,"Medium",IF(I15>=$M$14,"Low","Optional")))) -> High | L15: Optional | M15: 0
A16: ='Keyword Master Database'!A16 -> dental office of tampa | B16: 3 | C16: =IF('Keyword Master Database'!H16>=1000,5,IF('Keyword Master Database'!H16>=500,4,IF('Keyword Master Database'!H16>=200,3,IF('Keyword Master Database'!H16>=80,2,1)))) -> 3 | D16: =IF('Keyword Master Database'!I16<=20,5,IF('Keyword Master Database'!I16<=35,4,IF('Keyword Master Database'!I16<=50,3,IF('Keyword Master Database'!I16<=65,2,1)))) -> 5 | E16: =IF('Keyword Master Database'!E16="Transactional",5,IF('Keyword Master Database'!E16="Commercial",4,IF('Keyword Master Database'!E16="Navigational",3,2))) -> 3 | F16: 4 | G16: 3 | H16: =B16*$M$2+C16*$M$3+D16*$M$4+E16*$M$5+F16*$M$6+G16*$M$7 -> 3.55 | I16: =ROUND(H16*20,0) -> 71 | J16: =IF(I16>=$M$11,"Critical",IF(I16>=$M$12,"High",IF(I16>=$M$13,"Medium",IF(I16>=$M$14,"Low","Optional")))) -> Medium
A17: ='Keyword Master Database'!A17 -> dentalofficeoftampa.com | B17: 3 | C17: =IF('Keyword Master Database'!H17>=1000,5,IF('Keyword Master Database'!H17>=500,4,IF('Keyword Master Database'!H17>=200,3,IF('Keyword Master Database'!H17>=80,2,1)))) -> 1 | D17: =IF('Keyword Master Database'!I17<=20,5,IF('Keyword Master Database'!I17<=35,4,IF('Keyword Master Database'!I17<=50,3,IF('Keyword Master Database'!I17<=65,2,1)))) -> 5 | E17: =IF('Keyword Master Database'!E17="Transactional",5,IF('Keyword Master Database'!E17="Commercial",4,IF('Keyword Master Database'!E17="Navigational",3,2))) -> 3 | F17: 4 | G17: 3 | H17: =B17*$M$2+C17*$M$3+D17*$M$4+E17*$M$5+F17*$M$6+G17*$M$7 -> 3.25 | I17: =ROUND(H17*20,0) -> 65 | J17: =IF(I17>=$M$11,"Critical",IF(I17>=$M$12,"High",IF(I17>=$M$13,"Medium",IF(I17>=$M$14,"Low","Optional")))) -> Medium
A18: ='Keyword Master Database'!A18 -> dental office of tampa moran rd | B18: 3 | C18: =IF('Keyword Master Database'!H18>=1000,5,IF('Keyword Master Database'!H18>=500,4,IF('Keyword Master Database'!H18>=200,3,IF('Keyword Master Database'!H18>=80,2,1)))) -> 1 | D18: =IF('Keyword Master Database'!I18<=20,5,IF('Keyword Master Database'!I18<=35,4,IF('Keyword Master Database'!I18<=50,3,IF('Keyword Master Database'!I18<=65,2,1)))) -> 5 | E18: =IF('Keyword Master Database'!E18="Transactional",5,IF('Keyword Master Database'!E18="Commercial",4,IF('Keyword Master Database'!E18="Navigational",3,2))) -> 3 | F18: 4 | G18: 3 | H18: =B18*$M$2+C18*$M$3+D18*$M$4+E18*$M$5+F18*$M$6+G18*$M$7 -> 3.25 | I18: =ROUND(H18*20,0) -> 65 | J18: =IF(I18>=$M$11,"Critical",IF(I18>=$M$12,"High",IF(I18>=$M$13,"Medium",IF(I18>=$M$14,"Low","Optional")))) -> Medium
