Workbook

Sheet Cover
B2: SEO KEYWORD RESEARCH & STRATEGY WORKBOOK
B3: Dental Faith Aesthetic & Family Dentistry | Nashville, Tennessee, USA
B4: Prepared By: Md. Abdul Alim | Local SEO & AI Search Optimization Consultant
B10: RESEARCH SUMMARY DASHBOARD
B11: TOTAL KEYWORDS RESEARCHED | D11: KEYWORD CLUSTERS | F11: EST. MONTHLY SEARCH VOLUME | H11: LOCAL / NATIONAL KEYWORDS | J11: AVERAGE KEYWORD DIFFICULTY
B12: =COUNTA('Keyword Master Database'!$A$2:$A$287) -> 286 | D12: =COUNTA('Keyword Clusters'!$A$2:$A$76) -> 75 | F12: =SUM('Keyword Master Database'!$H$2:$H$287) -> 149200 | H12: =COUNTIF('Keyword Master Database'!$B$2:$B$287,"Local*")&" / "&COUNTIF('Keyword Master Database'!$B$2:$B$287,"National*") -> 198 / 88 | J12: =ROUND(AVERAGE('Keyword Master Database'!$J$2:$J$287),1) -> 31.5
B14: CRITICAL + HIGH PRIORITY | D14: PAGES MAPPED | F14: NEW PAGES RECOMMENDED | H14: INTERNAL LINKS PLANNED | J14: CONTENT OPPORTUNITIES
B15: =COUNTIF('Keyword Master Database'!$W$2:$W$287,"Critical")+COUNTIF('Keyword Master Database'!$W$2:$W$287,"High") -> 166 | D15: =COUNTA('Keyword Mapping'!$A$2:$A$79) -> 78 | F15: =COUNTIF('Keyword Mapping'!$G$2:$G$79,"New") -> 51 | H15: =COUNTA('Internal Linking Blueprint'!$A$2:$A$190) -> 189 | J15: =COUNTA('Content Roadmap'!$D$2:$D$51) -> 50
B18: VISUAL DASHBOARD
B36: DISTRIBUTION DATA
B37: Search Intent | C37: Keywords | D37: Share | E37: Priority Level | F37: Keywords | G37: Share | H37: Funnel Stage | I37: Keywords | J37: Share | K37: Remarks
B38: Informational | C38: =COUNTIF('Keyword Master Database'!$E$2:$E$287,B38) -> 64 | D38: =C38/SUM(C$38:C$41) -> 0.22377622 | E38: Critical | F38: =COUNTIF('Keyword Master Database'!$W$2:$W$287,E38) -> 15 | G38: =F38/SUM(F$38:F$41) -> 0.052447552 | H38: TOFU | I38: =COUNTIF('Keyword Master Database'!$F$2:$F$287,H38) -> 64 | J38: =I38/SUM(I$38:I$40) -> 0.22377622
B39: Navigational | C39: =COUNTIF('Keyword Master Database'!$E$2:$E$287,B39) -> 8 | D39: =C39/SUM(C$38:C$41) -> 0.027972028 | E39: High | F39: =COUNTIF('Keyword Master Database'!$W$2:$W$287,E39) -> 151 | G39: =F39/SUM(F$38:F$41) -> 0.52797203 | H39: MOFU | I39: =COUNTIF('Keyword Master Database'!$F$2:$F$287,H39) -> 37 | J39: =I39/SUM(I$38:I$40) -> 0.12937063
B40: Commercial | C40: =COUNTIF('Keyword Master Database'!$E$2:$E$287,B40) -> 37 | D40: =C40/SUM(C$38:C$41) -> 0.12937063 | E40: Medium | F40: =COUNTIF('Keyword Master Database'!$W$2:$W$287,E40) -> 65 | G40: =F40/SUM(F$38:F$41) -> 0.22727273 | H40: BOFU | I40: =COUNTIF('Keyword Master Database'!$F$2:$F$287,H40) -> 185 | J40: =I40/SUM(I$38:I$40) -> 0.64685315
B41: Transactional | C41: =COUNTIF('Keyword Master Database'!$E$2:$E$287,B41) -> 177 | D41: =C41/SUM(C$38:C$41) -> 0.61888112 | E41: Low | F41: =COUNTIF('Keyword Master Database'!$W$2:$W$287,E41) -> 55 | G41: =F41/SUM(F$38:F$41) -> 0.19230769
B43: WORKBOOK CONTENTS
B44: Sheet Name | E44: Purpose
B45: Business Analysis | E45: Business information, SEO goals and website analysis
B46: Keyword Master Database | E46: Complete keyword research database with metrics, scoring and strategy
B47: Keyword Clusters | E47: Keyword grouping and semantic organization
B48: Competitor Analysis | E48: Competitor keyword insights and opportunities
B49: Keyword Mapping | E49: Keyword to page targeting strategy
B50: Topical Authority Map | E50: Content authority planning
B51: SEO Silo Architecture | E51: Website structure planning
B52: Internal Linking Blueprint | E52: Internal authority flow strategy
B53: Content Roadmap | E53: Future content creation strategy (26 weeks)
B54: Quick Wins | E54: Immediate SEO opportunities
B55: Scoring Model | E55: Priority-score weights, scoring rules and data assumptions

Sheet Business Analysis
A1: BUSINESS ANALYSIS
A3: BUSINESS PROFILE
A4: Business Name | B4: Dental Faith Aesthetic & Family Dentistry
A5: Website | B5: https://dentalfaith.com/
A6: Industry | B6: Dental Clinic (general, cosmetic and family dentistry)
A7: Country | B7: United States
A8: Location | B8: 390 Harding Pl #101, Nashville, TN 37211, United States
A9: Services | B9: Preventive Dentistry; Dental Cleanings; Periodontal Therapy; Oral Cancer Screening; Cosmetic Dentistry; Dental Crowns; Dental Bridges; Dental Veneers; Teeth Whitening; Orthodontics; Restorative Dentistry; Dental Fillings; Partials & Dentures; Root Canals; Dental Implants; Emergency Dentistry (Broken Tooth, Cracked Tooth, Gum Bleeding, Toothache); Dental Extraction; Technology (Dental X-rays, Digital Dental Impressions, Intraoral Pictures)
A10: Products | B10: Not applicable (service-based practice)
A11: Primary SEO Focus | B11: Local SEO + AI SEO
A13: BUSINESS & SEO GOALS
A14: Goal 1 | B14: Generate more local leads (calls, bookings, direction requests)
A15: Goal 2 | B15: Increase organic traffic
A16: Goal 3 | B16: Improve rankings for service-page, Commercial and Transactional intent keywords
A17: Goal 4 | B17: Build topical authority across every service silo
A19: WEBSITE & CURRENT-STATE ANALYSIS
A20: Current intent profile | B20: Informational 69.0% (about 2K keywords, 158 traffic) | Navigational 9.1% (263, 174) | Commercial 19.2% (554, 76) | Transactional 2.6% (75, 14). Visibility skews heavily informational and branded; commercial/transactional demand is barely captured. This is the core opportunity.
A21: Website analysis method | B21: The live homepage could not be rendered by the crawler (compressed response), so on-page review was limited. Findings use the service list provided, public listings and SERP research. Run a Screaming Frog crawl to confirm titles, H1s, schema and URLs before implementation.
A22: Existing SEO strengths | B22: Broad service menu that maps cleanly to a hub-and-spoke architecture; combined aesthetic + family positioning; technology differentiators (digital x-rays, impressions, intraoral pictures); public mention as a family dentist in Nashville on a dental community site.
A23: Missing keyword opportunities | B23: Neighborhood/ZIP terms (37211, Nolensville Pike, Antioch); same-day/walk-in and open-Saturday intent; insurance/financing terms; kids/family; Spanish-language local queries; comparison queries (implants vs dentures, veneers vs crowns).
A24: Content gaps | B24: Problem-based emergency content (toothache at night, cracked tooth symptoms), cost-guidance pages, FAQ sections per service, technology explainers, comparison articles, review/proof pages.
A25: Commercial opportunities | B25: Implants, emergency, root canal, veneers/cosmetic and Invisalign/braces carry the highest CPCs ($8-$15+), signalling the strongest lead value. Prioritize those service pages and their local variants.
A26: Internal linking opportunities | B26: Connect emergency pages to root canal/crown/extraction treatment pages; link technology pages to the services they support; every educational article should link to its service page and the booking CTA.
A27: Page optimization opportunities | B27: Add LocalBusiness/Dentist + FAQ schema, click-to-call CTAs, NAP consistency, service-specific H1/title patterns, before/after galleries, clinician E-E-A-T (credentials, reviews) and AI-search-ready Q&A blocks.
A29: TARGET INTENT MIX vs CURRENT
A30: Intent | B30: Current share (screenshot) | Planned share in this workbook
A31: Informational | B31: ="Current "&TEXT(0.69,"0.0%")&" -> Planned "&TEXT(COUNTIF('Keyword Master Database'!$E$2:$E$287,A31)/COUNTA('Keyword Master Database'!$A$2:$A$287),"0.0%")&" ("&COUNTIF('Keyword Master Database'!$E$2:$E$287,A31)&" keywords)" -> Current 69.0% -> Planned 22.4% (64 keywords)
A32: Navigational | B32: ="Current "&TEXT(0.091,"0.0%")&" -> Planned "&TEXT(COUNTIF('Keyword Master Database'!$E$2:$E$287,A32)/COUNTA('Keyword Master Database'!$A$2:$A$287),"0.0%")&" ("&COUNTIF('Keyword Master Database'!$E$2:$E$287,A32)&" keywords)" -> Current 9.1% -> Planned 2.8% (8 keywords)
A33: Commercial | B33: ="Current "&TEXT(0.192,"0.0%")&" -> Planned "&TEXT(COUNTIF('Keyword Master Database'!$E$2:$E$287,A33)/COUNTA('Keyword Master Database'!$A$2:$A$287),"0.0%")&" ("&COUNTIF('Keyword Master Database'!$E$2:$E$287,A33)&" keywords)" -> Current 19.2% -> Planned 12.9% (37 keywords)
A34: Transactional | B34: ="Current "&TEXT(0.026,"0.0%")&" -> Planned "&TEXT(COUNTIF('Keyword Master Database'!$E$2:$E$287,A34)/COUNTA('Keyword Master Database'!$A$2:$A$287),"0.0%")&" ("&COUNTIF('Keyword Master Database'!$E$2:$E$287,A34)&" keywords)" -> Current 2.6% -> Planned 61.9% (177 keywords)

Sheet Keyword Master Database
A1: Keyword | B1: Keyword Type | C1: Parent Topic | D1: Cluster | E1: Search Intent | F1: Funnel Stage | G1: Primary/Secondary | H1: Search Volume | I1: Volume Source | J1: KD | K1: KD Source | L1: Estimated CPC | M1: CPC Source | N1: SERP Competition | O1: Ranking Competitors | P1: Business Value Score (1-5) | Q1: Search Demand Score (1-5) | R1: Ranking Opportunity Score (1-5) | S1: Intent Strength Score (1-5) | T1: Conversion Potential Score (1-5) | U1: Topical Importance Score (1-5) | V1: SEO Priority Score | W1: Priority Level | X1: Target URL | Y1: Recommended Action | Z1: Notes
A2: dental implants nashville | B2: Local - Service | C2: Dental Implants | D2: Dental Implants | E2: Transactional | F2: BOFU | G2: Primary | H2: 480 | I2: SEO Market Estimate | J2: 40 | K2: SERP Competition Analysis | L2: 14.5 | M2: Commercial Intent Analysis | N2: =IF(J2<=20,"Easy",IF(J2<=40,"Moderate",IF(J2<=70,"Competitive","Very Competitive"))) -> Moderate | O2: Local-pack practices; Yelp; Healthgrades; Nashville dental groups | P2: 5 | Q2: =IF(H2>=1000,5,IF(H2>=400,4,IF(H2>=150,3,IF(H2>=50,2,1)))) -> 4 | R2: =IF(J2<=25,5,IF(J2<=40,4,IF(J2<=55,3,IF(J2<=70,2,1)))) -> 4 | S2: 5 | T2: 5 | U2: 5 | V2: =ROUND((P2*'Scoring Model'!$C$4+Q2*'Scoring Model'!$C$5+R2*'Scoring Model'!$C$6+S2*'Scoring Model'!$C$7+T2*'Scoring Model'!$C$8+U2*'Scoring Model'!$C$9)/5*100,0) -> 93 | W2: =IF(V2>=90,"Critical",IF(V2>=75,"High",IF(V2>=60,"Medium",IF(V2>=40,"Low","Optional")))) -> Critical | X2: /services/dental-implants/ | Y2: Optimize | Z2: Money keyword: local pack + organic; add click-to-call, booking CTA, schema.
A3: dental implants nashville tn | B3: Local - Service | C3: Dental Implants | D3: Dental Implants | E3: Transactional | F3: BOFU | G3: Secondary | H3: 220 | I3: SEO Market Estimate | J3: 38 | K3: SERP Competition Analysis | L3: 14.5 | M3: Commercial Intent Analysis | N3: =IF(J3<=20,"Easy",IF(J3<=40,"Moderate",IF(J3<=70,"Competitive","Very Competitive"))) -> Moderate | O3: Local-pack practices; Yelp; Healthgrades; Nashville dental groups | P3: 5 | Q3: =IF(H3>=1000,5,IF(H3>=400,4,IF(H3>=150,3,IF(H3>=50,2,1)))) -> 3 | R3: =IF(J3<=25,5,IF(J3<=40,4,IF(J3<=55,3,IF(J3<=70,2,1)))) -> 4 | S3: 5 | T3: 5 | U3: 5 | V3: =ROUND((P3*'Scoring Model'!$C$4+Q3*'Scoring Model'!$C$5+R3*'Scoring Model'!$C$6+S3*'Scoring Model'!$C$7+T3*'Scoring Model'!$C$8+U3*'Scoring Model'!$C$9)/5*100,0) -> 90 | W3: =IF(V3>=90,"Critical",IF(V3>=75,"High",IF(V3>=60,"Medium",IF(V3>=40,"Low","Optional")))) -> Critical | X3: /services/dental-implants/ | Y3: Optimize | Z3: Money keyword: local pack + organic; add click-to-call, booking CTA, schema.
A4: dental implants near me | B4: Local - Near Me | C4: Dental Implants | D4: Dental Implants | E4: Transactional | F4: BOFU | G4: Secondary | H4: 720 | I4: SEO Market Estimate | J4: 46 | K4: SERP Competition Analysis | L4: 15.23 | M4: Commercial Intent Analysis | N4: =IF(J4<=20,"Easy",IF(J4<=40,"Moderate",IF(J4<=70,"Competitive","Very Competitive"))) -> Competitive | O4: Local-pack practices; Yelp; Healthgrades; Nashville dental groups | P4: 5 | Q4: =IF(H4>=1000,5,IF(H4>=400,4,IF(H4>=150,3,IF(H4>=50,2,1)))) -> 4 | R4: =IF(J4<=25,5,IF(J4<=40,4,IF(J4<=55,3,IF(J4<=70,2,1)))) -> 3 | S4: 5 | T4: 5 | U4: 5 | V4: =ROUND((P4*'Scoring Model'!$C$4+Q4*'Scoring Model'!$C$5+R4*'Scoring Model'!$C$6+S4*'Scoring Model'!$C$7+T4*'Scoring Model'!$C$8+U4*'Scoring Model'!$C$9)/5*100,0) -> 89 | W4: =IF(V4>=90,"Critical",IF(V4>=75,"High",IF(V4>=60,"Medium",IF(V4>=40,"Low","Optional")))) -> High | X4: /services/dental-implants/ | Y4: Optimize | Z4: Money keyword: local pack + organic; add click-to-call, booking CTA, schema.
A5: best dental implants in nashville | B5: Local - Commercial | C5: Dental Implants | D5: Dental Implants | E5: Commercial | F5: MOFU | G5: Secondary | H5: 140 | I5: SEO Market Estimate | J5: 37 | K5: SERP Competition Analysis | L5: 12.32 | M5: Commercial Intent Analysis | N5: =IF(J5<=20,"Easy",IF(J5<=40,"Moderate",IF(J5<=70,"Competitive","Very Competitive"))) -> Moderate | O5: Local-pack practices; Yelp; Healthgrades; Nashville dental groups | P5: 4 | Q5: =IF(H5>=1000,5,IF(H5>=400,4,IF(H5>=150,3,IF(H5>=50,2,1)))) -> 2 | R5: =IF(J5<=25,5,IF(J5<=40,4,IF(J5<=55,3,IF(J5<=70,2,1)))) -> 4 | S5: 4 | T5: 3 | U5: 5 | V5: =ROUND((P5*'Scoring Model'!$C$4+Q5*'Scoring Model'!$C$5+R5*'Scoring Model'!$C$6+S5*'Scoring Model'!$C$7+T5*'Scoring Model'!$C$8+U5*'Scoring Model'!$C$9)/5*100,0) -> 73 | W5: =IF(V5>=90,"Critical",IF(V5>=75,"High",IF(V5>=60,"Medium",IF(V5>=40,"Low","Optional")))) -> Medium | X5: /services/dental-implants/ | Y5: Optimize | Z5: Consideration stage: add proof (reviews, before/after, FAQs, pricing guidance).
A6: dental implants cost nashville | B6: Local - Cost | C6: Dental Implants | D6: Dental Implants | E6: Transactional | F6: BOFU | G6: Secondary | H6: 170 | I6: SEO Market Estimate | J6: 36 | K6: SERP Competition Analysis | L6: 11.6 | M6: Commercial Intent Analysis | N6: =IF(J6<=20,"Easy",IF(J6<=40,"Moderate",IF(J6<=70,"Competitive","Very Competitive"))) -> Moderate | O6: Local-pack practices; Yelp; Healthgrades; Nashville dental groups | P6: 5 | Q6: =IF(H6>=1000,5,IF(H6>=400,4,IF(H6>=150,3,IF(H6>=50,2,1)))) -> 3 | R6: =IF(J6<=25,5,IF(J6<=40,4,IF(J6<=55,3,IF(J6<=70,2,1)))) -> 4 | S6: 5 | T6: 4 | U6: 5 | V6: =ROUND((P6*'Scoring Model'!$C$4+Q6*'Scoring Model'!$C$5+R6*'Scoring Model'!$C$6+S6*'Scoring Model'!$C$7+T6*'Scoring Model'!$C$8+U6*'Scoring Model'!$C$9)/5*100,0) -> 87 | W6: =IF(V6>=90,"Critical",IF(V6>=75,"High",IF(V6>=60,"Medium",IF(V6>=40,"Low","Optional")))) -> High | X6: /services/dental-implants/ | Y6: Optimize | Z6: Money keyword: local pack + organic; add click-to-call, booking CTA, schema.
A7: what are dental implants | B7: National - Informational | C7: Dental Implants | D7: Dental Implants - Education | E7: Informational | F7: TOFU | G7: Primary | H7: 1050 | I7: SEO Market Estimate | J7: 26 | K7: SERP Competition Analysis | L7: 3.62 | M7: Commercial Intent Analysis | N7: =IF(J7<=20,"Easy",IF(J7<=40,"Moderate",IF(J7<=70,"Competitive","Very Competitive"))) -> Moderate | O7: Cleveland Clinic; Healthline; Mayo Clinic; Colgate | P7: 3 | Q7: =IF(H7>=1000,5,IF(H7>=400,4,IF(H7>=150,3,IF(H7>=50,2,1)))) -> 5 | R7: =IF(J7<=25,5,IF(J7<=40,4,IF(J7<=55,3,IF(J7<=70,2,1)))) -> 4 | S7: 1 | T7: 1 | U7: 5 | V7: =ROUND((P7*'Scoring Model'!$C$4+Q7*'Scoring Model'!$C$5+R7*'Scoring Model'!$C$6+S7*'Scoring Model'!$C$7+T7*'Scoring Model'!$C$8+U7*'Scoring Model'!$C$9)/5*100,0) -> 62 | W7: =IF(V7>=90,"Critical",IF(V7>=75,"High",IF(V7>=60,"Medium",IF(V7>=40,"Low","Optional")))) -> Medium | X7: /blog/dental-implants-guide/ | Y7: Create | Z7: Topical authority + TOFU traffic; link to the related service page with a booking CTA.
A8: same day dental implants nashville | B8: Local - Service | C8: Dental Implants | D8: Dental Implants | E8: Transactional | F8: BOFU | G8: Secondary | H8: 90 | I8: SEO Market Estimate | J8: 36 | K8: SERP Competition Analysis | L8: 15.2 | M8: Commercial Intent Analysis | N8: =IF(J8<=20,"Easy",IF(J8<=40,"Moderate",IF(J8<=70,"Competitive","Very Competitive"))) -> Moderate | O8: Local-pack practices; Yelp; Healthgrades; Nashville dental groups | P8: 5 | Q8: =IF(H8>=1000,5,IF(H8>=400,4,IF(H8>=150,3,IF(H8>=50,2,1)))) -> 2 | R8: =IF(J8<=25,5,IF(J8<=40,4,IF(J8<=55,3,IF(J8<=70,2,1)))) -> 4 | S8: 5 | T8: 5 | U8: 5 | V8: =ROUND((P8*'Scoring Model'!$C$4+Q8*'Scoring Model'!$C$5+R8*'Scoring Model'!$C$6+S8*'Scoring Model'!$C$7+T8*'Scoring Model'!$C$8+U8*'Scoring Model'!$C$9)/5*100,0) -> 87 | W8: =IF(V8>=90,"Critical",IF(V8>=75,"High",IF(V8>=60,"Medium",IF(V8>=40,"Low","Optional")))) -> High | X8: /services/dental-implants/ | Y8: Optimize | Z8: Verify service/insurance/hours before publishing. Money keyword: local pack + organic; add click-to-call, booking CTA, schema.
A9: dental implant dentist near me | B9: Local - Near Me | C9: Dental Implants | D9: Dental Implants | E9: Transactional | F9: BOFU | G9: Secondary | H9: 320 | I9: SEO Market Estimate | J9: 44 | K9: SERP Competition Analysis | L9: 15.8 | M9: Commercial Intent Analysis | N9: =IF(J9<=20,"Easy",IF(J9<=40,"Moderate",IF(J9<=70,"Competitive","Very Competitive"))) -> Competitive | O9: Local-pack practices; Yelp; Healthgrades; Nashville dental groups | P9: 5 | Q9: =IF(H9>=1000,5,IF(H9>=400,4,IF(H9>=150,3,IF(H9>=50,2,1)))) -> 3 | R9: =IF(J9<=25,5,IF(J9<=40,4,IF(J9<=55,3,IF(J9<=70,2,1)))) -> 3 | S9: 5 | T9: 5 | U9: 5 | V9: =ROUND((P9*'Scoring Model'!$C$4+Q9*'Scoring Model'!$C$5+R9*'Scoring Model'!$C$6+S9*'Scoring Model'!$C$7+T9*'Scoring Model'!$C$8+U9*'Scoring Model'!$C$9)/5*100,0) -> 86 | W9: =IF(V9>=90,"Critical",IF(V9>=75,"High",IF(V9>=60,"Medium",IF(V9>=40,"Low","Optional")))) -> High | X9: /services/dental-implants/ | Y9: Optimize | Z9: Money keyword: local pack + organic; add click-to-call, booking CTA, schema.
A10: how long do dental implants last | B10: National - Informational | C10: Dental Implants | D10: Dental Implants - Education | E10: Informational | F10: TOFU | G10: Secondary | H10: 1900 | I10: SEO Market Estimate | J10: 45 | K10: SERP Competition Analysis | L10: 2.1 | M10: Commercial Intent Analysis | N10: =IF(J10<=20,"Easy",IF(J10<=40,"Moderate",IF(J10<=70,"Competitive","Very Competitive"))) -> Competitive | O10: Cleveland Clinic; Healthline; Mayo Clinic; Colgate | P10: 3 | Q10: =IF(H10>=1000,5,IF(H10>=400,4,IF(H10>=150,3,IF(H10>=50,2,1)))) -> 5 | R10: =IF(J10<=25,5,IF(J10<=40,4,IF(J10<=55,3,IF(J10<=70,2,1)))) -> 3 | S10: 1 | T10: 1 | U10: 5 | V10: =ROUND((P10*'Scoring Model'!$C$4+Q10*'Scoring Model'!$C$5+R10*'Scoring Model'!$C$6+S10*'Scoring Model'!$C$7+T10*'Scoring Model'!$C$8+U10*'Scoring Model'!$C$9)/5*100,0) -> 58 | W10: =IF(V10>=90,"Critical",IF(V10>=75,"High",IF(V10>=60,"Medium",IF(V10>=40,"Low","Optional")))) -> Low | X10: /blog/dental-implants-guide/ | Y10: Create | Z10: Topical authority + TOFU traffic; link to the related service page with a booking CTA.
A11: dental implant procedure step by step | B11: National - Informational | C11: Dental Implants | D11: Dental Implants - Education | E11: Informational | F11: TOFU | G11: Secondary | H11: 880 | I11: SEO Market Estimate | J11: 38 | K11: SERP Competition Analysis | L11: 1.9 | M11: Commercial Intent Analysis | N11: =IF(J11<=20,"Easy",IF(J11<=40,"Moderate",IF(J11<=70,"Competitive","Very Competitive"))) -> Moderate | O11: Cleveland Clinic; Healthline; Mayo Clinic; Colgate | P11: 3 | Q11: =IF(H11>=1000,5,IF(H11>=400,4,IF(H11>=150,3,IF(H11>=50,2,1)))) -> 4 | R11: =IF(J11<=25,5,IF(J11<=40,4,IF(J11<=55,3,IF(J11<=70,2,1)))) -> 4 | S11: 1 | T11: 1 | U11: 5 | V11: =ROUND((P11*'Scoring Model'!$C$4+Q11*'Scoring Model'!$C$5+R11*'Scoring Model'!$C$6+S11*'Scoring Model'!$C$7+T11*'Scoring Model'!$C$8+U11*'Scoring Model'!$C$9)/5*100,0) -> 59 | W11: =IF(V11>=90,"Critical",IF(V11>=75,"High",IF(V11>=60,"Medium",IF(V11>=40,"Low","Optional")))) -> Low | X11: /blog/dental-implants-guide/ | Y11: Create | Z11: Topical authority + TOFU traffic; link to the related service page with a booking CTA.
A12: are dental implants worth it | B12: National - Informational | C12: Dental Implants | D12: Dental Implants - Education | E12: Informational | F12: TOFU | G12: Secondary | H12: 590 | I12: SEO Market Estimate | J12: 34 | K12: SERP Competition Analysis | L12: 2.4 | M12: Commercial Intent Analysis | N12: =IF(J12<=20,"Easy",IF(J12<=40,"Moderate",IF(J12<=70,"Competitive","Very Competitive"))) -> Moderate | O12: Cleveland Clinic; Healthline; Mayo Clinic; Colgate | P12: 3 | Q12: =IF(H12>=1000,5,IF(H12>=400,4,IF(H12>=150,3,IF(H12>=50,2,1)))) -> 4 | R12: =IF(J12<=25,5,IF(J12<=40,4,IF(J12<=55,3,IF(J12<=70,2,1)))) -> 4 | S12: 1 | T12: 1 | U12: 5 | V12: =ROUND((P12*'Scoring Model'!$C$4+Q12*'Scoring Model'!$C$5+R12*'Scoring Model'!$C$6+S12*'Scoring Model'!$C$7+T12*'Scoring Model'!$C$8+U12*'Scoring Model'!$C$9)/5*100,0) -> 59 | W12: =IF(V12>=90,"Critical",IF(V12>=75,"High",IF(V12>=60,"Medium",IF(V12>=40,"Low","Optional")))) -> Low | X12: /blog/dental-implants-guide/ | Y12: Create | Z12: Topical authority + TOFU traffic; link to the related service page with a booking CTA.
A13: dental implant recovery time | B13: National - Informational | C13: Dental Implants | D13: Dental Implants - Education | E13: Informational | F13: TOFU | G13: Secondary | H13: 1000 | I13: SEO Market Estimate | J13: 36 | K13: SERP Competition Analysis | L13: 1.8 | M13: Commercial Intent Analysis | N13: =IF(J13<=20,"Easy",IF(J13<=40,"Moderate",IF(J13<=70,"Competitive","Very Competitive"))) -> Moderate | O13: Cleveland Clinic; Healthline; Mayo Clinic; Colgate | P13: 3 | Q13: =IF(H13>=1000,5,IF(H13>=400,4,IF(H13>=150,3,IF(H13>=50,2,1)))) -> 5 | R13: =IF(J13<=25,5,IF(J13<=40,4,IF(J13<=55,3,IF(J13<=70,2,1)))) -> 4 | S13: 1 | T13: 1 | U13: 5 | V13: =ROUND((P13*'Scoring Model'!$C$4+Q13*'Scoring Model'!$C$5+R13*'Scoring Model'!$C$6+S13*'Scoring Model'!$C$7+T13*'Scoring Model'!$C$8+U13*'Scoring Model'!$C$9)/5*100,0) -> 62 | W13: =IF(V13>=90,"Critical",IF(V13>=75,"High",IF(V13>=60,"Medium",IF(V13>=40,"Low","Optional")))) -> Medium | X13: /blog/dental-implants-guide/ | Y13: Create | Z13: Topical authority + TOFU traffic; link to the related service page with a booking CTA.
... A287: bad breath that won't go away | B287: National - Problem-Based | C287: Oral Health Education | D287: Oral Health Education Hub | E287: Informational | F287: TOFU | G287: Secondary | H287: 1900 | I287: SEO Market Estimate | J287: 38 | K287: SERP Competition Analysis | L287: 1.2 | M287: Commercial Intent Analysis | N287: =IF(J287<=20,"Easy",IF(J287<=40,"Moderate",IF(J287<=70,"Competitive","Very Competitive"))) -> Moderate | O287: Cleveland Clinic; Healthline; Mayo Clinic; Colgate | P287: 1 | Q287: =IF(H287>=1000,5,IF(H287>=400,4,IF(H287>=150,3,IF(H287>=50,2,1)))) -> 5 | R287: =IF(J287<=25,5,IF(J287<=40,4,IF(J287<=55,3,IF(J287<=70,2,1)))) -> 4 | S287: 2 | T287: 2 | U287: 3 | V287: =ROUND((P287*'Scoring Model'!$C$4+Q287*'Scoring Model'!$C$5+R287*'Scoring Model'!$C$6+S287*'Scoring Model'!$C$7+T287*'Scoring Model'!$C$8+U287*'Scoring Model'!$C$9)/5*100,0) -> 54 | W287: =IF(V287>=90,"Critical",IF(V287>=75,"High",IF(V287>=60,"Medium",IF(V287>=40,"Low","Optional")))) -> Low | X287: /blog/persistent-bad-breath/ | Y287: Create | Z287: Topical authority + TOFU traffic; link to the related service page with a booking CTA.
A289: Blue scores = analyst inputs; Demand, Opportunity, SERP Competition, Priority Score and Level are formulas. All volume/KD/CPC values are estimates (see Scoring Model).

Sheet Keyword Clusters
A1: Cluster Name | B1: Primary Keyword | C1: Secondary Keywords | D1: Questions | E1: Entities | F1: Intent | G1: Funnel Stage | H1: Recommended Page | I1: Page Type | J1: # Keywords (formula)
A2: Dental Implants | B2: dental implants nashville | C2: dental implants nashville tn; dental implants near me; dental implants cost nashville; same day dental implants nashville; dental implant dentist near me; best dental implants in nashville | D2: what are dental implants; how long do dental implants last; dental implant procedure step by step; are dental implants worth it | E2: Titanium post, abutment, crown, bone graft, osseointegration, missing tooth replacement, CBCT scan | F2: Transactional | G2: BOFU | H2: /services/dental-implants/ | I2: Service Page | J2: =COUNTIF('Keyword Master Database'!$D$2:$D$287,A2) -> 7
A3: Dental Implants - Education | B3: what are dental implants | C3: missing tooth replacement options; dental implant recovery time; dental implant procedure step by step; are dental implants worth it; how long do dental implants last | D3: what are dental implants; how long do dental implants last; dental implant procedure step by step; are dental implants worth it | E3: Titanium post, abutment, crown, bone graft, osseointegration, missing tooth replacement, CBCT scan | F3: Informational | G3: TOFU | H3: /blog/dental-implants-guide/ | I3: Blog / Guide | J3: =COUNTIF('Keyword Master Database'!$D$2:$D$287,A3) -> 6
A4: Emergency Dentistry | B4: emergency dentist nashville | C4: emergency dentist near me; emergency dentist nashville tn; 24 hour emergency dentist nashville; emergency dentist open now nashville; emergency dentist cost nashville; emergency dentist for kids nashville | D4: what counts as a dental emergency | E4: Dental emergency, same-day appointment, toothache, abscess, trauma, after-hours care | F4: Transactional | G4: BOFU | H4: /services/emergency-dentistry/ | I4: Service Hub Page | J4: =COUNTIF('Keyword Master Database'!$D$2:$D$287,A4) -> 9
A5: Emergency Dentistry - Education | B5: what counts as a dental emergency | C5: - | D5: what counts as a dental emergency | E5: Dental emergency, same-day appointment, toothache, abscess, trauma, after-hours care | F5: Informational | G5: TOFU | H5: /blog/emergency-dentistry-guide/ | I5: Blog / Guide | J5: =COUNTIF('Keyword Master Database'!$D$2:$D$287,A5) -> 1
A6: Cosmetic Dentistry | B6: cosmetic dentist nashville | C6: cosmetic dentist near me; cosmetic dentist nashville tn; smile makeover nashville; cosmetic dentist cost nashville; how much does cosmetic dentistry cost; cosmetic dentistry before and after | D6: See paired Education cluster | E6: Smile makeover, veneers, whitening, bonding, smile design, aesthetic dentist | F6: Transactional | G6: BOFU | H6: /services/cosmetic-dentistry/ | I6: Service Hub Page | J6: =COUNTIF('Keyword Master Database'!$D$2:$D$287,A6) -> 9
A7: Dental Veneers | B7: dental veneers nashville | C7: dental veneers near me; dental veneers cost nashville; porcelain veneers nashville; dental veneers nashville tn; veneers before and after; best dental veneers in nashville | D7: what are dental veneers; how long do veneers last; are veneers worth it | E7: Porcelain veneers, composite veneers, enamel, smile design, shade matching | F7: Transactional | G7: BOFU | H7: /services/dental-veneers/ | I7: Service Page | J7: =COUNTIF('Keyword Master Database'!$D$2:$D$287,A7) -> 7
A8: Dental Veneers - Education | B8: what are dental veneers | C8: how long do veneers last; are veneers worth it | D8: what are dental veneers; how long do veneers last; are veneers worth it | E8: Porcelain veneers, composite veneers, enamel, smile design, shade matching | F8: Informational | G8: TOFU | H8: /blog/dental-veneers-guide/ | I8: Blog / Guide | J8: =COUNTIF('Keyword Master Database'!$D$2:$D$287,A8) -> 3
A9: Teeth Whitening | B9: teeth whitening nashville | C9: professional teeth whitening nashville; teeth whitening nashville tn; teeth whitening near me; teeth whitening cost nashville; best teeth whitening in nashville | D9: is professional teeth whitening worth it; how long does teeth whitening last; teeth whitening sensitivity how to prevent | E9: In-office whitening, take-home trays, peroxide, enamel sensitivity, stains | F9: Transactional | G9: BOFU | H9: /services/teeth-whitening/ | I9: Service Page | J9: =COUNTIF('Keyword Master Database'!$D$2:$D$287,A9) -> 6
A10: Teeth Whitening - Education | B10: is professional teeth whitening worth it | C10: teeth whitening sensitivity how to prevent; how long does teeth whitening last | D10: is professional teeth whitening worth it; how long does teeth whitening last; teeth whitening sensitivity how to prevent | E10: In-office whitening, take-home trays, peroxide, enamel sensitivity, stains | F10: Informational | G10: TOFU | H10: /blog/teeth-whitening-guide/ | I10: Blog / Guide | J10: =COUNTIF('Keyword Master Database'!$D$2:$D$287,A10) -> 3
A11: Orthodontics | B11: orthodontics nashville | C11: braces nashville; invisalign nashville; clear aligners nashville; adult braces nashville; orthodontics near me; orthodontics nashville tn | D11: how long do braces take | E11: Braces, clear aligners, retainers, bite alignment, adult orthodontics | F11: Transactional | G11: BOFU | H11: /services/orthodontics/ | I11: Service Hub Page | J11: =COUNTIF('Keyword Master Database'!$D$2:$D$287,A11) -> 8
A12: Orthodontics - Education | B12: how long do braces take | C12: - | D12: how long do braces take | E12: Braces, clear aligners, retainers, bite alignment, adult orthodontics | F12: Informational | G12: TOFU | H12: /blog/orthodontics-guide/ | I12: Blog / Guide | J12: =COUNTIF('Keyword Master Database'!$D$2:$D$287,A12) -> 1
A13: Dental Crowns | B13: dental crowns nashville | C13: dental crowns nashville tn; same day crowns nashville; dental crowns near me; dental crowns cost nashville; best dental crowns in nashville | D13: what are dental crowns; how long do dental crowns last; dental crown procedure; loose dental crown what to do | E13: Porcelain crown, ceramic crown, cap, tooth prep, digital impression | F13: Transactional | G13: BOFU | H13: /services/dental-crowns/ | I13: Service Page | J13: =COUNTIF('Keyword Master Database'!$D$2:$D$287,A13) -> 6
... A76: Oral Health Education Hub | B76: sensitive teeth causes | C76: bad breath that won't go away | D76: sensitive teeth causes; bad breath that won't go away | E76: Sensitive teeth, bad breath, enamel, hygiene habits | F76: Informational | G76: TOFU | H76: /blog/sensitive-teeth-causes/ | I76: Blog / Guide | J76: =COUNTIF('Keyword Master Database'!$D$2:$D$287,A76) -> 2

Sheet Competitor Analysis
A1: Competitor | B1: URL | C1: Ranking Topics | D1: Strong Pages | E1: Weakness | F1: Content Gap | G1: Opportunity
A2: Competitor 1: Dentistas en USA | B2: https://dentistasenusa.com/ | C2: Spanish-language dentist discovery (dentistas en [city], dentista cerca de mi) - estimated | D2: City/state dentist listing pages and homepage - estimated | E2: Directory-style content; weak practice-level trust signals (reviews, clinicians, before/after) - estimated | F2: Neighborhood-level and service-specific Spanish content for Nashville | G2: Own the Nashville Spanish SERP with a practice-specific bilingual hub plus GBP and Spanish-language citations
A3: Competitor 2: Siroco Dental | B3: https://www.sirocodental.com/ | C3: General, cosmetic and family dentistry service topics - estimated | D3: Homepage and core service pages - estimated | E3: Page depth, FAQ schema and location-page coverage need validation | F3: Problem-based emergency content and technology explainers | G3: Out-build on emergency, same-day and technology content; add FAQ + LocalBusiness schema
A4: Competitor 3: Buen Pastor Dental | B4: https://buenpastordental.com/ | C4: Spanish-speaking patient audience and affordable-care topics - estimated | D4: Homepage and service pages - estimated | E4: Likely thin informational content and limited topical depth - estimated | F4: Educational cluster content (implants, root canal, gum disease) and comparison pages | G4: Publish comparison + cost-guidance content and affordable/financing pages to capture MOFU demand
A5: Competitor 4: Hay Dentistas | B5: https://haydentistas.com/ | C5: Spanish dentist directory and service keywords - estimated | D5: Homepage and city pages - estimated | E5: Directory model; limited clinical authority and proof - estimated | F5: Nashville-specific neighborhood pages and procedure guides | G5: Differentiate with clinician-led content, reviews and local landing pages
A6: Local Competitor: Nashville Family Dentistry | B6: (site not provided) | C6: Family dentistry in ZIP 37211 (5802 Nolensville Pike) - public listing | D6: Strong review base on third-party listings (about 926 reviews on one health directory) | E6: Unknown; audit site architecture and service-page depth | F6: Technology, emergency and cosmetic cluster depth - to validate | G6: Match review velocity; win cosmetic + emergency + Spanish queries it may not target
A7: Local Competitor: East Side Smiles | B7: https://eastsidesmiles.net/ | C7: General + cosmetic dentistry, East Nashville focus - public listing | D7: Strong Google rating and review count on listings (about 4.9 stars, 478 reviews) | E7: East Nashville-centric; less coverage of South Nashville/37211 | F7: South Nashville and Antioch hyper-local pages | G7: Capture southern Nashville neighborhoods with dedicated location pages
A8: Local Competitor: Brentwood Aesthetic & Family Dentists | B8: (site not provided) | C8: Smile design and custom veneers; aesthetic + family positioning - public SERP snippet | D8: Cosmetic/veneer positioning and local awards messaging | E8: Brentwood-centric; premium positioning | F8: Affordable cosmetic options and Nashville-proper local pages | G8: Compete on aesthetic + family positioning in Nashville proper with veneers and whitening content

Sheet Keyword Mapping
A1: URL | B1: Page Name | C1: Primary Keyword | D1: Secondary Keywords | E1: Intent | F1: Funnel Stage | G1: Existing/New | H1: Action | I1: Cannibalization Risk | J1: Keywords Mapped (formula)
A2: /services/dental-implants/ | B2: Dental Implants | C2: dental implants nashville | D2: dental implants nashville tn; dental implants near me; dental implants cost nashville; same day dental implants nashville | E2: Transactional | F2: BOFU | G2: Existing | H2: Optimize | I2: Low | J2: =COUNTIF('Keyword Master Database'!$X$2:$X$287,A2) -> 7
A3: /blog/dental-implants-guide/ | B3: Dental Implants: Complete Guide | C3: missing tooth replacement options | D3: what are dental implants; dental implant recovery time; dental implant procedure step by step; are dental implants worth it | E3: Informational | F3: TOFU | G3: New | H3: Create | I3: Low | J3: =COUNTIF('Keyword Master Database'!$X$2:$X$287,A3) -> 6
A4: /services/emergency-dentistry/ | B4: Emergency Dentistry | C4: emergency dentist nashville | D4: emergency dentist near me; emergency dentist nashville tn; 24 hour emergency dentist nashville; emergency dentist open now nashville | E4: Transactional | F4: BOFU | G4: Existing | H4: Optimize | I4: Medium | J4: =COUNTIF('Keyword Master Database'!$X$2:$X$287,A4) -> 9
A5: /blog/emergency-dentistry-guide/ | B5: Emergency Dentistry: Complete Guide | C5: what counts as a dental emergency | D5: - | E5: Informational | F5: TOFU | G5: New | H5: Create | I5: Low | J5: =COUNTIF('Keyword Master Database'!$X$2:$X$287,A5) -> 1
A6: /services/cosmetic-dentistry/ | B6: Cosmetic Dentistry | C6: cosmetic dentist near me | D6: cosmetic dentist nashville; cosmetic dentist nashville tn; smile makeover nashville; cosmetic dentist cost nashville | E6: Transactional | F6: BOFU | G6: Existing | H6: Optimize | I6: Medium | J6: =COUNTIF('Keyword Master Database'!$X$2:$X$287,A6) -> 9
A7: /services/dental-veneers/ | B7: Dental Veneers | C7: dental veneers near me | D7: dental veneers nashville; dental veneers cost nashville; porcelain veneers nashville; dental veneers nashville tn | E7: Transactional | F7: BOFU | G7: Existing | H7: Optimize | I7: Low | J7: =COUNTIF('Keyword Master Database'!$X$2:$X$287,A7) -> 7
A8: /blog/dental-veneers-guide/ | B8: Dental Veneers: Complete Guide | C8: how long do veneers last | D8: are veneers worth it; what are dental veneers | E8: Informational | F8: TOFU | G8: New | H8: Create | I8: Low | J8: =COUNTIF('Keyword Master Database'!$X$2:$X$287,A8) -> 3
A9: /services/teeth-whitening/ | B9: Teeth Whitening | C9: teeth whitening nashville | D9: professional teeth whitening nashville; teeth whitening nashville tn; teeth whitening near me; teeth whitening cost nashville | E9: Transactional | F9: BOFU | G9: Existing | H9: Optimize | I9: Low | J9: =COUNTIF('Keyword Master Database'!$X$2:$X$287,A9) -> 6
A10: /blog/teeth-whitening-guide/ | B10: Teeth Whitening: Complete Guide | C10: teeth whitening sensitivity how to prevent | D10: how long does teeth whitening last; is professional teeth whitening worth it | E10: Informational | F10: TOFU | G10: New | H10: Create | I10: Low | J10: =COUNTIF('Keyword Master Database'!$X$2:$X$287,A10) -> 3
A11: /services/orthodontics/ | B11: Orthodontics | C11: braces nashville | D11: invisalign nashville; clear aligners nashville; adult braces nashville; orthodontics near me | E11: Transactional | F11: BOFU | G11: Existing | H11: Optimize | I11: Medium | J11: =COUNTIF('Keyword Master Database'!$X$2:$X$287,A11) -> 8
A12: /blog/orthodontics-guide/ | B12: Orthodontics: Complete Guide | C12: how long do braces take | D12: - | E12: Informational | F12: TOFU | G12: New | H12: Create | I12: Low | J12: =COUNTIF('Keyword Master Database'!$X$2:$X$287,A12) -> 1
A13: /services/dental-crowns/ | B13: Dental Crowns | C13: dental crowns nashville | D13: dental crowns nashville tn; same day crowns nashville; dental crowns near me; dental crowns cost nashville | E13: Transactional | F13: BOFU | G13: Existing | H13: Optimize | I13: Low | J13: =COUNTIF('Keyword Master Database'!$X$2:$X$287,A13) -> 6
... A79: /blog/persistent-bad-breath/ | B79: Persistent Bad Breath | C79: bad breath that won't go away | D79: - | E79: Informational | F79: TOFU | G79: New | H79: Create | I79: Low | J79: =COUNTIF('Keyword Master Database'!$X$2:$X$287,A79) -> 1
A81: Existing/New is assumed from the services list provided; confirm against a crawl. 'Merge' = consolidate thin content into the parent hub; 'Redirect' (301) applies to any standalone page that is merged.

Sheet Topical Authority Map
A1: Main Topic | B1: Sub Topics | C1: Supporting Content | D1: Entities | E1: Commercial Connection
A2: Dental Implants (Restorative) | B2: Cost, procedure, recovery, candidacy, same-day implants, implants vs dentures/bridges | C2: How long implants last; implant procedure guide; are implants worth it; implants vs dentures vs bridges; Spanish implant page | D2: Titanium post, abutment, crown, bone graft, CBCT | E2: /services/dental-implants/ - highest-value lead page; consult booking CTA
A3: Emergency & Urgent Dentistry | B3: Toothache, broken tooth, cracked tooth, bleeding gums, same-day/walk-in, after-hours | C3: What counts as a dental emergency; toothache at night; knocked-out tooth; cracked tooth symptoms; emergency Spanish page | D3: Abscess, trauma, pain relief, same-day appointment | E3: /services/emergency-dentistry/ + child pages - call-driven BOFU leads
A4: Cosmetic & Aesthetic Dentistry | B4: Veneers, whitening, smile makeover, bonding, crowns for aesthetics | C4: Veneers vs crowns vs bonding; how long veneers last; whitening in-office vs at-home; before/after gallery | D4: Smile design, porcelain, composite, enamel | E4: /services/cosmetic-dentistry/ - premium service pages and consultation requests
A5: Restorative Dentistry | B5: Crowns, bridges, partials & dentures, fillings, root canals, extractions | C5: Crown/bridge/denture longevity guides; root canal vs extraction; composite vs amalgam; lost filling and loose crown FAQs | D5: Endodontics, pulp, pontic, abutment, composite resin | E5: Restorative hub and service pages - treatment-plan leads
A6: Preventive & Periodontal Care | B6: Cleanings, periodontal therapy, oral cancer screening, checkups, x-rays | C6: How often to get cleanings; stages of gum disease; oral cancer signs; deep cleaning vs regular cleaning | D6: Plaque, tartar, gingivitis, periodontitis, screening | E6: New-patient acquisition and recurring-visit pipeline
A7: Orthodontics | B7: Braces, clear aligners, adult orthodontics, retainers | C7: Invisalign vs braces; how long braces take; adult braces guide | D7: Braces, aligners, bite alignment | E7: /services/orthodontics/ - consult requests (verify services)
A8: Dental Technology | B8: Digital x-rays, digital impressions, intraoral pictures, 3D imaging | C8: Are dental x-rays safe; digital vs traditional impressions; what an intraoral camera shows | D8: Sensors, scanners, CAD/CAM, radiation dose | E8: Differentiation and trust: supports all service pages with E-E-A-T proof
A9: Local Nashville Authority | B9: South Nashville/37211, Antioch, Nolensville, Brentwood, Nolensville Pike corridor | C9: Neighborhood pages, local reviews page, community content, GBP posts | D9: Harding Pl, Woodbine, Oak Hill, Berry Hill, Glencliff | E9: Local pack visibility and 'near me' conversions
A10: Family, New Patient & Affordability | B10: Family dentistry, children's dentistry, new patients, insurance, financing, anxiety/sedation | C10: What to expect at your first visit; insurance & financing FAQ; dental anxiety tips | D10: PPO plans, payment plans, membership plan, kids dentistry | E10: Removes friction: increases bookings from price-sensitive and family searches
A11: Spanish / Bilingual Local SEO | B11: Dentista en Nashville, emergency, implants, services, affordable dentistry | C11: Spanish hub + 4 service pages + 2 educational posts | D11: Comunidad hispana, español, dentista, urgencias | E11: Underserved local SERP segment; competitor set is Spanish-language

Sheet SEO Silo Architecture
A1: Silo | B1: Parent Page | C1: Child Pages | D1: Purpose | E1: Internal Linking Flow
A2: Cosmetic Dentistry | B2: /services/cosmetic-dentistry/ (Cosmetic Dentistry) | C2: /services/dental-veneers/ (Dental Veneers) /services/teeth-whitening/ (Teeth Whitening) /blog/dental-veneers-guide/ (Dental Veneers: Complete Guide) /blog/teeth-whitening-guide/ (Teeth Whitening: Complete Guide) /blog/veneers-vs-crowns-vs-bonding/ (Veneers vs Crowns vs Bonding) /blog/in-office-vs-at-home-teeth-whitening/ (In-Office vs At-Home Whitening) | D2: Capture smile-makeover demand; funnel to veneer and whitening consultations | E2: Cosmetic Dentistry -> each child (service anchors); each child -> parent (hub anchor); child pages cross-link only within the silo; every child -> /contact/ (CTA)
A3: Restorative Dentistry | B3: /services/restorative-dentistry/ (Restorative Dentistry) | C3: /services/dental-implants/ (Dental Implants) /services/dental-crowns/ (Dental Crowns) /services/dental-bridges/ (Dental Bridges) /services/partials-dentures/ (Partials & Dentures) /services/dental-fillings/ (Dental Fillings) /services/root-canals/ (Root Canals) /services/dental-extractions/ (Dental Extractions) /blog/dental-implants-guide/ (Dental Implants: Complete Guide) /blog/dental-implants-vs-dentures-vs-bridges/ (Implants vs Dentures vs Bridges) /blog/root-canal-vs-extraction/ (Root Canal vs Extraction) /blog/root-canals-guide/ (Root Canals: Complete Guide) /blog/dental-crowns-guide/ (Dental Crowns: Complete Guide) | D3: Own high-value restorative terms; implants and root canals are the revenue anchors | E3: Restorative Dentistry -> each child (service anchors); each child -> parent (hub anchor); child pages cross-link only within the silo; every child -> /contact/ (CTA)
A4: Preventive & Periodontal | B4: /services/preventive-dentistry/ (Preventive Dentistry) | C4: /services/dental-cleanings/ (Dental Cleanings) /services/periodontal-therapy/ (Periodontal Therapy) /services/oral-cancer-screening/ (Oral Cancer Screening) /blog/dental-cleanings-guide/ (Dental Cleanings: Complete Guide) /blog/periodontal-therapy-guide/ (Periodontal Therapy: Complete Guide) /blog/dental-cleaning-vs-deep-cleaning/ (Dental Cleaning vs Deep Cleaning) /blog/oral-cancer-screening-guide/ (Oral Cancer Screening: Complete Guide) | D4: Build recurring-patient pipeline and health-authority signals | E4: Preventive Dentistry -> each child (service anchors); each child -> parent (hub anchor); child pages cross-link only within the silo; every child -> /contact/ (CTA)
A5: Emergency Dentistry | B5: /services/emergency-dentistry/ (Emergency Dentistry) | C5: /services/emergency-dentistry/toothache/ (Toothache) /services/emergency-dentistry/broken-tooth/ (Broken Tooth) /services/emergency-dentistry/cracked-tooth/ (Cracked Tooth) /services/emergency-dentistry/bleeding-gums/ (Gum Bleeding) /same-day-dentist-nashville/ (Same-Day & Walk-In Dentist) /blog/emergency-dentistry-guide/ (Emergency Dentistry: Complete Guide) /blog/toothache-guide/ (Toothache: Complete Guide) | D5: Capture urgent BOFU searches; call-first conversion pages | E5: Emergency Dentistry -> each child (service anchors); each child -> parent (hub anchor); child pages cross-link only within the silo; every child -> /contact/ (CTA)
A6: Orthodontics | B6: /services/orthodontics/ (Orthodontics) | C6: /blog/orthodontics-guide/ (Orthodontics: Complete Guide) /blog/invisalign-vs-braces/ (Invisalign vs Braces) | D6: Capture braces/aligner consults (verify services offered) | E6: Orthodontics -> each child (service anchors); each child -> parent (hub anchor); child pages cross-link only within the silo; every child -> /contact/ (CTA)
A7: Dental Technology | B7: /technology/ (Dental Technology Hub) | C7: /technology/digital-dental-x-rays/ (Digital Dental X-Rays) /technology/digital-dental-impressions/ (Digital Dental Impressions) /technology/intraoral-pictures/ (Intraoral Pictures) | D7: Prove modern care; E-E-A-T support for every service silo | E7: Dental Technology Hub -> each child (service anchors); each child -> parent (hub anchor); child pages cross-link only within the silo; every child -> /contact/ (CTA)
A8: Local Authority (Nashville) | B8: / (Homepage) | C8: /locations/south-nashville-dentist/ (South Nashville / 37211 Dentist) /locations/antioch-dentist/ (Antioch Dentist) /locations/nolensville-dentist/ (Nolensville Dentist) /locations/brentwood-dentist/ (Brentwood Dentist) /reviews/ (Patient Reviews) /contact/ (Contact / Book Appointment) | D8: Local pack + neighborhood relevance; connect GBP to site | E8: Homepage -> each child (service anchors); each child -> parent (hub anchor); child pages cross-link only within the silo; every child -> /contact/ (CTA)
A9: Family & New Patients | B9: /family-dentistry/ (Family Dentistry) | C9: /childrens-dentistry/ (Children's Dentistry) /new-patients/ (New Patients) /insurance-financing/ (Insurance & Financing) /dental-anxiety-sedation/ (Dental Anxiety & Sedation) | D9: Remove friction and capture family and price-sensitive searches | E9: Family Dentistry -> each child (service anchors); each child -> parent (hub anchor); child pages cross-link only within the silo; every child -> /contact/ (CTA)
A10: Spanish / Bilingual | B10: /es/dentista-en-nashville/ (Dentista en Nashville (Spanish Hub)) | C10: /es/dentista-de-emergencia/ (Dentista de Emergencia) /es/implantes-dentales/ (Implantes Dentales) /es/servicios-dentales/ (Servicios Dentales (Spanish)) /es/dentista-economico/ (Dentista Económico) /es/blog/dolor-de-muela-que-hacer/ (Dolor de Muela: Qué Hacer) /es/blog/encias-sangrantes-causas/ (Encías Sangrantes: Causas) | D10: Capture underserved Spanish-language local search | E10: Dentista en Nashville (Spanish Hub) -> each child (service anchors); each child -> parent (hub anchor); child pages cross-link only within the silo; every child -> /contact/ (CTA)
A11: Oral Health Education | B11: /blog/ (Blog / Oral Health Education Hub) | C11: /blog/sensitive-teeth-causes/ (Sensitive Teeth: Causes) /blog/persistent-bad-breath/ (Persistent Bad Breath) /blog/dental-implants-guide/ (Dental Implants: Complete Guide) /blog/emergency-dentistry-guide/ (Emergency Dentistry: Complete Guide) /blog/toothache-guide/ (Toothache: Complete Guide) | D11: Topical authority and AI-search citations; every article links to a service page | E11: Blog / Oral Health Education Hub -> each child (service anchors); each child -> parent (hub anchor); child pages cross-link only within the silo; every child -> /contact/ (CTA)

Sheet Internal Linking Blueprint
A1: Source Page | B1: Target Page | C1: Anchor Concept | D1: Purpose | E1: Silo
A2: /services/cosmetic-dentistry/ | B2: /services/dental-veneers/ | C2: Dental Veneers | D2: Distribute hub authority to child page | E2: Cosmetic Dentistry
A3: /services/dental-veneers/ | B3: /services/cosmetic-dentistry/ | C3: Cosmetic Dentistry | D3: Reinforce hub relevance (upward link) | E3: Cosmetic Dentistry
A4: /services/cosmetic-dentistry/ | B4: /services/teeth-whitening/ | C4: Teeth Whitening | D4: Distribute hub authority to child page | E4: Cosmetic Dentistry
A5: /services/teeth-whitening/ | B5: /services/cosmetic-dentistry/ | C5: Cosmetic Dentistry | D5: Reinforce hub relevance (upward link) | E5: Cosmetic Dentistry
A6: /services/cosmetic-dentistry/ | B6: /blog/dental-veneers-guide/ | C6: Dental Veneers | D6: Distribute hub authority to child page | E6: Cosmetic Dentistry
A7: /blog/dental-veneers-guide/ | B7: /services/cosmetic-dentistry/ | C7: Cosmetic Dentistry | D7: Reinforce hub relevance (upward link) | E7: Cosmetic Dentistry
A8: /services/cosmetic-dentistry/ | B8: /blog/teeth-whitening-guide/ | C8: Teeth Whitening | D8: Distribute hub authority to child page | E8: Cosmetic Dentistry
A9: /blog/teeth-whitening-guide/ | B9: /services/cosmetic-dentistry/ | C9: Cosmetic Dentistry | D9: Reinforce hub relevance (upward link) | E9: Cosmetic Dentistry
A10: /services/cosmetic-dentistry/ | B10: /blog/veneers-vs-crowns-vs-bonding/ | C10: Veneers vs Crowns vs Bonding | D10: Distribute hub authority to child page | E10: Cosmetic Dentistry
A11: /blog/veneers-vs-crowns-vs-bonding/ | B11: /services/cosmetic-dentistry/ | C11: Cosmetic Dentistry | D11: Reinforce hub relevance (upward link) | E11: Cosmetic Dentistry
A12: /services/cosmetic-dentistry/ | B12: /blog/in-office-vs-at-home-teeth-whitening/ | C12: In-Office vs At-Home Whitening | D12: Distribute hub authority to child page | E12: Cosmetic Dentistry
... A190: /reviews/ | B190: /services/ | C190: Our services | D190: Social proof to service | E190: Cross-link / Conversion

Sheet Content Roadmap
A1: Timeline | B1: Priority | C1: Content Type | D1: Title | E1: Target Keyword | F1: Search Intent | G1: Funnel Stage | H1: URL | I1: Business Goal
A2: Month 1 (Weeks 1-4) | B2: {=INDEX('Keyword Master Database'!$W$2:$W$287,MATCH(E2,'Keyword Master Database'!$A$2:$A$287,0))} -> Critical | C2: Page Optimization | D2: Homepage rewrite: Aesthetic & Family Dentist in South Nashville | E2: dentist nashville | F2: {=INDEX('Keyword Master Database'!$E$2:$E$287,MATCH(E2,'Keyword Master Database'!$A$2:$A$287,0))} -> Transactional | G2: {=INDEX('Keyword Master Database'!$F$2:$F$287,MATCH(E2,'Keyword Master Database'!$A$2:$A$287,0))} -> BOFU | H2: / | I2: Local leads
A3: Month 1 (Weeks 1-4) | B3: {=INDEX('Keyword Master Database'!$W$2:$W$287,MATCH(E3,'Keyword Master Database'!$A$2:$A$287,0))} -> Critical | C3: Page Optimization | D3: Dental Implants page refresh: pricing guidance, FAQs, schema | E3: dental implants nashville | F3: {=INDEX('Keyword Master Database'!$E$2:$E$287,MATCH(E3,'Keyword Master Database'!$A$2:$A$287,0))} -> Transactional | G3: {=INDEX('Keyword Master Database'!$F$2:$F$287,MATCH(E3,'Keyword Master Database'!$A$2:$A$287,0))} -> BOFU | H3: /services/dental-implants/ | I3: Service/transactional rankings
A4: Month 1 (Weeks 1-4) | B4: {=INDEX('Keyword Master Database'!$W$2:$W$287,MATCH(E4,'Keyword Master Database'!$A$2:$A$287,0))} -> Critical | C4: Page Optimization | D4: Emergency Dentistry hub: same-day care, click-to-call, hours | E4: emergency dentist nashville | F4: {=INDEX('Keyword Master Database'!$E$2:$E$287,MATCH(E4,'Keyword Master Database'!$A$2:$A$287,0))} -> Transactional | G4: {=INDEX('Keyword Master Database'!$F$2:$F$287,MATCH(E4,'Keyword Master Database'!$A$2:$A$287,0))} -> BOFU | H4: /services/emergency-dentistry/ | I4: Local leads
A5: Month 1 (Weeks 1-4) | B5: {=INDEX('Keyword Master Database'!$W$2:$W$287,MATCH(E5,'Keyword Master Database'!$A$2:$A$287,0))} -> High | C5: Page Optimization | D5: Cosmetic Dentistry hub: smile makeover with before/after | E5: cosmetic dentist nashville | F5: {=INDEX('Keyword Master Database'!$E$2:$E$287,MATCH(E5,'Keyword Master Database'!$A$2:$A$287,0))} -> Transactional | G5: {=INDEX('Keyword Master Database'!$F$2:$F$287,MATCH(E5,'Keyword Master Database'!$A$2:$A$287,0))} -> BOFU | H5: /services/cosmetic-dentistry/ | I5: Service/transactional rankings
A6: Month 1 (Weeks 1-4) | B6: {=INDEX('Keyword Master Database'!$W$2:$W$287,MATCH(E6,'Keyword Master Database'!$A$2:$A$287,0))} -> High | C6: Page Optimization | D6: Root Canals page: pain myths, process, same-day options | E6: root canal nashville | F6: {=INDEX('Keyword Master Database'!$E$2:$E$287,MATCH(E6,'Keyword Master Database'!$A$2:$A$287,0))} -> Transactional | G6: {=INDEX('Keyword Master Database'!$F$2:$F$287,MATCH(E6,'Keyword Master Database'!$A$2:$A$287,0))} -> BOFU | H6: /services/root-canals/ | I6: Service/transactional rankings
A7: Month 1 (Weeks 1-4) | B7: {=INDEX('Keyword Master Database'!$W$2:$W$287,MATCH(E7,'Keyword Master Database'!$A$2:$A$287,0))} -> High | C7: Page Optimization | D7: Dental Veneers page: process, cost range, gallery | E7: dental veneers nashville | F7: {=INDEX('Keyword Master Database'!$E$2:$E$287,MATCH(E7,'Keyword Master Database'!$A$2:$A$287,0))} -> Transactional | G7: {=INDEX('Keyword Master Database'!$F$2:$F$287,MATCH(E7,'Keyword Master Database'!$A$2:$A$287,0))} -> BOFU | H7: /services/dental-veneers/ | I7: Service/transactional rankings
A8: Month 1 (Weeks 1-4) | B8: {=INDEX('Keyword Master Database'!$W$2:$W$287,MATCH(E8,'Keyword Master Database'!$A$2:$A$287,0))} -> Critical | C8: New Page | D8: Family Dentistry in Nashville | E8: family dentist nashville | F8: {=INDEX('Keyword Master Database'!$E$2:$E$287,MATCH(E8,'Keyword Master Database'!$A$2:$A$287,0))} -> Transactional | G8: {=INDEX('Keyword Master Database'!$F$2:$F$287,MATCH(E8,'Keyword Master Database'!$A$2:$A$287,0))} -> BOFU | H8: /family-dentistry/ | I8: Local leads
A9: Month 1 (Weeks 1-4) | B9: {=INDEX('Keyword Master Database'!$W$2:$W$287,MATCH(E9,'Keyword Master Database'!$A$2:$A$287,0))} -> High | C9: GBP Optimization | D9: Google Business Profile: services, Q&A, posts aligned to money keywords | E9: dentist near me | F9: {=INDEX('Keyword Master Database'!$E$2:$E$287,MATCH(E9,'Keyword Master Database'!$A$2:$A$287,0))} -> Transactional | G9: {=INDEX('Keyword Master Database'!$F$2:$F$287,MATCH(E9,'Keyword Master Database'!$A$2:$A$287,0))} -> BOFU | H9: / | I9: Local leads
A10: Month 2 (Weeks 5-8) | B10: {=INDEX('Keyword Master Database'!$W$2:$W$287,MATCH(E10,'Keyword Master Database'!$A$2:$A$287,0))} -> High | C10: New Page | D10: Dental Insurance & Financing Options | E10: dentist that accepts insurance nashville | F10: {=INDEX('Keyword Master Database'!$E$2:$E$287,MATCH(E10,'Keyword Master Database'!$A$2:$A$287,0))} -> Transactional | G10: {=INDEX('Keyword Master Database'!$F$2:$F$287,MATCH(E10,'Keyword Master Database'!$A$2:$A$287,0))} -> BOFU | H10: /insurance-financing/ | I10: Local leads
A11: Month 2 (Weeks 5-8) | B11: {=INDEX('Keyword Master Database'!$W$2:$W$287,MATCH(E11,'Keyword Master Database'!$A$2:$A$287,0))} -> High | C11: New Page | D11: South Nashville / 37211 Dentist | E11: dentist south nashville | F11: {=INDEX('Keyword Master Database'!$E$2:$E$287,MATCH(E11,'Keyword Master Database'!$A$2:$A$287,0))} -> Transactional | G11: {=INDEX('Keyword Master Database'!$F$2:$F$287,MATCH(E11,'Keyword Master Database'!$A$2:$A$287,0))} -> BOFU | H11: /locations/south-nashville-dentist/ | I11: Local leads
A12: Month 2 (Weeks 5-8) | B12: {=INDEX('Keyword Master Database'!$W$2:$W$287,MATCH(E12,'Keyword Master Database'!$A$2:$A$287,0))} -> High | C12: New Page | D12: New Patients: what to expect and how to book | E12: dentist accepting new patients nashville | F12: {=INDEX('Keyword Master Database'!$E$2:$E$287,MATCH(E12,'Keyword Master Database'!$A$2:$A$287,0))} -> Transactional | G12: {=INDEX('Keyword Master Database'!$F$2:$F$287,MATCH(E12,'Keyword Master Database'!$A$2:$A$287,0))} -> BOFU | H12: /new-patients/ | I12: Local leads
A13: Month 2 (Weeks 5-8) | B13: {=INDEX('Keyword Master Database'!$W$2:$W$287,MATCH(E13,'Keyword Master Database'!$A$2:$A$287,0))} -> High | C13: New Page | D13: Same-Day & Walk-In Dentist in Nashville | E13: walk in dentist nashville | F13: {=INDEX('Keyword Master Database'!$E$2:$E$287,MATCH(E13,'Keyword Master Database'!$A$2:$A$287,0))} -> Transactional | G13: {=INDEX('Keyword Master Database'!$F$2:$F$287,MATCH(E13,'Keyword Master Database'!$A$2:$A$287,0))} -> BOFU | H13: /same-day-dentist-nashville/ | I13: Local leads
... A51: Month 6 (Weeks 21-26) | B51: {=INDEX('Keyword Master Database'!$W$2:$W$287,MATCH(E51,'Keyword Master Database'!$A$2:$A$287,0))} -> High | C51: New Page | D51: Patient Reviews page with review schema | E51: dental faith nashville reviews | F51: {=INDEX('Keyword Master Database'!$E$2:$E$287,MATCH(E51,'Keyword Master Database'!$A$2:$A$287,0))} -> Navigational | G51: {=INDEX('Keyword Master Database'!$F$2:$F$287,MATCH(E51,'Keyword Master Database'!$A$2:$A$287,0))} -> BOFU | H51: /reviews/ | I51: Local leads

Sheet Quick Wins
A1: Keyword | B1: Intent | C1: Funnel Stage | D1: Opportunity | E1: Reason | F1: Recommended Action
A2: dentista hispano nashville | B2: {=INDEX('Keyword Master Database'!$E$2:$E$287,MATCH(A2,'Keyword Master Database'!$A$2:$A$287,0))} -> Transactional | C2: {=INDEX('Keyword Master Database'!$F$2:$F$287,MATCH(A2,'Keyword Master Database'!$A$2:$A$287,0))} -> BOFU | D2: {="KD "&INDEX('Keyword Master Database'!$J$2:$J$287,MATCH(A2,'Keyword Master Database'!$A$2:$A$287,0))&" | ~"&TEXT(INDEX('Keyword Master Database'!$H$2:$H$287,MATCH(A2,'Keyword Master Database'!$A$2:$A$287,0)),"#,##0")&" searches/mo | Priority "&INDEX('Keyword Master Database'!$V$2:$V$287,MATCH(A2,'Keyword Master Database'!$A$2:$A$287,0))} -> KD 22 | ~210 searches/mo | Priority 92 | E2: Low-difficulty Spanish-language local term; Spanish SERPs are typically thinly optimized and the competitor set is Spanish-language. | F2: Create/optimize /es/dentista-en-nashville/: Spanish title, H1, FAQ, GBP service link, native-speaker review.
A3: dentista que habla español nashville | B3: {=INDEX('Keyword Master Database'!$E$2:$E$287,MATCH(A3,'Keyword Master Database'!$A$2:$A$287,0))} -> Transactional | C3: {=INDEX('Keyword Master Database'!$F$2:$F$287,MATCH(A3,'Keyword Master Database'!$A$2:$A$287,0))} -> BOFU | D3: {="KD "&INDEX('Keyword Master Database'!$J$2:$J$287,MATCH(A3,'Keyword Master Database'!$A$2:$A$287,0))&" | ~"&TEXT(INDEX('Keyword Master Database'!$H$2:$H$287,MATCH(A3,'Keyword Master Database'!$A$2:$A$287,0)),"#,##0")&" searches/mo | Priority "&INDEX('Keyword Master Database'!$V$2:$V$287,MATCH(A3,'Keyword Master Database'!$A$2:$A$287,0))} -> KD 20 | ~170 searches/mo | Priority 92 | E3: Low-difficulty Spanish-language local term; Spanish SERPs are typically thinly optimized and the competitor set is Spanish-language. | F3: Create/optimize /es/dentista-en-nashville/: Spanish title, H1, FAQ, GBP service link, native-speaker review.
A4: dentista de emergencia nashville | B4: {=INDEX('Keyword Master Database'!$E$2:$E$287,MATCH(A4,'Keyword Master Database'!$A$2:$A$287,0))} -> Transactional | C4: {=INDEX('Keyword Master Database'!$F$2:$F$287,MATCH(A4,'Keyword Master Database'!$A$2:$A$287,0))} -> BOFU | D4: {="KD "&INDEX('Keyword Master Database'!$J$2:$J$287,MATCH(A4,'Keyword Master Database'!$A$2:$A$287,0))&" | ~"&TEXT(INDEX('Keyword Master Database'!$H$2:$H$287,MATCH(A4,'Keyword Master Database'!$A$2:$A$287,0)),"#,##0")&" searches/mo | Priority "&INDEX('Keyword Master Database'!$V$2:$V$287,MATCH(A4,'Keyword Master Database'!$A$2:$A$287,0))} -> KD 24 | ~140 searches/mo | Priority 89 | E4: Low-difficulty Spanish-language local term; Spanish SERPs are typically thinly optimized and the competitor set is Spanish-language. | F4: Create/optimize /es/dentista-de-emergencia/: Spanish title, H1, FAQ, GBP service link, native-speaker review.
